{
 "cells": [
  {
   "cell_type": "code",
   "execution_count": 15,
   "metadata": {},
   "outputs": [],
   "source": [
    "import pandas as pd\n",
    "import numpy as np\n",
    "import joblib\n",
    "from sklearn.ensemble import RandomForestClassifier\n",
    "from sklearn.metrics import recall_score\n",
    "from sklearn.pipeline import Pipeline\n",
    "from sklearn.preprocessing import StandardScaler, OneHotEncoder, LabelEncoder\n",
    "from sklearn.impute import SimpleImputer\n",
    "from sklearn.metrics import confusion_matrix, classification_report,accuracy_score, recall_score\n",
    "from xgboost import XGBClassifier\n",
    "from sklearn.model_selection import GridSearchCV, RepeatedStratifiedKFold\n",
    "\n",
    "import matplotlib.pyplot as plt\n",
    "import dill\n",
    "import sys\n",
    "import seaborn as sns\n",
    "# import the pipeline file\n",
    "sys.path.insert(0,'../')\n",
    "from utils import split_data"
   ]
  },
  {
   "cell_type": "code",
   "execution_count": 8,
   "metadata": {},
   "outputs": [
    {
     "name": "stdout",
     "output_type": "stream",
     "text": [
      "<class 'pandas.core.frame.DataFrame'>\n",
      "RangeIndex: 25832 entries, 0 to 25831\n",
      "Data columns (total 13 columns):\n",
      " #   Column       Non-Null Count  Dtype  \n",
      "---  ------       --------------  -----  \n",
      " 0   Time         25832 non-null  object \n",
      " 1   CellName     25832 non-null  object \n",
      " 2   PRBUsageUL   25832 non-null  float64\n",
      " 3   PRBUsageDL   25832 non-null  float64\n",
      " 4   meanThr_DL   25832 non-null  float64\n",
      " 5   meanThr_UL   25832 non-null  float64\n",
      " 6   maxThr_DL    25832 non-null  float64\n",
      " 7   maxThr_UL    25832 non-null  float64\n",
      " 8   meanUE_DL    25832 non-null  float64\n",
      " 9   meanUE_UL    25832 non-null  float64\n",
      " 10  maxUE_DL     25773 non-null  float64\n",
      " 11  maxUE_UL     25773 non-null  float64\n",
      " 12  maxUE_UL+DL  25828 non-null  object \n",
      "dtypes: float64(10), object(3)\n",
      "memory usage: 2.6+ MB\n"
     ]
    }
   ],
   "source": [
    "X_train,y_train = split_data.get_train_data()\n",
    "X_test,y_test = split_data.get_test_data()\n",
    "X_train.info()"
   ]
  },
  {
   "cell_type": "code",
   "execution_count": 9,
   "metadata": {},
   "outputs": [
    {
     "name": "stdout",
     "output_type": "stream",
     "text": [
      "Pipeline(steps=[('SetNull', NullEncoder()),\n",
      "                ('TimeConversion', TimeConversation()),\n",
      "                ('ObjectToFloat', ObjectToFloat()), ('Scaling', Scaling()),\n",
      "                ('OneHotEncoding',\n",
      "                 OneHotEncoding(categories=array(['10ALTE', '10BLTE', '10CLTE', '1ALTE', '1BLTE', '1CLTE', '2ALTE',\n",
      "       '3ALTE', '3BLTE', '3CLTE', '4ALTE', '4BLTE', '4CLTE', '5ALTE',\n",
      "       '5BLTE', '5CLTE', '6ALTE', '6BLTE', '6CLTE', '6ULTE', '6VLTE',\n",
      "       '6WLTE', '7ALTE', '7BLTE', '7CLTE', '7ULTE', '7VLTE', '7WLTE',\n",
      "       '8ALTE', '8BLTE', '8CLTE', '9ALTE', '9BLTE'], dtype=object)))])\n"
     ]
    }
   ],
   "source": [
    "with open('../pipelines/PreprocessingPipeline2.0.pkl', 'rb') as f:\n",
    "    pipeline,categories = dill.load(f)\n",
    "print(pipeline)"
   ]
  },
  {
   "cell_type": "code",
   "execution_count": 19,
   "metadata": {},
   "outputs": [],
   "source": [
    "# Define the pipeline\n",
    "pipeline = Pipeline([\n",
    "    ('preprocessing', pipeline),\n",
    "    ('imputer', SimpleImputer(strategy='mean')),\n",
    "    ('classifier', None)\n",
    "])"
   ]
  },
  {
   "cell_type": "code",
   "execution_count": 20,
   "metadata": {},
   "outputs": [],
   "source": [
    "# Define the hyperparameter grid for Random Forest\n",
    "rf_param_grid = {\n",
    "    'classifier': [RandomForestClassifier()],\n",
    "    'classifier__n_estimators': [50, 100, 200],\n",
    "    'classifier__max_depth': [None, 5, 10],\n",
    "    'classifier__min_samples_split': [2, 5],\n",
    "}\n",
    "\n",
    "# Define the hyperparameter grid for XGBoost\n",
    "xgb_param_grid = {\n",
    "    'classifier': [XGBClassifier()],\n",
    "    'classifier__learning_rate': [0.1, 0.01],\n",
    "    'classifier__max_depth': [3, 5],\n",
    "    'classifier__n_estimators': [50, 100, 200],\n",
    "}\n"
   ]
  },
  {
   "cell_type": "code",
   "execution_count": 23,
   "metadata": {},
   "outputs": [
    {
     "name": "stderr",
     "output_type": "stream",
     "text": [
      "/Users/nikulnayi/opt/anaconda3/lib/python3.9/site-packages/sklearn/model_selection/_validation.py:770: UserWarning: Scoring failed. The score on this train-test partition for these parameters will be set to nan. Details: \n",
      "Traceback (most recent call last):\n",
      "  File \"/Users/nikulnayi/opt/anaconda3/lib/python3.9/site-packages/sklearn/model_selection/_validation.py\", line 761, in _score\n",
      "    scores = scorer(estimator, X_test, y_test)\n",
      "  File \"/Users/nikulnayi/opt/anaconda3/lib/python3.9/site-packages/sklearn/metrics/_scorer.py\", line 216, in __call__\n",
      "    return self._score(\n",
      "  File \"/Users/nikulnayi/opt/anaconda3/lib/python3.9/site-packages/sklearn/metrics/_scorer.py\", line 264, in _score\n",
      "    return self._sign * self._score_func(y_true, y_pred, **self._kwargs)\n",
      "  File \"/Users/nikulnayi/opt/anaconda3/lib/python3.9/site-packages/sklearn/metrics/_classification.py\", line 1901, in recall_score\n",
      "    _, r, _, _ = precision_recall_fscore_support(\n",
      "  File \"/Users/nikulnayi/opt/anaconda3/lib/python3.9/site-packages/sklearn/metrics/_classification.py\", line 1544, in precision_recall_fscore_support\n",
      "    labels = _check_set_wise_labels(y_true, y_pred, average, labels, pos_label)\n",
      "  File \"/Users/nikulnayi/opt/anaconda3/lib/python3.9/site-packages/sklearn/metrics/_classification.py\", line 1348, in _check_set_wise_labels\n",
      "    y_type, y_true, y_pred = _check_targets(y_true, y_pred)\n",
      "  File \"/Users/nikulnayi/opt/anaconda3/lib/python3.9/site-packages/sklearn/metrics/_classification.py\", line 84, in _check_targets\n",
      "    check_consistent_length(y_true, y_pred)\n",
      "  File \"/Users/nikulnayi/opt/anaconda3/lib/python3.9/site-packages/sklearn/utils/validation.py\", line 332, in check_consistent_length\n",
      "    raise ValueError(\n",
      "ValueError: Found input variables with inconsistent numbers of samples: [5166, 10332]\n",
      "\n",
      "  warnings.warn(\n",
      "/Users/nikulnayi/opt/anaconda3/lib/python3.9/site-packages/sklearn/model_selection/_validation.py:770: UserWarning: Scoring failed. The score on this train-test partition for these parameters will be set to nan. Details: \n",
      "Traceback (most recent call last):\n",
      "  File \"/Users/nikulnayi/opt/anaconda3/lib/python3.9/site-packages/sklearn/model_selection/_validation.py\", line 761, in _score\n",
      "    scores = scorer(estimator, X_test, y_test)\n",
      "  File \"/Users/nikulnayi/opt/anaconda3/lib/python3.9/site-packages/sklearn/metrics/_scorer.py\", line 216, in __call__\n",
      "    return self._score(\n",
      "  File \"/Users/nikulnayi/opt/anaconda3/lib/python3.9/site-packages/sklearn/metrics/_scorer.py\", line 264, in _score\n",
      "    return self._sign * self._score_func(y_true, y_pred, **self._kwargs)\n",
      "  File \"/Users/nikulnayi/opt/anaconda3/lib/python3.9/site-packages/sklearn/metrics/_classification.py\", line 1901, in recall_score\n",
      "    _, r, _, _ = precision_recall_fscore_support(\n",
      "  File \"/Users/nikulnayi/opt/anaconda3/lib/python3.9/site-packages/sklearn/metrics/_classification.py\", line 1544, in precision_recall_fscore_support\n",
      "    labels = _check_set_wise_labels(y_true, y_pred, average, labels, pos_label)\n",
      "  File \"/Users/nikulnayi/opt/anaconda3/lib/python3.9/site-packages/sklearn/metrics/_classification.py\", line 1348, in _check_set_wise_labels\n",
      "    y_type, y_true, y_pred = _check_targets(y_true, y_pred)\n",
      "  File \"/Users/nikulnayi/opt/anaconda3/lib/python3.9/site-packages/sklearn/metrics/_classification.py\", line 84, in _check_targets\n",
      "    check_consistent_length(y_true, y_pred)\n",
      "  File \"/Users/nikulnayi/opt/anaconda3/lib/python3.9/site-packages/sklearn/utils/validation.py\", line 332, in check_consistent_length\n",
      "    raise ValueError(\n",
      "ValueError: Found input variables with inconsistent numbers of samples: [5166, 10332]\n",
      "\n",
      "  warnings.warn(\n",
      "/Users/nikulnayi/opt/anaconda3/lib/python3.9/site-packages/sklearn/model_selection/_validation.py:770: UserWarning: Scoring failed. The score on this train-test partition for these parameters will be set to nan. Details: \n",
      "Traceback (most recent call last):\n",
      "  File \"/Users/nikulnayi/opt/anaconda3/lib/python3.9/site-packages/sklearn/model_selection/_validation.py\", line 761, in _score\n",
      "    scores = scorer(estimator, X_test, y_test)\n",
      "  File \"/Users/nikulnayi/opt/anaconda3/lib/python3.9/site-packages/sklearn/metrics/_scorer.py\", line 216, in __call__\n",
      "    return self._score(\n",
      "  File \"/Users/nikulnayi/opt/anaconda3/lib/python3.9/site-packages/sklearn/metrics/_scorer.py\", line 264, in _score\n",
      "    return self._sign * self._score_func(y_true, y_pred, **self._kwargs)\n",
      "  File \"/Users/nikulnayi/opt/anaconda3/lib/python3.9/site-packages/sklearn/metrics/_classification.py\", line 1901, in recall_score\n",
      "    _, r, _, _ = precision_recall_fscore_support(\n",
      "  File \"/Users/nikulnayi/opt/anaconda3/lib/python3.9/site-packages/sklearn/metrics/_classification.py\", line 1544, in precision_recall_fscore_support\n",
      "    labels = _check_set_wise_labels(y_true, y_pred, average, labels, pos_label)\n",
      "  File \"/Users/nikulnayi/opt/anaconda3/lib/python3.9/site-packages/sklearn/metrics/_classification.py\", line 1348, in _check_set_wise_labels\n",
      "    y_type, y_true, y_pred = _check_targets(y_true, y_pred)\n",
      "  File \"/Users/nikulnayi/opt/anaconda3/lib/python3.9/site-packages/sklearn/metrics/_classification.py\", line 84, in _check_targets\n",
      "    check_consistent_length(y_true, y_pred)\n",
      "  File \"/Users/nikulnayi/opt/anaconda3/lib/python3.9/site-packages/sklearn/utils/validation.py\", line 332, in check_consistent_length\n",
      "    raise ValueError(\n",
      "ValueError: Found input variables with inconsistent numbers of samples: [5166, 10332]\n",
      "\n",
      "  warnings.warn(\n",
      "/Users/nikulnayi/opt/anaconda3/lib/python3.9/site-packages/sklearn/model_selection/_validation.py:770: UserWarning: Scoring failed. The score on this train-test partition for these parameters will be set to nan. Details: \n",
      "Traceback (most recent call last):\n",
      "  File \"/Users/nikulnayi/opt/anaconda3/lib/python3.9/site-packages/sklearn/model_selection/_validation.py\", line 761, in _score\n",
      "    scores = scorer(estimator, X_test, y_test)\n",
      "  File \"/Users/nikulnayi/opt/anaconda3/lib/python3.9/site-packages/sklearn/metrics/_scorer.py\", line 216, in __call__\n",
      "    return self._score(\n",
      "  File \"/Users/nikulnayi/opt/anaconda3/lib/python3.9/site-packages/sklearn/metrics/_scorer.py\", line 264, in _score\n",
      "    return self._sign * self._score_func(y_true, y_pred, **self._kwargs)\n",
      "  File \"/Users/nikulnayi/opt/anaconda3/lib/python3.9/site-packages/sklearn/metrics/_classification.py\", line 1901, in recall_score\n",
      "    _, r, _, _ = precision_recall_fscore_support(\n",
      "  File \"/Users/nikulnayi/opt/anaconda3/lib/python3.9/site-packages/sklearn/metrics/_classification.py\", line 1544, in precision_recall_fscore_support\n",
      "    labels = _check_set_wise_labels(y_true, y_pred, average, labels, pos_label)\n",
      "  File \"/Users/nikulnayi/opt/anaconda3/lib/python3.9/site-packages/sklearn/metrics/_classification.py\", line 1348, in _check_set_wise_labels\n",
      "    y_type, y_true, y_pred = _check_targets(y_true, y_pred)\n",
      "  File \"/Users/nikulnayi/opt/anaconda3/lib/python3.9/site-packages/sklearn/metrics/_classification.py\", line 84, in _check_targets\n",
      "    check_consistent_length(y_true, y_pred)\n",
      "  File \"/Users/nikulnayi/opt/anaconda3/lib/python3.9/site-packages/sklearn/utils/validation.py\", line 332, in check_consistent_length\n",
      "    raise ValueError(\n",
      "ValueError: Found input variables with inconsistent numbers of samples: [5166, 10332]\n",
      "\n",
      "  warnings.warn(\n",
      "/Users/nikulnayi/opt/anaconda3/lib/python3.9/site-packages/sklearn/model_selection/_validation.py:770: UserWarning: Scoring failed. The score on this train-test partition for these parameters will be set to nan. Details: \n",
      "Traceback (most recent call last):\n",
      "  File \"/Users/nikulnayi/opt/anaconda3/lib/python3.9/site-packages/sklearn/model_selection/_validation.py\", line 761, in _score\n",
      "    scores = scorer(estimator, X_test, y_test)\n",
      "  File \"/Users/nikulnayi/opt/anaconda3/lib/python3.9/site-packages/sklearn/metrics/_scorer.py\", line 216, in __call__\n",
      "    return self._score(\n",
      "  File \"/Users/nikulnayi/opt/anaconda3/lib/python3.9/site-packages/sklearn/metrics/_scorer.py\", line 264, in _score\n",
      "    return self._sign * self._score_func(y_true, y_pred, **self._kwargs)\n",
      "  File \"/Users/nikulnayi/opt/anaconda3/lib/python3.9/site-packages/sklearn/metrics/_classification.py\", line 1901, in recall_score\n",
      "    _, r, _, _ = precision_recall_fscore_support(\n",
      "  File \"/Users/nikulnayi/opt/anaconda3/lib/python3.9/site-packages/sklearn/metrics/_classification.py\", line 1544, in precision_recall_fscore_support\n",
      "    labels = _check_set_wise_labels(y_true, y_pred, average, labels, pos_label)\n",
      "  File \"/Users/nikulnayi/opt/anaconda3/lib/python3.9/site-packages/sklearn/metrics/_classification.py\", line 1348, in _check_set_wise_labels\n",
      "    y_type, y_true, y_pred = _check_targets(y_true, y_pred)\n",
      "  File \"/Users/nikulnayi/opt/anaconda3/lib/python3.9/site-packages/sklearn/metrics/_classification.py\", line 84, in _check_targets\n",
      "    check_consistent_length(y_true, y_pred)\n",
      "  File \"/Users/nikulnayi/opt/anaconda3/lib/python3.9/site-packages/sklearn/utils/validation.py\", line 332, in check_consistent_length\n",
      "    raise ValueError(\n",
      "ValueError: Found input variables with inconsistent numbers of samples: [5166, 10332]\n",
      "\n",
      "  warnings.warn(\n"
     ]
    },
    {
     "name": "stderr",
     "output_type": "stream",
     "text": [
      "/Users/nikulnayi/opt/anaconda3/lib/python3.9/site-packages/sklearn/model_selection/_validation.py:770: UserWarning: Scoring failed. The score on this train-test partition for these parameters will be set to nan. Details: \n",
      "Traceback (most recent call last):\n",
      "  File \"/Users/nikulnayi/opt/anaconda3/lib/python3.9/site-packages/sklearn/model_selection/_validation.py\", line 761, in _score\n",
      "    scores = scorer(estimator, X_test, y_test)\n",
      "  File \"/Users/nikulnayi/opt/anaconda3/lib/python3.9/site-packages/sklearn/metrics/_scorer.py\", line 216, in __call__\n",
      "    return self._score(\n",
      "  File \"/Users/nikulnayi/opt/anaconda3/lib/python3.9/site-packages/sklearn/metrics/_scorer.py\", line 264, in _score\n",
      "    return self._sign * self._score_func(y_true, y_pred, **self._kwargs)\n",
      "  File \"/Users/nikulnayi/opt/anaconda3/lib/python3.9/site-packages/sklearn/metrics/_classification.py\", line 1901, in recall_score\n",
      "    _, r, _, _ = precision_recall_fscore_support(\n",
      "  File \"/Users/nikulnayi/opt/anaconda3/lib/python3.9/site-packages/sklearn/metrics/_classification.py\", line 1544, in precision_recall_fscore_support\n",
      "    labels = _check_set_wise_labels(y_true, y_pred, average, labels, pos_label)\n",
      "  File \"/Users/nikulnayi/opt/anaconda3/lib/python3.9/site-packages/sklearn/metrics/_classification.py\", line 1348, in _check_set_wise_labels\n",
      "    y_type, y_true, y_pred = _check_targets(y_true, y_pred)\n",
      "  File \"/Users/nikulnayi/opt/anaconda3/lib/python3.9/site-packages/sklearn/metrics/_classification.py\", line 84, in _check_targets\n",
      "    check_consistent_length(y_true, y_pred)\n",
      "  File \"/Users/nikulnayi/opt/anaconda3/lib/python3.9/site-packages/sklearn/utils/validation.py\", line 332, in check_consistent_length\n",
      "    raise ValueError(\n",
      "ValueError: Found input variables with inconsistent numbers of samples: [5166, 10332]\n",
      "\n",
      "  warnings.warn(\n",
      "/Users/nikulnayi/opt/anaconda3/lib/python3.9/site-packages/sklearn/model_selection/_validation.py:770: UserWarning: Scoring failed. The score on this train-test partition for these parameters will be set to nan. Details: \n",
      "Traceback (most recent call last):\n",
      "  File \"/Users/nikulnayi/opt/anaconda3/lib/python3.9/site-packages/sklearn/model_selection/_validation.py\", line 761, in _score\n",
      "    scores = scorer(estimator, X_test, y_test)\n",
      "  File \"/Users/nikulnayi/opt/anaconda3/lib/python3.9/site-packages/sklearn/metrics/_scorer.py\", line 216, in __call__\n",
      "    return self._score(\n",
      "  File \"/Users/nikulnayi/opt/anaconda3/lib/python3.9/site-packages/sklearn/metrics/_scorer.py\", line 264, in _score\n",
      "    return self._sign * self._score_func(y_true, y_pred, **self._kwargs)\n",
      "  File \"/Users/nikulnayi/opt/anaconda3/lib/python3.9/site-packages/sklearn/metrics/_classification.py\", line 1901, in recall_score\n",
      "    _, r, _, _ = precision_recall_fscore_support(\n",
      "  File \"/Users/nikulnayi/opt/anaconda3/lib/python3.9/site-packages/sklearn/metrics/_classification.py\", line 1544, in precision_recall_fscore_support\n",
      "    labels = _check_set_wise_labels(y_true, y_pred, average, labels, pos_label)\n",
      "  File \"/Users/nikulnayi/opt/anaconda3/lib/python3.9/site-packages/sklearn/metrics/_classification.py\", line 1348, in _check_set_wise_labels\n",
      "    y_type, y_true, y_pred = _check_targets(y_true, y_pred)\n",
      "  File \"/Users/nikulnayi/opt/anaconda3/lib/python3.9/site-packages/sklearn/metrics/_classification.py\", line 84, in _check_targets\n",
      "    check_consistent_length(y_true, y_pred)\n",
      "  File \"/Users/nikulnayi/opt/anaconda3/lib/python3.9/site-packages/sklearn/utils/validation.py\", line 332, in check_consistent_length\n",
      "    raise ValueError(\n",
      "ValueError: Found input variables with inconsistent numbers of samples: [5166, 10332]\n",
      "\n",
      "  warnings.warn(\n",
      "/Users/nikulnayi/opt/anaconda3/lib/python3.9/site-packages/sklearn/model_selection/_validation.py:770: UserWarning: Scoring failed. The score on this train-test partition for these parameters will be set to nan. Details: \n",
      "Traceback (most recent call last):\n",
      "  File \"/Users/nikulnayi/opt/anaconda3/lib/python3.9/site-packages/sklearn/model_selection/_validation.py\", line 761, in _score\n",
      "    scores = scorer(estimator, X_test, y_test)\n",
      "  File \"/Users/nikulnayi/opt/anaconda3/lib/python3.9/site-packages/sklearn/metrics/_scorer.py\", line 216, in __call__\n",
      "    return self._score(\n",
      "  File \"/Users/nikulnayi/opt/anaconda3/lib/python3.9/site-packages/sklearn/metrics/_scorer.py\", line 264, in _score\n",
      "    return self._sign * self._score_func(y_true, y_pred, **self._kwargs)\n",
      "  File \"/Users/nikulnayi/opt/anaconda3/lib/python3.9/site-packages/sklearn/metrics/_classification.py\", line 1901, in recall_score\n",
      "    _, r, _, _ = precision_recall_fscore_support(\n",
      "  File \"/Users/nikulnayi/opt/anaconda3/lib/python3.9/site-packages/sklearn/metrics/_classification.py\", line 1544, in precision_recall_fscore_support\n",
      "    labels = _check_set_wise_labels(y_true, y_pred, average, labels, pos_label)\n",
      "  File \"/Users/nikulnayi/opt/anaconda3/lib/python3.9/site-packages/sklearn/metrics/_classification.py\", line 1348, in _check_set_wise_labels\n",
      "    y_type, y_true, y_pred = _check_targets(y_true, y_pred)\n",
      "  File \"/Users/nikulnayi/opt/anaconda3/lib/python3.9/site-packages/sklearn/metrics/_classification.py\", line 84, in _check_targets\n",
      "    check_consistent_length(y_true, y_pred)\n",
      "  File \"/Users/nikulnayi/opt/anaconda3/lib/python3.9/site-packages/sklearn/utils/validation.py\", line 332, in check_consistent_length\n",
      "    raise ValueError(\n",
      "ValueError: Found input variables with inconsistent numbers of samples: [5166, 10332]\n",
      "\n",
      "  warnings.warn(\n",
      "/Users/nikulnayi/opt/anaconda3/lib/python3.9/site-packages/sklearn/model_selection/_validation.py:770: UserWarning: Scoring failed. The score on this train-test partition for these parameters will be set to nan. Details: \n",
      "Traceback (most recent call last):\n",
      "  File \"/Users/nikulnayi/opt/anaconda3/lib/python3.9/site-packages/sklearn/model_selection/_validation.py\", line 761, in _score\n",
      "    scores = scorer(estimator, X_test, y_test)\n",
      "  File \"/Users/nikulnayi/opt/anaconda3/lib/python3.9/site-packages/sklearn/metrics/_scorer.py\", line 216, in __call__\n",
      "    return self._score(\n",
      "  File \"/Users/nikulnayi/opt/anaconda3/lib/python3.9/site-packages/sklearn/metrics/_scorer.py\", line 264, in _score\n",
      "    return self._sign * self._score_func(y_true, y_pred, **self._kwargs)\n",
      "  File \"/Users/nikulnayi/opt/anaconda3/lib/python3.9/site-packages/sklearn/metrics/_classification.py\", line 1901, in recall_score\n",
      "    _, r, _, _ = precision_recall_fscore_support(\n",
      "  File \"/Users/nikulnayi/opt/anaconda3/lib/python3.9/site-packages/sklearn/metrics/_classification.py\", line 1544, in precision_recall_fscore_support\n",
      "    labels = _check_set_wise_labels(y_true, y_pred, average, labels, pos_label)\n",
      "  File \"/Users/nikulnayi/opt/anaconda3/lib/python3.9/site-packages/sklearn/metrics/_classification.py\", line 1348, in _check_set_wise_labels\n",
      "    y_type, y_true, y_pred = _check_targets(y_true, y_pred)\n",
      "  File \"/Users/nikulnayi/opt/anaconda3/lib/python3.9/site-packages/sklearn/metrics/_classification.py\", line 84, in _check_targets\n",
      "    check_consistent_length(y_true, y_pred)\n",
      "  File \"/Users/nikulnayi/opt/anaconda3/lib/python3.9/site-packages/sklearn/utils/validation.py\", line 332, in check_consistent_length\n",
      "    raise ValueError(\n",
      "ValueError: Found input variables with inconsistent numbers of samples: [5166, 10332]\n",
      "\n",
      "  warnings.warn(\n",
      "/Users/nikulnayi/opt/anaconda3/lib/python3.9/site-packages/sklearn/model_selection/_validation.py:770: UserWarning: Scoring failed. The score on this train-test partition for these parameters will be set to nan. Details: \n",
      "Traceback (most recent call last):\n",
      "  File \"/Users/nikulnayi/opt/anaconda3/lib/python3.9/site-packages/sklearn/model_selection/_validation.py\", line 761, in _score\n",
      "    scores = scorer(estimator, X_test, y_test)\n",
      "  File \"/Users/nikulnayi/opt/anaconda3/lib/python3.9/site-packages/sklearn/metrics/_scorer.py\", line 216, in __call__\n",
      "    return self._score(\n",
      "  File \"/Users/nikulnayi/opt/anaconda3/lib/python3.9/site-packages/sklearn/metrics/_scorer.py\", line 264, in _score\n",
      "    return self._sign * self._score_func(y_true, y_pred, **self._kwargs)\n",
      "  File \"/Users/nikulnayi/opt/anaconda3/lib/python3.9/site-packages/sklearn/metrics/_classification.py\", line 1901, in recall_score\n",
      "    _, r, _, _ = precision_recall_fscore_support(\n",
      "  File \"/Users/nikulnayi/opt/anaconda3/lib/python3.9/site-packages/sklearn/metrics/_classification.py\", line 1544, in precision_recall_fscore_support\n",
      "    labels = _check_set_wise_labels(y_true, y_pred, average, labels, pos_label)\n",
      "  File \"/Users/nikulnayi/opt/anaconda3/lib/python3.9/site-packages/sklearn/metrics/_classification.py\", line 1348, in _check_set_wise_labels\n",
      "    y_type, y_true, y_pred = _check_targets(y_true, y_pred)\n",
      "  File \"/Users/nikulnayi/opt/anaconda3/lib/python3.9/site-packages/sklearn/metrics/_classification.py\", line 84, in _check_targets\n",
      "    check_consistent_length(y_true, y_pred)\n",
      "  File \"/Users/nikulnayi/opt/anaconda3/lib/python3.9/site-packages/sklearn/utils/validation.py\", line 332, in check_consistent_length\n",
      "    raise ValueError(\n",
      "ValueError: Found input variables with inconsistent numbers of samples: [5166, 10332]\n",
      "\n",
      "  warnings.warn(\n"
     ]
    },
    {
     "name": "stderr",
     "output_type": "stream",
     "text": [
      "/Users/nikulnayi/opt/anaconda3/lib/python3.9/site-packages/sklearn/model_selection/_validation.py:770: UserWarning: Scoring failed. The score on this train-test partition for these parameters will be set to nan. Details: \n",
      "Traceback (most recent call last):\n",
      "  File \"/Users/nikulnayi/opt/anaconda3/lib/python3.9/site-packages/sklearn/model_selection/_validation.py\", line 761, in _score\n",
      "    scores = scorer(estimator, X_test, y_test)\n",
      "  File \"/Users/nikulnayi/opt/anaconda3/lib/python3.9/site-packages/sklearn/metrics/_scorer.py\", line 216, in __call__\n",
      "    return self._score(\n",
      "  File \"/Users/nikulnayi/opt/anaconda3/lib/python3.9/site-packages/sklearn/metrics/_scorer.py\", line 264, in _score\n",
      "    return self._sign * self._score_func(y_true, y_pred, **self._kwargs)\n",
      "  File \"/Users/nikulnayi/opt/anaconda3/lib/python3.9/site-packages/sklearn/metrics/_classification.py\", line 1901, in recall_score\n",
      "    _, r, _, _ = precision_recall_fscore_support(\n",
      "  File \"/Users/nikulnayi/opt/anaconda3/lib/python3.9/site-packages/sklearn/metrics/_classification.py\", line 1544, in precision_recall_fscore_support\n",
      "    labels = _check_set_wise_labels(y_true, y_pred, average, labels, pos_label)\n",
      "  File \"/Users/nikulnayi/opt/anaconda3/lib/python3.9/site-packages/sklearn/metrics/_classification.py\", line 1348, in _check_set_wise_labels\n",
      "    y_type, y_true, y_pred = _check_targets(y_true, y_pred)\n",
      "  File \"/Users/nikulnayi/opt/anaconda3/lib/python3.9/site-packages/sklearn/metrics/_classification.py\", line 84, in _check_targets\n",
      "    check_consistent_length(y_true, y_pred)\n",
      "  File \"/Users/nikulnayi/opt/anaconda3/lib/python3.9/site-packages/sklearn/utils/validation.py\", line 332, in check_consistent_length\n",
      "    raise ValueError(\n",
      "ValueError: Found input variables with inconsistent numbers of samples: [5166, 10332]\n",
      "\n",
      "  warnings.warn(\n",
      "/Users/nikulnayi/opt/anaconda3/lib/python3.9/site-packages/sklearn/model_selection/_validation.py:770: UserWarning: Scoring failed. The score on this train-test partition for these parameters will be set to nan. Details: \n",
      "Traceback (most recent call last):\n",
      "  File \"/Users/nikulnayi/opt/anaconda3/lib/python3.9/site-packages/sklearn/model_selection/_validation.py\", line 761, in _score\n",
      "    scores = scorer(estimator, X_test, y_test)\n",
      "  File \"/Users/nikulnayi/opt/anaconda3/lib/python3.9/site-packages/sklearn/metrics/_scorer.py\", line 216, in __call__\n",
      "    return self._score(\n",
      "  File \"/Users/nikulnayi/opt/anaconda3/lib/python3.9/site-packages/sklearn/metrics/_scorer.py\", line 264, in _score\n",
      "    return self._sign * self._score_func(y_true, y_pred, **self._kwargs)\n",
      "  File \"/Users/nikulnayi/opt/anaconda3/lib/python3.9/site-packages/sklearn/metrics/_classification.py\", line 1901, in recall_score\n",
      "    _, r, _, _ = precision_recall_fscore_support(\n",
      "  File \"/Users/nikulnayi/opt/anaconda3/lib/python3.9/site-packages/sklearn/metrics/_classification.py\", line 1544, in precision_recall_fscore_support\n",
      "    labels = _check_set_wise_labels(y_true, y_pred, average, labels, pos_label)\n",
      "  File \"/Users/nikulnayi/opt/anaconda3/lib/python3.9/site-packages/sklearn/metrics/_classification.py\", line 1348, in _check_set_wise_labels\n",
      "    y_type, y_true, y_pred = _check_targets(y_true, y_pred)\n",
      "  File \"/Users/nikulnayi/opt/anaconda3/lib/python3.9/site-packages/sklearn/metrics/_classification.py\", line 84, in _check_targets\n",
      "    check_consistent_length(y_true, y_pred)\n",
      "  File \"/Users/nikulnayi/opt/anaconda3/lib/python3.9/site-packages/sklearn/utils/validation.py\", line 332, in check_consistent_length\n",
      "    raise ValueError(\n",
      "ValueError: Found input variables with inconsistent numbers of samples: [5166, 10332]\n",
      "\n",
      "  warnings.warn(\n",
      "/Users/nikulnayi/opt/anaconda3/lib/python3.9/site-packages/sklearn/model_selection/_validation.py:770: UserWarning: Scoring failed. The score on this train-test partition for these parameters will be set to nan. Details: \n",
      "Traceback (most recent call last):\n",
      "  File \"/Users/nikulnayi/opt/anaconda3/lib/python3.9/site-packages/sklearn/model_selection/_validation.py\", line 761, in _score\n",
      "    scores = scorer(estimator, X_test, y_test)\n",
      "  File \"/Users/nikulnayi/opt/anaconda3/lib/python3.9/site-packages/sklearn/metrics/_scorer.py\", line 216, in __call__\n",
      "    return self._score(\n",
      "  File \"/Users/nikulnayi/opt/anaconda3/lib/python3.9/site-packages/sklearn/metrics/_scorer.py\", line 264, in _score\n",
      "    return self._sign * self._score_func(y_true, y_pred, **self._kwargs)\n",
      "  File \"/Users/nikulnayi/opt/anaconda3/lib/python3.9/site-packages/sklearn/metrics/_classification.py\", line 1901, in recall_score\n",
      "    _, r, _, _ = precision_recall_fscore_support(\n",
      "  File \"/Users/nikulnayi/opt/anaconda3/lib/python3.9/site-packages/sklearn/metrics/_classification.py\", line 1544, in precision_recall_fscore_support\n",
      "    labels = _check_set_wise_labels(y_true, y_pred, average, labels, pos_label)\n",
      "  File \"/Users/nikulnayi/opt/anaconda3/lib/python3.9/site-packages/sklearn/metrics/_classification.py\", line 1348, in _check_set_wise_labels\n",
      "    y_type, y_true, y_pred = _check_targets(y_true, y_pred)\n",
      "  File \"/Users/nikulnayi/opt/anaconda3/lib/python3.9/site-packages/sklearn/metrics/_classification.py\", line 84, in _check_targets\n",
      "    check_consistent_length(y_true, y_pred)\n",
      "  File \"/Users/nikulnayi/opt/anaconda3/lib/python3.9/site-packages/sklearn/utils/validation.py\", line 332, in check_consistent_length\n",
      "    raise ValueError(\n",
      "ValueError: Found input variables with inconsistent numbers of samples: [5166, 10332]\n",
      "\n",
      "  warnings.warn(\n",
      "/Users/nikulnayi/opt/anaconda3/lib/python3.9/site-packages/sklearn/model_selection/_validation.py:770: UserWarning: Scoring failed. The score on this train-test partition for these parameters will be set to nan. Details: \n",
      "Traceback (most recent call last):\n",
      "  File \"/Users/nikulnayi/opt/anaconda3/lib/python3.9/site-packages/sklearn/model_selection/_validation.py\", line 761, in _score\n",
      "    scores = scorer(estimator, X_test, y_test)\n",
      "  File \"/Users/nikulnayi/opt/anaconda3/lib/python3.9/site-packages/sklearn/metrics/_scorer.py\", line 216, in __call__\n",
      "    return self._score(\n",
      "  File \"/Users/nikulnayi/opt/anaconda3/lib/python3.9/site-packages/sklearn/metrics/_scorer.py\", line 264, in _score\n",
      "    return self._sign * self._score_func(y_true, y_pred, **self._kwargs)\n",
      "  File \"/Users/nikulnayi/opt/anaconda3/lib/python3.9/site-packages/sklearn/metrics/_classification.py\", line 1901, in recall_score\n",
      "    _, r, _, _ = precision_recall_fscore_support(\n",
      "  File \"/Users/nikulnayi/opt/anaconda3/lib/python3.9/site-packages/sklearn/metrics/_classification.py\", line 1544, in precision_recall_fscore_support\n",
      "    labels = _check_set_wise_labels(y_true, y_pred, average, labels, pos_label)\n",
      "  File \"/Users/nikulnayi/opt/anaconda3/lib/python3.9/site-packages/sklearn/metrics/_classification.py\", line 1348, in _check_set_wise_labels\n",
      "    y_type, y_true, y_pred = _check_targets(y_true, y_pred)\n",
      "  File \"/Users/nikulnayi/opt/anaconda3/lib/python3.9/site-packages/sklearn/metrics/_classification.py\", line 84, in _check_targets\n",
      "    check_consistent_length(y_true, y_pred)\n",
      "  File \"/Users/nikulnayi/opt/anaconda3/lib/python3.9/site-packages/sklearn/utils/validation.py\", line 332, in check_consistent_length\n",
      "    raise ValueError(\n",
      "ValueError: Found input variables with inconsistent numbers of samples: [5166, 10332]\n",
      "\n",
      "  warnings.warn(\n",
      "/Users/nikulnayi/opt/anaconda3/lib/python3.9/site-packages/sklearn/model_selection/_validation.py:770: UserWarning: Scoring failed. The score on this train-test partition for these parameters will be set to nan. Details: \n",
      "Traceback (most recent call last):\n",
      "  File \"/Users/nikulnayi/opt/anaconda3/lib/python3.9/site-packages/sklearn/model_selection/_validation.py\", line 761, in _score\n",
      "    scores = scorer(estimator, X_test, y_test)\n",
      "  File \"/Users/nikulnayi/opt/anaconda3/lib/python3.9/site-packages/sklearn/metrics/_scorer.py\", line 216, in __call__\n",
      "    return self._score(\n",
      "  File \"/Users/nikulnayi/opt/anaconda3/lib/python3.9/site-packages/sklearn/metrics/_scorer.py\", line 264, in _score\n",
      "    return self._sign * self._score_func(y_true, y_pred, **self._kwargs)\n",
      "  File \"/Users/nikulnayi/opt/anaconda3/lib/python3.9/site-packages/sklearn/metrics/_classification.py\", line 1901, in recall_score\n",
      "    _, r, _, _ = precision_recall_fscore_support(\n",
      "  File \"/Users/nikulnayi/opt/anaconda3/lib/python3.9/site-packages/sklearn/metrics/_classification.py\", line 1544, in precision_recall_fscore_support\n",
      "    labels = _check_set_wise_labels(y_true, y_pred, average, labels, pos_label)\n",
      "  File \"/Users/nikulnayi/opt/anaconda3/lib/python3.9/site-packages/sklearn/metrics/_classification.py\", line 1348, in _check_set_wise_labels\n",
      "    y_type, y_true, y_pred = _check_targets(y_true, y_pred)\n",
      "  File \"/Users/nikulnayi/opt/anaconda3/lib/python3.9/site-packages/sklearn/metrics/_classification.py\", line 84, in _check_targets\n",
      "    check_consistent_length(y_true, y_pred)\n",
      "  File \"/Users/nikulnayi/opt/anaconda3/lib/python3.9/site-packages/sklearn/utils/validation.py\", line 332, in check_consistent_length\n",
      "    raise ValueError(\n",
      "ValueError: Found input variables with inconsistent numbers of samples: [5166, 10332]\n",
      "\n",
      "  warnings.warn(\n",
      "/Users/nikulnayi/opt/anaconda3/lib/python3.9/site-packages/sklearn/model_selection/_validation.py:770: UserWarning: Scoring failed. The score on this train-test partition for these parameters will be set to nan. Details: \n",
      "Traceback (most recent call last):\n",
      "  File \"/Users/nikulnayi/opt/anaconda3/lib/python3.9/site-packages/sklearn/model_selection/_validation.py\", line 761, in _score\n",
      "    scores = scorer(estimator, X_test, y_test)\n",
      "  File \"/Users/nikulnayi/opt/anaconda3/lib/python3.9/site-packages/sklearn/metrics/_scorer.py\", line 216, in __call__\n",
      "    return self._score(\n",
      "  File \"/Users/nikulnayi/opt/anaconda3/lib/python3.9/site-packages/sklearn/metrics/_scorer.py\", line 264, in _score\n",
      "    return self._sign * self._score_func(y_true, y_pred, **self._kwargs)\n",
      "  File \"/Users/nikulnayi/opt/anaconda3/lib/python3.9/site-packages/sklearn/metrics/_classification.py\", line 1901, in recall_score\n",
      "    _, r, _, _ = precision_recall_fscore_support(\n",
      "  File \"/Users/nikulnayi/opt/anaconda3/lib/python3.9/site-packages/sklearn/metrics/_classification.py\", line 1544, in precision_recall_fscore_support\n",
      "    labels = _check_set_wise_labels(y_true, y_pred, average, labels, pos_label)\n",
      "  File \"/Users/nikulnayi/opt/anaconda3/lib/python3.9/site-packages/sklearn/metrics/_classification.py\", line 1348, in _check_set_wise_labels\n",
      "    y_type, y_true, y_pred = _check_targets(y_true, y_pred)\n",
      "  File \"/Users/nikulnayi/opt/anaconda3/lib/python3.9/site-packages/sklearn/metrics/_classification.py\", line 84, in _check_targets\n",
      "    check_consistent_length(y_true, y_pred)\n",
      "  File \"/Users/nikulnayi/opt/anaconda3/lib/python3.9/site-packages/sklearn/utils/validation.py\", line 332, in check_consistent_length\n",
      "    raise ValueError(\n",
      "ValueError: Found input variables with inconsistent numbers of samples: [5166, 10332]\n",
      "\n",
      "  warnings.warn(\n"
     ]
    },
    {
     "name": "stderr",
     "output_type": "stream",
     "text": [
      "/Users/nikulnayi/opt/anaconda3/lib/python3.9/site-packages/sklearn/model_selection/_validation.py:770: UserWarning: Scoring failed. The score on this train-test partition for these parameters will be set to nan. Details: \n",
      "Traceback (most recent call last):\n",
      "  File \"/Users/nikulnayi/opt/anaconda3/lib/python3.9/site-packages/sklearn/model_selection/_validation.py\", line 761, in _score\n",
      "    scores = scorer(estimator, X_test, y_test)\n",
      "  File \"/Users/nikulnayi/opt/anaconda3/lib/python3.9/site-packages/sklearn/metrics/_scorer.py\", line 216, in __call__\n",
      "    return self._score(\n",
      "  File \"/Users/nikulnayi/opt/anaconda3/lib/python3.9/site-packages/sklearn/metrics/_scorer.py\", line 264, in _score\n",
      "    return self._sign * self._score_func(y_true, y_pred, **self._kwargs)\n",
      "  File \"/Users/nikulnayi/opt/anaconda3/lib/python3.9/site-packages/sklearn/metrics/_classification.py\", line 1901, in recall_score\n",
      "    _, r, _, _ = precision_recall_fscore_support(\n",
      "  File \"/Users/nikulnayi/opt/anaconda3/lib/python3.9/site-packages/sklearn/metrics/_classification.py\", line 1544, in precision_recall_fscore_support\n",
      "    labels = _check_set_wise_labels(y_true, y_pred, average, labels, pos_label)\n",
      "  File \"/Users/nikulnayi/opt/anaconda3/lib/python3.9/site-packages/sklearn/metrics/_classification.py\", line 1348, in _check_set_wise_labels\n",
      "    y_type, y_true, y_pred = _check_targets(y_true, y_pred)\n",
      "  File \"/Users/nikulnayi/opt/anaconda3/lib/python3.9/site-packages/sklearn/metrics/_classification.py\", line 84, in _check_targets\n",
      "    check_consistent_length(y_true, y_pred)\n",
      "  File \"/Users/nikulnayi/opt/anaconda3/lib/python3.9/site-packages/sklearn/utils/validation.py\", line 332, in check_consistent_length\n",
      "    raise ValueError(\n",
      "ValueError: Found input variables with inconsistent numbers of samples: [5166, 10332]\n",
      "\n",
      "  warnings.warn(\n",
      "/Users/nikulnayi/opt/anaconda3/lib/python3.9/site-packages/sklearn/model_selection/_validation.py:770: UserWarning: Scoring failed. The score on this train-test partition for these parameters will be set to nan. Details: \n",
      "Traceback (most recent call last):\n",
      "  File \"/Users/nikulnayi/opt/anaconda3/lib/python3.9/site-packages/sklearn/model_selection/_validation.py\", line 761, in _score\n",
      "    scores = scorer(estimator, X_test, y_test)\n",
      "  File \"/Users/nikulnayi/opt/anaconda3/lib/python3.9/site-packages/sklearn/metrics/_scorer.py\", line 216, in __call__\n",
      "    return self._score(\n",
      "  File \"/Users/nikulnayi/opt/anaconda3/lib/python3.9/site-packages/sklearn/metrics/_scorer.py\", line 264, in _score\n",
      "    return self._sign * self._score_func(y_true, y_pred, **self._kwargs)\n",
      "  File \"/Users/nikulnayi/opt/anaconda3/lib/python3.9/site-packages/sklearn/metrics/_classification.py\", line 1901, in recall_score\n",
      "    _, r, _, _ = precision_recall_fscore_support(\n",
      "  File \"/Users/nikulnayi/opt/anaconda3/lib/python3.9/site-packages/sklearn/metrics/_classification.py\", line 1544, in precision_recall_fscore_support\n",
      "    labels = _check_set_wise_labels(y_true, y_pred, average, labels, pos_label)\n",
      "  File \"/Users/nikulnayi/opt/anaconda3/lib/python3.9/site-packages/sklearn/metrics/_classification.py\", line 1348, in _check_set_wise_labels\n",
      "    y_type, y_true, y_pred = _check_targets(y_true, y_pred)\n",
      "  File \"/Users/nikulnayi/opt/anaconda3/lib/python3.9/site-packages/sklearn/metrics/_classification.py\", line 84, in _check_targets\n",
      "    check_consistent_length(y_true, y_pred)\n",
      "  File \"/Users/nikulnayi/opt/anaconda3/lib/python3.9/site-packages/sklearn/utils/validation.py\", line 332, in check_consistent_length\n",
      "    raise ValueError(\n",
      "ValueError: Found input variables with inconsistent numbers of samples: [5166, 10332]\n",
      "\n",
      "  warnings.warn(\n",
      "/Users/nikulnayi/opt/anaconda3/lib/python3.9/site-packages/sklearn/model_selection/_validation.py:770: UserWarning: Scoring failed. The score on this train-test partition for these parameters will be set to nan. Details: \n",
      "Traceback (most recent call last):\n",
      "  File \"/Users/nikulnayi/opt/anaconda3/lib/python3.9/site-packages/sklearn/model_selection/_validation.py\", line 761, in _score\n",
      "    scores = scorer(estimator, X_test, y_test)\n",
      "  File \"/Users/nikulnayi/opt/anaconda3/lib/python3.9/site-packages/sklearn/metrics/_scorer.py\", line 216, in __call__\n",
      "    return self._score(\n",
      "  File \"/Users/nikulnayi/opt/anaconda3/lib/python3.9/site-packages/sklearn/metrics/_scorer.py\", line 264, in _score\n",
      "    return self._sign * self._score_func(y_true, y_pred, **self._kwargs)\n",
      "  File \"/Users/nikulnayi/opt/anaconda3/lib/python3.9/site-packages/sklearn/metrics/_classification.py\", line 1901, in recall_score\n",
      "    _, r, _, _ = precision_recall_fscore_support(\n",
      "  File \"/Users/nikulnayi/opt/anaconda3/lib/python3.9/site-packages/sklearn/metrics/_classification.py\", line 1544, in precision_recall_fscore_support\n",
      "    labels = _check_set_wise_labels(y_true, y_pred, average, labels, pos_label)\n",
      "  File \"/Users/nikulnayi/opt/anaconda3/lib/python3.9/site-packages/sklearn/metrics/_classification.py\", line 1348, in _check_set_wise_labels\n",
      "    y_type, y_true, y_pred = _check_targets(y_true, y_pred)\n",
      "  File \"/Users/nikulnayi/opt/anaconda3/lib/python3.9/site-packages/sklearn/metrics/_classification.py\", line 84, in _check_targets\n",
      "    check_consistent_length(y_true, y_pred)\n",
      "  File \"/Users/nikulnayi/opt/anaconda3/lib/python3.9/site-packages/sklearn/utils/validation.py\", line 332, in check_consistent_length\n",
      "    raise ValueError(\n",
      "ValueError: Found input variables with inconsistent numbers of samples: [5166, 10332]\n",
      "\n",
      "  warnings.warn(\n",
      "/Users/nikulnayi/opt/anaconda3/lib/python3.9/site-packages/sklearn/model_selection/_validation.py:770: UserWarning: Scoring failed. The score on this train-test partition for these parameters will be set to nan. Details: \n",
      "Traceback (most recent call last):\n",
      "  File \"/Users/nikulnayi/opt/anaconda3/lib/python3.9/site-packages/sklearn/model_selection/_validation.py\", line 761, in _score\n",
      "    scores = scorer(estimator, X_test, y_test)\n",
      "  File \"/Users/nikulnayi/opt/anaconda3/lib/python3.9/site-packages/sklearn/metrics/_scorer.py\", line 216, in __call__\n",
      "    return self._score(\n",
      "  File \"/Users/nikulnayi/opt/anaconda3/lib/python3.9/site-packages/sklearn/metrics/_scorer.py\", line 264, in _score\n",
      "    return self._sign * self._score_func(y_true, y_pred, **self._kwargs)\n",
      "  File \"/Users/nikulnayi/opt/anaconda3/lib/python3.9/site-packages/sklearn/metrics/_classification.py\", line 1901, in recall_score\n",
      "    _, r, _, _ = precision_recall_fscore_support(\n",
      "  File \"/Users/nikulnayi/opt/anaconda3/lib/python3.9/site-packages/sklearn/metrics/_classification.py\", line 1544, in precision_recall_fscore_support\n",
      "    labels = _check_set_wise_labels(y_true, y_pred, average, labels, pos_label)\n",
      "  File \"/Users/nikulnayi/opt/anaconda3/lib/python3.9/site-packages/sklearn/metrics/_classification.py\", line 1348, in _check_set_wise_labels\n",
      "    y_type, y_true, y_pred = _check_targets(y_true, y_pred)\n",
      "  File \"/Users/nikulnayi/opt/anaconda3/lib/python3.9/site-packages/sklearn/metrics/_classification.py\", line 84, in _check_targets\n",
      "    check_consistent_length(y_true, y_pred)\n",
      "  File \"/Users/nikulnayi/opt/anaconda3/lib/python3.9/site-packages/sklearn/utils/validation.py\", line 332, in check_consistent_length\n",
      "    raise ValueError(\n",
      "ValueError: Found input variables with inconsistent numbers of samples: [5166, 10332]\n",
      "\n",
      "  warnings.warn(\n",
      "/Users/nikulnayi/opt/anaconda3/lib/python3.9/site-packages/sklearn/model_selection/_validation.py:770: UserWarning: Scoring failed. The score on this train-test partition for these parameters will be set to nan. Details: \n",
      "Traceback (most recent call last):\n",
      "  File \"/Users/nikulnayi/opt/anaconda3/lib/python3.9/site-packages/sklearn/model_selection/_validation.py\", line 761, in _score\n",
      "    scores = scorer(estimator, X_test, y_test)\n",
      "  File \"/Users/nikulnayi/opt/anaconda3/lib/python3.9/site-packages/sklearn/metrics/_scorer.py\", line 216, in __call__\n",
      "    return self._score(\n",
      "  File \"/Users/nikulnayi/opt/anaconda3/lib/python3.9/site-packages/sklearn/metrics/_scorer.py\", line 264, in _score\n",
      "    return self._sign * self._score_func(y_true, y_pred, **self._kwargs)\n",
      "  File \"/Users/nikulnayi/opt/anaconda3/lib/python3.9/site-packages/sklearn/metrics/_classification.py\", line 1901, in recall_score\n",
      "    _, r, _, _ = precision_recall_fscore_support(\n",
      "  File \"/Users/nikulnayi/opt/anaconda3/lib/python3.9/site-packages/sklearn/metrics/_classification.py\", line 1544, in precision_recall_fscore_support\n",
      "    labels = _check_set_wise_labels(y_true, y_pred, average, labels, pos_label)\n",
      "  File \"/Users/nikulnayi/opt/anaconda3/lib/python3.9/site-packages/sklearn/metrics/_classification.py\", line 1348, in _check_set_wise_labels\n",
      "    y_type, y_true, y_pred = _check_targets(y_true, y_pred)\n",
      "  File \"/Users/nikulnayi/opt/anaconda3/lib/python3.9/site-packages/sklearn/metrics/_classification.py\", line 84, in _check_targets\n",
      "    check_consistent_length(y_true, y_pred)\n",
      "  File \"/Users/nikulnayi/opt/anaconda3/lib/python3.9/site-packages/sklearn/utils/validation.py\", line 332, in check_consistent_length\n",
      "    raise ValueError(\n",
      "ValueError: Found input variables with inconsistent numbers of samples: [5166, 10332]\n",
      "\n",
      "  warnings.warn(\n"
     ]
    },
    {
     "name": "stderr",
     "output_type": "stream",
     "text": [
      "/Users/nikulnayi/opt/anaconda3/lib/python3.9/site-packages/sklearn/model_selection/_validation.py:770: UserWarning: Scoring failed. The score on this train-test partition for these parameters will be set to nan. Details: \n",
      "Traceback (most recent call last):\n",
      "  File \"/Users/nikulnayi/opt/anaconda3/lib/python3.9/site-packages/sklearn/model_selection/_validation.py\", line 761, in _score\n",
      "    scores = scorer(estimator, X_test, y_test)\n",
      "  File \"/Users/nikulnayi/opt/anaconda3/lib/python3.9/site-packages/sklearn/metrics/_scorer.py\", line 216, in __call__\n",
      "    return self._score(\n",
      "  File \"/Users/nikulnayi/opt/anaconda3/lib/python3.9/site-packages/sklearn/metrics/_scorer.py\", line 264, in _score\n",
      "    return self._sign * self._score_func(y_true, y_pred, **self._kwargs)\n",
      "  File \"/Users/nikulnayi/opt/anaconda3/lib/python3.9/site-packages/sklearn/metrics/_classification.py\", line 1901, in recall_score\n",
      "    _, r, _, _ = precision_recall_fscore_support(\n",
      "  File \"/Users/nikulnayi/opt/anaconda3/lib/python3.9/site-packages/sklearn/metrics/_classification.py\", line 1544, in precision_recall_fscore_support\n",
      "    labels = _check_set_wise_labels(y_true, y_pred, average, labels, pos_label)\n",
      "  File \"/Users/nikulnayi/opt/anaconda3/lib/python3.9/site-packages/sklearn/metrics/_classification.py\", line 1348, in _check_set_wise_labels\n",
      "    y_type, y_true, y_pred = _check_targets(y_true, y_pred)\n",
      "  File \"/Users/nikulnayi/opt/anaconda3/lib/python3.9/site-packages/sklearn/metrics/_classification.py\", line 84, in _check_targets\n",
      "    check_consistent_length(y_true, y_pred)\n",
      "  File \"/Users/nikulnayi/opt/anaconda3/lib/python3.9/site-packages/sklearn/utils/validation.py\", line 332, in check_consistent_length\n",
      "    raise ValueError(\n",
      "ValueError: Found input variables with inconsistent numbers of samples: [5166, 10332]\n",
      "\n",
      "  warnings.warn(\n",
      "/Users/nikulnayi/opt/anaconda3/lib/python3.9/site-packages/sklearn/model_selection/_validation.py:770: UserWarning: Scoring failed. The score on this train-test partition for these parameters will be set to nan. Details: \n",
      "Traceback (most recent call last):\n",
      "  File \"/Users/nikulnayi/opt/anaconda3/lib/python3.9/site-packages/sklearn/model_selection/_validation.py\", line 761, in _score\n",
      "    scores = scorer(estimator, X_test, y_test)\n",
      "  File \"/Users/nikulnayi/opt/anaconda3/lib/python3.9/site-packages/sklearn/metrics/_scorer.py\", line 216, in __call__\n",
      "    return self._score(\n",
      "  File \"/Users/nikulnayi/opt/anaconda3/lib/python3.9/site-packages/sklearn/metrics/_scorer.py\", line 264, in _score\n",
      "    return self._sign * self._score_func(y_true, y_pred, **self._kwargs)\n",
      "  File \"/Users/nikulnayi/opt/anaconda3/lib/python3.9/site-packages/sklearn/metrics/_classification.py\", line 1901, in recall_score\n",
      "    _, r, _, _ = precision_recall_fscore_support(\n",
      "  File \"/Users/nikulnayi/opt/anaconda3/lib/python3.9/site-packages/sklearn/metrics/_classification.py\", line 1544, in precision_recall_fscore_support\n",
      "    labels = _check_set_wise_labels(y_true, y_pred, average, labels, pos_label)\n",
      "  File \"/Users/nikulnayi/opt/anaconda3/lib/python3.9/site-packages/sklearn/metrics/_classification.py\", line 1348, in _check_set_wise_labels\n",
      "    y_type, y_true, y_pred = _check_targets(y_true, y_pred)\n",
      "  File \"/Users/nikulnayi/opt/anaconda3/lib/python3.9/site-packages/sklearn/metrics/_classification.py\", line 84, in _check_targets\n",
      "    check_consistent_length(y_true, y_pred)\n",
      "  File \"/Users/nikulnayi/opt/anaconda3/lib/python3.9/site-packages/sklearn/utils/validation.py\", line 332, in check_consistent_length\n",
      "    raise ValueError(\n",
      "ValueError: Found input variables with inconsistent numbers of samples: [5166, 10332]\n",
      "\n",
      "  warnings.warn(\n",
      "/Users/nikulnayi/opt/anaconda3/lib/python3.9/site-packages/sklearn/model_selection/_validation.py:770: UserWarning: Scoring failed. The score on this train-test partition for these parameters will be set to nan. Details: \n",
      "Traceback (most recent call last):\n",
      "  File \"/Users/nikulnayi/opt/anaconda3/lib/python3.9/site-packages/sklearn/model_selection/_validation.py\", line 761, in _score\n",
      "    scores = scorer(estimator, X_test, y_test)\n",
      "  File \"/Users/nikulnayi/opt/anaconda3/lib/python3.9/site-packages/sklearn/metrics/_scorer.py\", line 216, in __call__\n",
      "    return self._score(\n",
      "  File \"/Users/nikulnayi/opt/anaconda3/lib/python3.9/site-packages/sklearn/metrics/_scorer.py\", line 264, in _score\n",
      "    return self._sign * self._score_func(y_true, y_pred, **self._kwargs)\n",
      "  File \"/Users/nikulnayi/opt/anaconda3/lib/python3.9/site-packages/sklearn/metrics/_classification.py\", line 1901, in recall_score\n",
      "    _, r, _, _ = precision_recall_fscore_support(\n",
      "  File \"/Users/nikulnayi/opt/anaconda3/lib/python3.9/site-packages/sklearn/metrics/_classification.py\", line 1544, in precision_recall_fscore_support\n",
      "    labels = _check_set_wise_labels(y_true, y_pred, average, labels, pos_label)\n",
      "  File \"/Users/nikulnayi/opt/anaconda3/lib/python3.9/site-packages/sklearn/metrics/_classification.py\", line 1348, in _check_set_wise_labels\n",
      "    y_type, y_true, y_pred = _check_targets(y_true, y_pred)\n",
      "  File \"/Users/nikulnayi/opt/anaconda3/lib/python3.9/site-packages/sklearn/metrics/_classification.py\", line 84, in _check_targets\n",
      "    check_consistent_length(y_true, y_pred)\n",
      "  File \"/Users/nikulnayi/opt/anaconda3/lib/python3.9/site-packages/sklearn/utils/validation.py\", line 332, in check_consistent_length\n",
      "    raise ValueError(\n",
      "ValueError: Found input variables with inconsistent numbers of samples: [5166, 10332]\n",
      "\n",
      "  warnings.warn(\n",
      "/Users/nikulnayi/opt/anaconda3/lib/python3.9/site-packages/sklearn/model_selection/_validation.py:770: UserWarning: Scoring failed. The score on this train-test partition for these parameters will be set to nan. Details: \n",
      "Traceback (most recent call last):\n",
      "  File \"/Users/nikulnayi/opt/anaconda3/lib/python3.9/site-packages/sklearn/model_selection/_validation.py\", line 761, in _score\n",
      "    scores = scorer(estimator, X_test, y_test)\n",
      "  File \"/Users/nikulnayi/opt/anaconda3/lib/python3.9/site-packages/sklearn/metrics/_scorer.py\", line 216, in __call__\n",
      "    return self._score(\n",
      "  File \"/Users/nikulnayi/opt/anaconda3/lib/python3.9/site-packages/sklearn/metrics/_scorer.py\", line 264, in _score\n",
      "    return self._sign * self._score_func(y_true, y_pred, **self._kwargs)\n",
      "  File \"/Users/nikulnayi/opt/anaconda3/lib/python3.9/site-packages/sklearn/metrics/_classification.py\", line 1901, in recall_score\n",
      "    _, r, _, _ = precision_recall_fscore_support(\n",
      "  File \"/Users/nikulnayi/opt/anaconda3/lib/python3.9/site-packages/sklearn/metrics/_classification.py\", line 1544, in precision_recall_fscore_support\n",
      "    labels = _check_set_wise_labels(y_true, y_pred, average, labels, pos_label)\n",
      "  File \"/Users/nikulnayi/opt/anaconda3/lib/python3.9/site-packages/sklearn/metrics/_classification.py\", line 1348, in _check_set_wise_labels\n",
      "    y_type, y_true, y_pred = _check_targets(y_true, y_pred)\n",
      "  File \"/Users/nikulnayi/opt/anaconda3/lib/python3.9/site-packages/sklearn/metrics/_classification.py\", line 84, in _check_targets\n",
      "    check_consistent_length(y_true, y_pred)\n",
      "  File \"/Users/nikulnayi/opt/anaconda3/lib/python3.9/site-packages/sklearn/utils/validation.py\", line 332, in check_consistent_length\n",
      "    raise ValueError(\n",
      "ValueError: Found input variables with inconsistent numbers of samples: [5166, 10332]\n",
      "\n",
      "  warnings.warn(\n",
      "/Users/nikulnayi/opt/anaconda3/lib/python3.9/site-packages/sklearn/model_selection/_validation.py:770: UserWarning: Scoring failed. The score on this train-test partition for these parameters will be set to nan. Details: \n",
      "Traceback (most recent call last):\n",
      "  File \"/Users/nikulnayi/opt/anaconda3/lib/python3.9/site-packages/sklearn/model_selection/_validation.py\", line 761, in _score\n",
      "    scores = scorer(estimator, X_test, y_test)\n",
      "  File \"/Users/nikulnayi/opt/anaconda3/lib/python3.9/site-packages/sklearn/metrics/_scorer.py\", line 216, in __call__\n",
      "    return self._score(\n",
      "  File \"/Users/nikulnayi/opt/anaconda3/lib/python3.9/site-packages/sklearn/metrics/_scorer.py\", line 264, in _score\n",
      "    return self._sign * self._score_func(y_true, y_pred, **self._kwargs)\n",
      "  File \"/Users/nikulnayi/opt/anaconda3/lib/python3.9/site-packages/sklearn/metrics/_classification.py\", line 1901, in recall_score\n",
      "    _, r, _, _ = precision_recall_fscore_support(\n",
      "  File \"/Users/nikulnayi/opt/anaconda3/lib/python3.9/site-packages/sklearn/metrics/_classification.py\", line 1544, in precision_recall_fscore_support\n",
      "    labels = _check_set_wise_labels(y_true, y_pred, average, labels, pos_label)\n",
      "  File \"/Users/nikulnayi/opt/anaconda3/lib/python3.9/site-packages/sklearn/metrics/_classification.py\", line 1348, in _check_set_wise_labels\n",
      "    y_type, y_true, y_pred = _check_targets(y_true, y_pred)\n",
      "  File \"/Users/nikulnayi/opt/anaconda3/lib/python3.9/site-packages/sklearn/metrics/_classification.py\", line 84, in _check_targets\n",
      "    check_consistent_length(y_true, y_pred)\n",
      "  File \"/Users/nikulnayi/opt/anaconda3/lib/python3.9/site-packages/sklearn/utils/validation.py\", line 332, in check_consistent_length\n",
      "    raise ValueError(\n",
      "ValueError: Found input variables with inconsistent numbers of samples: [5166, 10332]\n",
      "\n",
      "  warnings.warn(\n"
     ]
    },
    {
     "name": "stderr",
     "output_type": "stream",
     "text": [
      "/Users/nikulnayi/opt/anaconda3/lib/python3.9/site-packages/sklearn/model_selection/_validation.py:770: UserWarning: Scoring failed. The score on this train-test partition for these parameters will be set to nan. Details: \n",
      "Traceback (most recent call last):\n",
      "  File \"/Users/nikulnayi/opt/anaconda3/lib/python3.9/site-packages/sklearn/model_selection/_validation.py\", line 761, in _score\n",
      "    scores = scorer(estimator, X_test, y_test)\n",
      "  File \"/Users/nikulnayi/opt/anaconda3/lib/python3.9/site-packages/sklearn/metrics/_scorer.py\", line 216, in __call__\n",
      "    return self._score(\n",
      "  File \"/Users/nikulnayi/opt/anaconda3/lib/python3.9/site-packages/sklearn/metrics/_scorer.py\", line 264, in _score\n",
      "    return self._sign * self._score_func(y_true, y_pred, **self._kwargs)\n",
      "  File \"/Users/nikulnayi/opt/anaconda3/lib/python3.9/site-packages/sklearn/metrics/_classification.py\", line 1901, in recall_score\n",
      "    _, r, _, _ = precision_recall_fscore_support(\n",
      "  File \"/Users/nikulnayi/opt/anaconda3/lib/python3.9/site-packages/sklearn/metrics/_classification.py\", line 1544, in precision_recall_fscore_support\n",
      "    labels = _check_set_wise_labels(y_true, y_pred, average, labels, pos_label)\n",
      "  File \"/Users/nikulnayi/opt/anaconda3/lib/python3.9/site-packages/sklearn/metrics/_classification.py\", line 1348, in _check_set_wise_labels\n",
      "    y_type, y_true, y_pred = _check_targets(y_true, y_pred)\n",
      "  File \"/Users/nikulnayi/opt/anaconda3/lib/python3.9/site-packages/sklearn/metrics/_classification.py\", line 84, in _check_targets\n",
      "    check_consistent_length(y_true, y_pred)\n",
      "  File \"/Users/nikulnayi/opt/anaconda3/lib/python3.9/site-packages/sklearn/utils/validation.py\", line 332, in check_consistent_length\n",
      "    raise ValueError(\n",
      "ValueError: Found input variables with inconsistent numbers of samples: [5166, 10332]\n",
      "\n",
      "  warnings.warn(\n",
      "/Users/nikulnayi/opt/anaconda3/lib/python3.9/site-packages/sklearn/model_selection/_validation.py:770: UserWarning: Scoring failed. The score on this train-test partition for these parameters will be set to nan. Details: \n",
      "Traceback (most recent call last):\n",
      "  File \"/Users/nikulnayi/opt/anaconda3/lib/python3.9/site-packages/sklearn/model_selection/_validation.py\", line 761, in _score\n",
      "    scores = scorer(estimator, X_test, y_test)\n",
      "  File \"/Users/nikulnayi/opt/anaconda3/lib/python3.9/site-packages/sklearn/metrics/_scorer.py\", line 216, in __call__\n",
      "    return self._score(\n",
      "  File \"/Users/nikulnayi/opt/anaconda3/lib/python3.9/site-packages/sklearn/metrics/_scorer.py\", line 264, in _score\n",
      "    return self._sign * self._score_func(y_true, y_pred, **self._kwargs)\n",
      "  File \"/Users/nikulnayi/opt/anaconda3/lib/python3.9/site-packages/sklearn/metrics/_classification.py\", line 1901, in recall_score\n",
      "    _, r, _, _ = precision_recall_fscore_support(\n",
      "  File \"/Users/nikulnayi/opt/anaconda3/lib/python3.9/site-packages/sklearn/metrics/_classification.py\", line 1544, in precision_recall_fscore_support\n",
      "    labels = _check_set_wise_labels(y_true, y_pred, average, labels, pos_label)\n",
      "  File \"/Users/nikulnayi/opt/anaconda3/lib/python3.9/site-packages/sklearn/metrics/_classification.py\", line 1348, in _check_set_wise_labels\n",
      "    y_type, y_true, y_pred = _check_targets(y_true, y_pred)\n",
      "  File \"/Users/nikulnayi/opt/anaconda3/lib/python3.9/site-packages/sklearn/metrics/_classification.py\", line 84, in _check_targets\n",
      "    check_consistent_length(y_true, y_pred)\n",
      "  File \"/Users/nikulnayi/opt/anaconda3/lib/python3.9/site-packages/sklearn/utils/validation.py\", line 332, in check_consistent_length\n",
      "    raise ValueError(\n",
      "ValueError: Found input variables with inconsistent numbers of samples: [5166, 10332]\n",
      "\n",
      "  warnings.warn(\n",
      "/Users/nikulnayi/opt/anaconda3/lib/python3.9/site-packages/sklearn/model_selection/_validation.py:770: UserWarning: Scoring failed. The score on this train-test partition for these parameters will be set to nan. Details: \n",
      "Traceback (most recent call last):\n",
      "  File \"/Users/nikulnayi/opt/anaconda3/lib/python3.9/site-packages/sklearn/model_selection/_validation.py\", line 761, in _score\n",
      "    scores = scorer(estimator, X_test, y_test)\n",
      "  File \"/Users/nikulnayi/opt/anaconda3/lib/python3.9/site-packages/sklearn/metrics/_scorer.py\", line 216, in __call__\n",
      "    return self._score(\n",
      "  File \"/Users/nikulnayi/opt/anaconda3/lib/python3.9/site-packages/sklearn/metrics/_scorer.py\", line 264, in _score\n",
      "    return self._sign * self._score_func(y_true, y_pred, **self._kwargs)\n",
      "  File \"/Users/nikulnayi/opt/anaconda3/lib/python3.9/site-packages/sklearn/metrics/_classification.py\", line 1901, in recall_score\n",
      "    _, r, _, _ = precision_recall_fscore_support(\n",
      "  File \"/Users/nikulnayi/opt/anaconda3/lib/python3.9/site-packages/sklearn/metrics/_classification.py\", line 1544, in precision_recall_fscore_support\n",
      "    labels = _check_set_wise_labels(y_true, y_pred, average, labels, pos_label)\n",
      "  File \"/Users/nikulnayi/opt/anaconda3/lib/python3.9/site-packages/sklearn/metrics/_classification.py\", line 1348, in _check_set_wise_labels\n",
      "    y_type, y_true, y_pred = _check_targets(y_true, y_pred)\n",
      "  File \"/Users/nikulnayi/opt/anaconda3/lib/python3.9/site-packages/sklearn/metrics/_classification.py\", line 84, in _check_targets\n",
      "    check_consistent_length(y_true, y_pred)\n",
      "  File \"/Users/nikulnayi/opt/anaconda3/lib/python3.9/site-packages/sklearn/utils/validation.py\", line 332, in check_consistent_length\n",
      "    raise ValueError(\n",
      "ValueError: Found input variables with inconsistent numbers of samples: [5166, 10332]\n",
      "\n",
      "  warnings.warn(\n",
      "/Users/nikulnayi/opt/anaconda3/lib/python3.9/site-packages/sklearn/model_selection/_validation.py:770: UserWarning: Scoring failed. The score on this train-test partition for these parameters will be set to nan. Details: \n",
      "Traceback (most recent call last):\n",
      "  File \"/Users/nikulnayi/opt/anaconda3/lib/python3.9/site-packages/sklearn/model_selection/_validation.py\", line 761, in _score\n",
      "    scores = scorer(estimator, X_test, y_test)\n",
      "  File \"/Users/nikulnayi/opt/anaconda3/lib/python3.9/site-packages/sklearn/metrics/_scorer.py\", line 216, in __call__\n",
      "    return self._score(\n",
      "  File \"/Users/nikulnayi/opt/anaconda3/lib/python3.9/site-packages/sklearn/metrics/_scorer.py\", line 264, in _score\n",
      "    return self._sign * self._score_func(y_true, y_pred, **self._kwargs)\n",
      "  File \"/Users/nikulnayi/opt/anaconda3/lib/python3.9/site-packages/sklearn/metrics/_classification.py\", line 1901, in recall_score\n",
      "    _, r, _, _ = precision_recall_fscore_support(\n",
      "  File \"/Users/nikulnayi/opt/anaconda3/lib/python3.9/site-packages/sklearn/metrics/_classification.py\", line 1544, in precision_recall_fscore_support\n",
      "    labels = _check_set_wise_labels(y_true, y_pred, average, labels, pos_label)\n",
      "  File \"/Users/nikulnayi/opt/anaconda3/lib/python3.9/site-packages/sklearn/metrics/_classification.py\", line 1348, in _check_set_wise_labels\n",
      "    y_type, y_true, y_pred = _check_targets(y_true, y_pred)\n",
      "  File \"/Users/nikulnayi/opt/anaconda3/lib/python3.9/site-packages/sklearn/metrics/_classification.py\", line 84, in _check_targets\n",
      "    check_consistent_length(y_true, y_pred)\n",
      "  File \"/Users/nikulnayi/opt/anaconda3/lib/python3.9/site-packages/sklearn/utils/validation.py\", line 332, in check_consistent_length\n",
      "    raise ValueError(\n",
      "ValueError: Found input variables with inconsistent numbers of samples: [5166, 10332]\n",
      "\n",
      "  warnings.warn(\n",
      "/Users/nikulnayi/opt/anaconda3/lib/python3.9/site-packages/sklearn/model_selection/_validation.py:372: FitFailedWarning: \n",
      "120 fits failed out of a total of 150.\n",
      "The score on these train-test partitions for these parameters will be set to nan.\n",
      "If these failures are not expected, you can try to debug them by setting error_score='raise'.\n",
      "\n",
      "Below are more details about the failures:\n",
      "--------------------------------------------------------------------------------\n",
      "36 fits failed with the following error:\n",
      "Traceback (most recent call last):\n",
      "  File \"/Users/nikulnayi/opt/anaconda3/lib/python3.9/site-packages/sklearn/model_selection/_validation.py\", line 680, in _fit_and_score\n",
      "    estimator.fit(X_train, y_train, **fit_params)\n",
      "  File \"/Users/nikulnayi/opt/anaconda3/lib/python3.9/site-packages/sklearn/pipeline.py\", line 394, in fit\n",
      "    self._final_estimator.fit(Xt, y, **fit_params_last_step)\n",
      "  File \"/Users/nikulnayi/opt/anaconda3/lib/python3.9/site-packages/sklearn/ensemble/_forest.py\", line 327, in fit\n",
      "    X, y = self._validate_data(\n",
      "  File \"/Users/nikulnayi/opt/anaconda3/lib/python3.9/site-packages/sklearn/base.py\", line 581, in _validate_data\n",
      "    X, y = check_X_y(X, y, **check_params)\n",
      "  File \"/Users/nikulnayi/opt/anaconda3/lib/python3.9/site-packages/sklearn/utils/validation.py\", line 981, in check_X_y\n",
      "    check_consistent_length(X, y)\n",
      "  File \"/Users/nikulnayi/opt/anaconda3/lib/python3.9/site-packages/sklearn/utils/validation.py\", line 332, in check_consistent_length\n",
      "    raise ValueError(\n",
      "ValueError: Found input variables with inconsistent numbers of samples: [25832, 20665]\n",
      "\n",
      "--------------------------------------------------------------------------------\n",
      "36 fits failed with the following error:\n",
      "Traceback (most recent call last):\n",
      "  File \"/Users/nikulnayi/opt/anaconda3/lib/python3.9/site-packages/sklearn/model_selection/_validation.py\", line 680, in _fit_and_score\n",
      "    estimator.fit(X_train, y_train, **fit_params)\n",
      "  File \"/Users/nikulnayi/opt/anaconda3/lib/python3.9/site-packages/sklearn/pipeline.py\", line 394, in fit\n",
      "    self._final_estimator.fit(Xt, y, **fit_params_last_step)\n",
      "  File \"/Users/nikulnayi/opt/anaconda3/lib/python3.9/site-packages/sklearn/ensemble/_forest.py\", line 327, in fit\n",
      "    X, y = self._validate_data(\n",
      "  File \"/Users/nikulnayi/opt/anaconda3/lib/python3.9/site-packages/sklearn/base.py\", line 581, in _validate_data\n",
      "    X, y = check_X_y(X, y, **check_params)\n",
      "  File \"/Users/nikulnayi/opt/anaconda3/lib/python3.9/site-packages/sklearn/utils/validation.py\", line 981, in check_X_y\n",
      "    check_consistent_length(X, y)\n",
      "  File \"/Users/nikulnayi/opt/anaconda3/lib/python3.9/site-packages/sklearn/utils/validation.py\", line 332, in check_consistent_length\n",
      "    raise ValueError(\n",
      "ValueError: Found input variables with inconsistent numbers of samples: [25832, 20666]\n",
      "\n",
      "--------------------------------------------------------------------------------\n",
      "2 fits failed with the following error:\n",
      "Traceback (most recent call last):\n",
      "  File \"/Users/nikulnayi/opt/anaconda3/lib/python3.9/site-packages/sklearn/model_selection/_validation.py\", line 680, in _fit_and_score\n",
      "    estimator.fit(X_train, y_train, **fit_params)\n",
      "  File \"/Users/nikulnayi/opt/anaconda3/lib/python3.9/site-packages/sklearn/pipeline.py\", line 394, in fit\n",
      "    self._final_estimator.fit(Xt, y, **fit_params_last_step)\n",
      "  File \"/Users/nikulnayi/opt/anaconda3/lib/python3.9/site-packages/xgboost/core.py\", line 620, in inner_f\n",
      "    return func(**kwargs)\n",
      "  File \"/Users/nikulnayi/opt/anaconda3/lib/python3.9/site-packages/xgboost/sklearn.py\", line 1471, in fit\n",
      "    train_dmatrix, evals = _wrap_evaluation_matrices(\n",
      "  File \"/Users/nikulnayi/opt/anaconda3/lib/python3.9/site-packages/xgboost/sklearn.py\", line 448, in _wrap_evaluation_matrices\n",
      "    train_dmatrix = create_dmatrix(\n",
      "  File \"/Users/nikulnayi/opt/anaconda3/lib/python3.9/site-packages/xgboost/sklearn.py\", line 908, in _create_dmatrix\n",
      "    return DMatrix(**kwargs, nthread=self.n_jobs)\n",
      "  File \"/Users/nikulnayi/opt/anaconda3/lib/python3.9/site-packages/xgboost/core.py\", line 620, in inner_f\n",
      "    return func(**kwargs)\n",
      "  File \"/Users/nikulnayi/opt/anaconda3/lib/python3.9/site-packages/xgboost/core.py\", line 754, in __init__\n",
      "    self.set_info(\n",
      "  File \"/Users/nikulnayi/opt/anaconda3/lib/python3.9/site-packages/xgboost/core.py\", line 620, in inner_f\n",
      "    return func(**kwargs)\n",
      "  File \"/Users/nikulnayi/opt/anaconda3/lib/python3.9/site-packages/xgboost/core.py\", line 819, in set_info\n",
      "    self.set_label(label)\n",
      "  File \"/Users/nikulnayi/opt/anaconda3/lib/python3.9/site-packages/xgboost/core.py\", line 950, in set_label\n",
      "    dispatch_meta_backend(self, label, 'label', 'float')\n",
      "  File \"/Users/nikulnayi/opt/anaconda3/lib/python3.9/site-packages/xgboost/data.py\", line 1134, in dispatch_meta_backend\n",
      "    _meta_from_pandas_series(data, name, dtype, handle)\n",
      "  File \"/Users/nikulnayi/opt/anaconda3/lib/python3.9/site-packages/xgboost/data.py\", line 443, in _meta_from_pandas_series\n",
      "    _meta_from_numpy(data, name, dtype, handle)\n",
      "  File \"/Users/nikulnayi/opt/anaconda3/lib/python3.9/site-packages/xgboost/data.py\", line 1050, in _meta_from_numpy\n",
      "    _check_call(_LIB.XGDMatrixSetInfoFromInterface(handle, c_str(field), interface_str))\n",
      "  File \"/Users/nikulnayi/opt/anaconda3/lib/python3.9/site-packages/xgboost/core.py\", line 279, in _check_call\n",
      "    raise XGBoostError(py_str(_LIB.XGBGetLastError()))\n",
      "xgboost.core.XGBoostError: [15:15:08] /Users/runner/work/xgboost/xgboost/python-package/build/temp.macosx-10.9-x86_64-cpython-38/xgboost/src/data/data.cc:455: Check failed: this->labels.Size() % this->num_row_ == 0 (20665 vs. 0) : Incorrect size for labels.\n",
      "Stack trace:\n",
      "  [bt] (0) 1   libxgboost.dylib                    0x0000000132ffeb15 dmlc::LogMessageFatal::~LogMessageFatal() + 117\n",
      "  [bt] (1) 2   libxgboost.dylib                    0x00000001330947aa xgboost::MetaInfo::SetInfoFromHost(xgboost::GenericParameter const&, xgboost::StringView, xgboost::Json) + 4282\n",
      "  [bt] (2) 3   libxgboost.dylib                    0x0000000133093602 xgboost::MetaInfo::SetInfo(xgboost::GenericParameter const&, xgboost::StringView, xgboost::StringView) + 146\n",
      "  [bt] (3) 4   libxgboost.dylib                    0x00000001330151f9 XGDMatrixSetInfoFromInterface + 233\n",
      "  [bt] (4) 5   libffi.7.dylib                      0x000000010a8c7ead ffi_call_unix64 + 85\n",
      "  [bt] (5) 6   ???                                 0x0000000303483090 0x0 + 12939964560\n",
      "\n",
      "\n",
      "\n",
      "--------------------------------------------------------------------------------\n",
      "1 fits failed with the following error:\n",
      "Traceback (most recent call last):\n",
      "  File \"/Users/nikulnayi/opt/anaconda3/lib/python3.9/site-packages/sklearn/model_selection/_validation.py\", line 680, in _fit_and_score\n",
      "    estimator.fit(X_train, y_train, **fit_params)\n",
      "  File \"/Users/nikulnayi/opt/anaconda3/lib/python3.9/site-packages/sklearn/pipeline.py\", line 394, in fit\n",
      "    self._final_estimator.fit(Xt, y, **fit_params_last_step)\n",
      "  File \"/Users/nikulnayi/opt/anaconda3/lib/python3.9/site-packages/xgboost/core.py\", line 620, in inner_f\n",
      "    return func(**kwargs)\n",
      "  File \"/Users/nikulnayi/opt/anaconda3/lib/python3.9/site-packages/xgboost/sklearn.py\", line 1471, in fit\n",
      "    train_dmatrix, evals = _wrap_evaluation_matrices(\n",
      "  File \"/Users/nikulnayi/opt/anaconda3/lib/python3.9/site-packages/xgboost/sklearn.py\", line 448, in _wrap_evaluation_matrices\n",
      "    train_dmatrix = create_dmatrix(\n",
      "  File \"/Users/nikulnayi/opt/anaconda3/lib/python3.9/site-packages/xgboost/sklearn.py\", line 908, in _create_dmatrix\n",
      "    return DMatrix(**kwargs, nthread=self.n_jobs)\n",
      "  File \"/Users/nikulnayi/opt/anaconda3/lib/python3.9/site-packages/xgboost/core.py\", line 620, in inner_f\n",
      "    return func(**kwargs)\n",
      "  File \"/Users/nikulnayi/opt/anaconda3/lib/python3.9/site-packages/xgboost/core.py\", line 754, in __init__\n",
      "    self.set_info(\n",
      "  File \"/Users/nikulnayi/opt/anaconda3/lib/python3.9/site-packages/xgboost/core.py\", line 620, in inner_f\n",
      "    return func(**kwargs)\n",
      "  File \"/Users/nikulnayi/opt/anaconda3/lib/python3.9/site-packages/xgboost/core.py\", line 819, in set_info\n",
      "    self.set_label(label)\n",
      "  File \"/Users/nikulnayi/opt/anaconda3/lib/python3.9/site-packages/xgboost/core.py\", line 950, in set_label\n",
      "    dispatch_meta_backend(self, label, 'label', 'float')\n",
      "  File \"/Users/nikulnayi/opt/anaconda3/lib/python3.9/site-packages/xgboost/data.py\", line 1134, in dispatch_meta_backend\n",
      "    _meta_from_pandas_series(data, name, dtype, handle)\n",
      "  File \"/Users/nikulnayi/opt/anaconda3/lib/python3.9/site-packages/xgboost/data.py\", line 443, in _meta_from_pandas_series\n",
      "    _meta_from_numpy(data, name, dtype, handle)\n",
      "  File \"/Users/nikulnayi/opt/anaconda3/lib/python3.9/site-packages/xgboost/data.py\", line 1050, in _meta_from_numpy\n",
      "    _check_call(_LIB.XGDMatrixSetInfoFromInterface(handle, c_str(field), interface_str))\n",
      "  File \"/Users/nikulnayi/opt/anaconda3/lib/python3.9/site-packages/xgboost/core.py\", line 279, in _check_call\n",
      "    raise XGBoostError(py_str(_LIB.XGBGetLastError()))\n",
      "xgboost.core.XGBoostError: [15:15:08] /Users/runner/work/xgboost/xgboost/python-package/build/temp.macosx-10.9-x86_64-cpython-38/xgboost/src/data/data.cc:455: Check failed: this->labels.Size() % this->num_row_ == 0 (20666 vs. 0) : Incorrect size for labels.\n",
      "Stack trace:\n",
      "  [bt] (0) 1   libxgboost.dylib                    0x0000000136c8ab15 dmlc::LogMessageFatal::~LogMessageFatal() + 117\n",
      "  [bt] (1) 2   libxgboost.dylib                    0x0000000136d207aa xgboost::MetaInfo::SetInfoFromHost(xgboost::GenericParameter const&, xgboost::StringView, xgboost::Json) + 4282\n",
      "  [bt] (2) 3   libxgboost.dylib                    0x0000000136d1f602 xgboost::MetaInfo::SetInfo(xgboost::GenericParameter const&, xgboost::StringView, xgboost::StringView) + 146\n",
      "  [bt] (3) 4   libxgboost.dylib                    0x0000000136ca11f9 XGDMatrixSetInfoFromInterface + 233\n",
      "  [bt] (4) 5   libffi.7.dylib                      0x000000010e553ead ffi_call_unix64 + 85\n",
      "  [bt] (5) 6   ???                                 0x000000030aefc090 0x0 + 13068386448\n",
      "\n",
      "\n",
      "\n",
      "--------------------------------------------------------------------------------\n",
      "3 fits failed with the following error:\n",
      "Traceback (most recent call last):\n",
      "  File \"/Users/nikulnayi/opt/anaconda3/lib/python3.9/site-packages/sklearn/model_selection/_validation.py\", line 680, in _fit_and_score\n",
      "    estimator.fit(X_train, y_train, **fit_params)\n",
      "  File \"/Users/nikulnayi/opt/anaconda3/lib/python3.9/site-packages/sklearn/pipeline.py\", line 394, in fit\n",
      "    self._final_estimator.fit(Xt, y, **fit_params_last_step)\n",
      "  File \"/Users/nikulnayi/opt/anaconda3/lib/python3.9/site-packages/xgboost/core.py\", line 620, in inner_f\n",
      "    return func(**kwargs)\n",
      "  File \"/Users/nikulnayi/opt/anaconda3/lib/python3.9/site-packages/xgboost/sklearn.py\", line 1471, in fit\n",
      "    train_dmatrix, evals = _wrap_evaluation_matrices(\n",
      "  File \"/Users/nikulnayi/opt/anaconda3/lib/python3.9/site-packages/xgboost/sklearn.py\", line 448, in _wrap_evaluation_matrices\n",
      "    train_dmatrix = create_dmatrix(\n",
      "  File \"/Users/nikulnayi/opt/anaconda3/lib/python3.9/site-packages/xgboost/sklearn.py\", line 908, in _create_dmatrix\n",
      "    return DMatrix(**kwargs, nthread=self.n_jobs)\n",
      "  File \"/Users/nikulnayi/opt/anaconda3/lib/python3.9/site-packages/xgboost/core.py\", line 620, in inner_f\n",
      "    return func(**kwargs)\n",
      "  File \"/Users/nikulnayi/opt/anaconda3/lib/python3.9/site-packages/xgboost/core.py\", line 754, in __init__\n",
      "    self.set_info(\n",
      "  File \"/Users/nikulnayi/opt/anaconda3/lib/python3.9/site-packages/xgboost/core.py\", line 620, in inner_f\n",
      "    return func(**kwargs)\n",
      "  File \"/Users/nikulnayi/opt/anaconda3/lib/python3.9/site-packages/xgboost/core.py\", line 819, in set_info\n",
      "    self.set_label(label)\n",
      "  File \"/Users/nikulnayi/opt/anaconda3/lib/python3.9/site-packages/xgboost/core.py\", line 950, in set_label\n",
      "    dispatch_meta_backend(self, label, 'label', 'float')\n",
      "  File \"/Users/nikulnayi/opt/anaconda3/lib/python3.9/site-packages/xgboost/data.py\", line 1134, in dispatch_meta_backend\n",
      "    _meta_from_pandas_series(data, name, dtype, handle)\n",
      "  File \"/Users/nikulnayi/opt/anaconda3/lib/python3.9/site-packages/xgboost/data.py\", line 443, in _meta_from_pandas_series\n",
      "    _meta_from_numpy(data, name, dtype, handle)\n",
      "  File \"/Users/nikulnayi/opt/anaconda3/lib/python3.9/site-packages/xgboost/data.py\", line 1050, in _meta_from_numpy\n",
      "    _check_call(_LIB.XGDMatrixSetInfoFromInterface(handle, c_str(field), interface_str))\n",
      "  File \"/Users/nikulnayi/opt/anaconda3/lib/python3.9/site-packages/xgboost/core.py\", line 279, in _check_call\n",
      "    raise XGBoostError(py_str(_LIB.XGBGetLastError()))\n",
      "xgboost.core.XGBoostError: [15:15:09] /Users/runner/work/xgboost/xgboost/python-package/build/temp.macosx-10.9-x86_64-cpython-38/xgboost/src/data/data.cc:455: Check failed: this->labels.Size() % this->num_row_ == 0 (20666 vs. 0) : Incorrect size for labels.\n",
      "Stack trace:\n",
      "  [bt] (0) 1   libxgboost.dylib                    0x0000000136c8ab15 dmlc::LogMessageFatal::~LogMessageFatal() + 117\n",
      "  [bt] (1) 2   libxgboost.dylib                    0x0000000136d207aa xgboost::MetaInfo::SetInfoFromHost(xgboost::GenericParameter const&, xgboost::StringView, xgboost::Json) + 4282\n",
      "  [bt] (2) 3   libxgboost.dylib                    0x0000000136d1f602 xgboost::MetaInfo::SetInfo(xgboost::GenericParameter const&, xgboost::StringView, xgboost::StringView) + 146\n",
      "  [bt] (3) 4   libxgboost.dylib                    0x0000000136ca11f9 XGDMatrixSetInfoFromInterface + 233\n",
      "  [bt] (4) 5   libffi.7.dylib                      0x000000010e553ead ffi_call_unix64 + 85\n",
      "  [bt] (5) 6   ???                                 0x000000030aefc090 0x0 + 13068386448\n",
      "\n",
      "\n",
      "\n",
      "--------------------------------------------------------------------------------\n",
      "2 fits failed with the following error:\n",
      "Traceback (most recent call last):\n",
      "  File \"/Users/nikulnayi/opt/anaconda3/lib/python3.9/site-packages/sklearn/model_selection/_validation.py\", line 680, in _fit_and_score\n",
      "    estimator.fit(X_train, y_train, **fit_params)\n",
      "  File \"/Users/nikulnayi/opt/anaconda3/lib/python3.9/site-packages/sklearn/pipeline.py\", line 394, in fit\n",
      "    self._final_estimator.fit(Xt, y, **fit_params_last_step)\n",
      "  File \"/Users/nikulnayi/opt/anaconda3/lib/python3.9/site-packages/xgboost/core.py\", line 620, in inner_f\n",
      "    return func(**kwargs)\n",
      "  File \"/Users/nikulnayi/opt/anaconda3/lib/python3.9/site-packages/xgboost/sklearn.py\", line 1471, in fit\n",
      "    train_dmatrix, evals = _wrap_evaluation_matrices(\n",
      "  File \"/Users/nikulnayi/opt/anaconda3/lib/python3.9/site-packages/xgboost/sklearn.py\", line 448, in _wrap_evaluation_matrices\n",
      "    train_dmatrix = create_dmatrix(\n",
      "  File \"/Users/nikulnayi/opt/anaconda3/lib/python3.9/site-packages/xgboost/sklearn.py\", line 908, in _create_dmatrix\n",
      "    return DMatrix(**kwargs, nthread=self.n_jobs)\n",
      "  File \"/Users/nikulnayi/opt/anaconda3/lib/python3.9/site-packages/xgboost/core.py\", line 620, in inner_f\n",
      "    return func(**kwargs)\n",
      "  File \"/Users/nikulnayi/opt/anaconda3/lib/python3.9/site-packages/xgboost/core.py\", line 754, in __init__\n",
      "    self.set_info(\n",
      "  File \"/Users/nikulnayi/opt/anaconda3/lib/python3.9/site-packages/xgboost/core.py\", line 620, in inner_f\n",
      "    return func(**kwargs)\n",
      "  File \"/Users/nikulnayi/opt/anaconda3/lib/python3.9/site-packages/xgboost/core.py\", line 819, in set_info\n",
      "    self.set_label(label)\n",
      "  File \"/Users/nikulnayi/opt/anaconda3/lib/python3.9/site-packages/xgboost/core.py\", line 950, in set_label\n",
      "    dispatch_meta_backend(self, label, 'label', 'float')\n",
      "  File \"/Users/nikulnayi/opt/anaconda3/lib/python3.9/site-packages/xgboost/data.py\", line 1134, in dispatch_meta_backend\n",
      "    _meta_from_pandas_series(data, name, dtype, handle)\n",
      "  File \"/Users/nikulnayi/opt/anaconda3/lib/python3.9/site-packages/xgboost/data.py\", line 443, in _meta_from_pandas_series\n",
      "    _meta_from_numpy(data, name, dtype, handle)\n",
      "  File \"/Users/nikulnayi/opt/anaconda3/lib/python3.9/site-packages/xgboost/data.py\", line 1050, in _meta_from_numpy\n",
      "    _check_call(_LIB.XGDMatrixSetInfoFromInterface(handle, c_str(field), interface_str))\n",
      "  File \"/Users/nikulnayi/opt/anaconda3/lib/python3.9/site-packages/xgboost/core.py\", line 279, in _check_call\n",
      "    raise XGBoostError(py_str(_LIB.XGBGetLastError()))\n",
      "xgboost.core.XGBoostError: [15:15:10] /Users/runner/work/xgboost/xgboost/python-package/build/temp.macosx-10.9-x86_64-cpython-38/xgboost/src/data/data.cc:455: Check failed: this->labels.Size() % this->num_row_ == 0 (20665 vs. 0) : Incorrect size for labels.\n",
      "Stack trace:\n",
      "  [bt] (0) 1   libxgboost.dylib                    0x000000013643eb15 dmlc::LogMessageFatal::~LogMessageFatal() + 117\n",
      "  [bt] (1) 2   libxgboost.dylib                    0x00000001364d47aa xgboost::MetaInfo::SetInfoFromHost(xgboost::GenericParameter const&, xgboost::StringView, xgboost::Json) + 4282\n",
      "  [bt] (2) 3   libxgboost.dylib                    0x00000001364d3602 xgboost::MetaInfo::SetInfo(xgboost::GenericParameter const&, xgboost::StringView, xgboost::StringView) + 146\n",
      "  [bt] (3) 4   libxgboost.dylib                    0x00000001364551f9 XGDMatrixSetInfoFromInterface + 233\n",
      "  [bt] (4) 5   libffi.7.dylib                      0x000000010dd07ead ffi_call_unix64 + 85\n",
      "  [bt] (5) 6   ???                                 0x0000000309c88090 0x0 + 13049036944\n",
      "\n",
      "\n",
      "\n",
      "--------------------------------------------------------------------------------\n",
      "1 fits failed with the following error:\n",
      "Traceback (most recent call last):\n",
      "  File \"/Users/nikulnayi/opt/anaconda3/lib/python3.9/site-packages/sklearn/model_selection/_validation.py\", line 680, in _fit_and_score\n",
      "    estimator.fit(X_train, y_train, **fit_params)\n",
      "  File \"/Users/nikulnayi/opt/anaconda3/lib/python3.9/site-packages/sklearn/pipeline.py\", line 394, in fit\n",
      "    self._final_estimator.fit(Xt, y, **fit_params_last_step)\n",
      "  File \"/Users/nikulnayi/opt/anaconda3/lib/python3.9/site-packages/xgboost/core.py\", line 620, in inner_f\n",
      "    return func(**kwargs)\n",
      "  File \"/Users/nikulnayi/opt/anaconda3/lib/python3.9/site-packages/xgboost/sklearn.py\", line 1471, in fit\n",
      "    train_dmatrix, evals = _wrap_evaluation_matrices(\n",
      "  File \"/Users/nikulnayi/opt/anaconda3/lib/python3.9/site-packages/xgboost/sklearn.py\", line 448, in _wrap_evaluation_matrices\n",
      "    train_dmatrix = create_dmatrix(\n",
      "  File \"/Users/nikulnayi/opt/anaconda3/lib/python3.9/site-packages/xgboost/sklearn.py\", line 908, in _create_dmatrix\n",
      "    return DMatrix(**kwargs, nthread=self.n_jobs)\n",
      "  File \"/Users/nikulnayi/opt/anaconda3/lib/python3.9/site-packages/xgboost/core.py\", line 620, in inner_f\n",
      "    return func(**kwargs)\n",
      "  File \"/Users/nikulnayi/opt/anaconda3/lib/python3.9/site-packages/xgboost/core.py\", line 754, in __init__\n",
      "    self.set_info(\n",
      "  File \"/Users/nikulnayi/opt/anaconda3/lib/python3.9/site-packages/xgboost/core.py\", line 620, in inner_f\n",
      "    return func(**kwargs)\n",
      "  File \"/Users/nikulnayi/opt/anaconda3/lib/python3.9/site-packages/xgboost/core.py\", line 819, in set_info\n",
      "    self.set_label(label)\n",
      "  File \"/Users/nikulnayi/opt/anaconda3/lib/python3.9/site-packages/xgboost/core.py\", line 950, in set_label\n",
      "    dispatch_meta_backend(self, label, 'label', 'float')\n",
      "  File \"/Users/nikulnayi/opt/anaconda3/lib/python3.9/site-packages/xgboost/data.py\", line 1134, in dispatch_meta_backend\n",
      "    _meta_from_pandas_series(data, name, dtype, handle)\n",
      "  File \"/Users/nikulnayi/opt/anaconda3/lib/python3.9/site-packages/xgboost/data.py\", line 443, in _meta_from_pandas_series\n",
      "    _meta_from_numpy(data, name, dtype, handle)\n",
      "  File \"/Users/nikulnayi/opt/anaconda3/lib/python3.9/site-packages/xgboost/data.py\", line 1050, in _meta_from_numpy\n",
      "    _check_call(_LIB.XGDMatrixSetInfoFromInterface(handle, c_str(field), interface_str))\n",
      "  File \"/Users/nikulnayi/opt/anaconda3/lib/python3.9/site-packages/xgboost/core.py\", line 279, in _check_call\n",
      "    raise XGBoostError(py_str(_LIB.XGBGetLastError()))\n",
      "xgboost.core.XGBoostError: [15:15:09] /Users/runner/work/xgboost/xgboost/python-package/build/temp.macosx-10.9-x86_64-cpython-38/xgboost/src/data/data.cc:455: Check failed: this->labels.Size() % this->num_row_ == 0 (20665 vs. 0) : Incorrect size for labels.\n",
      "Stack trace:\n",
      "  [bt] (0) 1   libxgboost.dylib                    0x0000000132ffeb15 dmlc::LogMessageFatal::~LogMessageFatal() + 117\n",
      "  [bt] (1) 2   libxgboost.dylib                    0x00000001330947aa xgboost::MetaInfo::SetInfoFromHost(xgboost::GenericParameter const&, xgboost::StringView, xgboost::Json) + 4282\n",
      "  [bt] (2) 3   libxgboost.dylib                    0x0000000133093602 xgboost::MetaInfo::SetInfo(xgboost::GenericParameter const&, xgboost::StringView, xgboost::StringView) + 146\n",
      "  [bt] (3) 4   libxgboost.dylib                    0x00000001330151f9 XGDMatrixSetInfoFromInterface + 233\n",
      "  [bt] (4) 5   libffi.7.dylib                      0x000000010a8c7ead ffi_call_unix64 + 85\n",
      "  [bt] (5) 6   ???                                 0x0000000303483090 0x0 + 12939964560\n",
      "\n",
      "\n",
      "\n",
      "--------------------------------------------------------------------------------\n",
      "1 fits failed with the following error:\n",
      "Traceback (most recent call last):\n",
      "  File \"/Users/nikulnayi/opt/anaconda3/lib/python3.9/site-packages/sklearn/model_selection/_validation.py\", line 680, in _fit_and_score\n",
      "    estimator.fit(X_train, y_train, **fit_params)\n",
      "  File \"/Users/nikulnayi/opt/anaconda3/lib/python3.9/site-packages/sklearn/pipeline.py\", line 394, in fit\n",
      "    self._final_estimator.fit(Xt, y, **fit_params_last_step)\n",
      "  File \"/Users/nikulnayi/opt/anaconda3/lib/python3.9/site-packages/xgboost/core.py\", line 620, in inner_f\n",
      "    return func(**kwargs)\n",
      "  File \"/Users/nikulnayi/opt/anaconda3/lib/python3.9/site-packages/xgboost/sklearn.py\", line 1471, in fit\n",
      "    train_dmatrix, evals = _wrap_evaluation_matrices(\n",
      "  File \"/Users/nikulnayi/opt/anaconda3/lib/python3.9/site-packages/xgboost/sklearn.py\", line 448, in _wrap_evaluation_matrices\n",
      "    train_dmatrix = create_dmatrix(\n",
      "  File \"/Users/nikulnayi/opt/anaconda3/lib/python3.9/site-packages/xgboost/sklearn.py\", line 908, in _create_dmatrix\n",
      "    return DMatrix(**kwargs, nthread=self.n_jobs)\n",
      "  File \"/Users/nikulnayi/opt/anaconda3/lib/python3.9/site-packages/xgboost/core.py\", line 620, in inner_f\n",
      "    return func(**kwargs)\n",
      "  File \"/Users/nikulnayi/opt/anaconda3/lib/python3.9/site-packages/xgboost/core.py\", line 754, in __init__\n",
      "    self.set_info(\n",
      "  File \"/Users/nikulnayi/opt/anaconda3/lib/python3.9/site-packages/xgboost/core.py\", line 620, in inner_f\n",
      "    return func(**kwargs)\n",
      "  File \"/Users/nikulnayi/opt/anaconda3/lib/python3.9/site-packages/xgboost/core.py\", line 819, in set_info\n",
      "    self.set_label(label)\n",
      "  File \"/Users/nikulnayi/opt/anaconda3/lib/python3.9/site-packages/xgboost/core.py\", line 950, in set_label\n",
      "    dispatch_meta_backend(self, label, 'label', 'float')\n",
      "  File \"/Users/nikulnayi/opt/anaconda3/lib/python3.9/site-packages/xgboost/data.py\", line 1134, in dispatch_meta_backend\n",
      "    _meta_from_pandas_series(data, name, dtype, handle)\n",
      "  File \"/Users/nikulnayi/opt/anaconda3/lib/python3.9/site-packages/xgboost/data.py\", line 443, in _meta_from_pandas_series\n",
      "    _meta_from_numpy(data, name, dtype, handle)\n",
      "  File \"/Users/nikulnayi/opt/anaconda3/lib/python3.9/site-packages/xgboost/data.py\", line 1050, in _meta_from_numpy\n",
      "    _check_call(_LIB.XGDMatrixSetInfoFromInterface(handle, c_str(field), interface_str))\n",
      "  File \"/Users/nikulnayi/opt/anaconda3/lib/python3.9/site-packages/xgboost/core.py\", line 279, in _check_call\n",
      "    raise XGBoostError(py_str(_LIB.XGBGetLastError()))\n",
      "xgboost.core.XGBoostError: [15:15:09] /Users/runner/work/xgboost/xgboost/python-package/build/temp.macosx-10.9-x86_64-cpython-38/xgboost/src/data/data.cc:455: Check failed: this->labels.Size() % this->num_row_ == 0 (20666 vs. 0) : Incorrect size for labels.\n",
      "Stack trace:\n",
      "  [bt] (0) 1   libxgboost.dylib                    0x0000000132ffeb15 dmlc::LogMessageFatal::~LogMessageFatal() + 117\n",
      "  [bt] (1) 2   libxgboost.dylib                    0x00000001330947aa xgboost::MetaInfo::SetInfoFromHost(xgboost::GenericParameter const&, xgboost::StringView, xgboost::Json) + 4282\n",
      "  [bt] (2) 3   libxgboost.dylib                    0x0000000133093602 xgboost::MetaInfo::SetInfo(xgboost::GenericParameter const&, xgboost::StringView, xgboost::StringView) + 146\n",
      "  [bt] (3) 4   libxgboost.dylib                    0x00000001330151f9 XGDMatrixSetInfoFromInterface + 233\n",
      "  [bt] (4) 5   libffi.7.dylib                      0x000000010a8c7ead ffi_call_unix64 + 85\n",
      "  [bt] (5) 6   ???                                 0x0000000303483090 0x0 + 12939964560\n",
      "\n",
      "\n",
      "\n",
      "--------------------------------------------------------------------------------\n",
      "2 fits failed with the following error:\n",
      "Traceback (most recent call last):\n",
      "  File \"/Users/nikulnayi/opt/anaconda3/lib/python3.9/site-packages/sklearn/model_selection/_validation.py\", line 680, in _fit_and_score\n",
      "    estimator.fit(X_train, y_train, **fit_params)\n",
      "  File \"/Users/nikulnayi/opt/anaconda3/lib/python3.9/site-packages/sklearn/pipeline.py\", line 394, in fit\n",
      "    self._final_estimator.fit(Xt, y, **fit_params_last_step)\n",
      "  File \"/Users/nikulnayi/opt/anaconda3/lib/python3.9/site-packages/xgboost/core.py\", line 620, in inner_f\n",
      "    return func(**kwargs)\n",
      "  File \"/Users/nikulnayi/opt/anaconda3/lib/python3.9/site-packages/xgboost/sklearn.py\", line 1471, in fit\n",
      "    train_dmatrix, evals = _wrap_evaluation_matrices(\n",
      "  File \"/Users/nikulnayi/opt/anaconda3/lib/python3.9/site-packages/xgboost/sklearn.py\", line 448, in _wrap_evaluation_matrices\n",
      "    train_dmatrix = create_dmatrix(\n",
      "  File \"/Users/nikulnayi/opt/anaconda3/lib/python3.9/site-packages/xgboost/sklearn.py\", line 908, in _create_dmatrix\n",
      "    return DMatrix(**kwargs, nthread=self.n_jobs)\n",
      "  File \"/Users/nikulnayi/opt/anaconda3/lib/python3.9/site-packages/xgboost/core.py\", line 620, in inner_f\n",
      "    return func(**kwargs)\n",
      "  File \"/Users/nikulnayi/opt/anaconda3/lib/python3.9/site-packages/xgboost/core.py\", line 754, in __init__\n",
      "    self.set_info(\n",
      "  File \"/Users/nikulnayi/opt/anaconda3/lib/python3.9/site-packages/xgboost/core.py\", line 620, in inner_f\n",
      "    return func(**kwargs)\n",
      "  File \"/Users/nikulnayi/opt/anaconda3/lib/python3.9/site-packages/xgboost/core.py\", line 819, in set_info\n",
      "    self.set_label(label)\n",
      "  File \"/Users/nikulnayi/opt/anaconda3/lib/python3.9/site-packages/xgboost/core.py\", line 950, in set_label\n",
      "    dispatch_meta_backend(self, label, 'label', 'float')\n",
      "  File \"/Users/nikulnayi/opt/anaconda3/lib/python3.9/site-packages/xgboost/data.py\", line 1134, in dispatch_meta_backend\n",
      "    _meta_from_pandas_series(data, name, dtype, handle)\n",
      "  File \"/Users/nikulnayi/opt/anaconda3/lib/python3.9/site-packages/xgboost/data.py\", line 443, in _meta_from_pandas_series\n",
      "    _meta_from_numpy(data, name, dtype, handle)\n",
      "  File \"/Users/nikulnayi/opt/anaconda3/lib/python3.9/site-packages/xgboost/data.py\", line 1050, in _meta_from_numpy\n",
      "    _check_call(_LIB.XGDMatrixSetInfoFromInterface(handle, c_str(field), interface_str))\n",
      "  File \"/Users/nikulnayi/opt/anaconda3/lib/python3.9/site-packages/xgboost/core.py\", line 279, in _check_call\n",
      "    raise XGBoostError(py_str(_LIB.XGBGetLastError()))\n",
      "xgboost.core.XGBoostError: [15:15:09] /Users/runner/work/xgboost/xgboost/python-package/build/temp.macosx-10.9-x86_64-cpython-38/xgboost/src/data/data.cc:455: Check failed: this->labels.Size() % this->num_row_ == 0 (20665 vs. 0) : Incorrect size for labels.\n",
      "Stack trace:\n",
      "  [bt] (0) 1   libxgboost.dylib                    0x0000000136c8ab15 dmlc::LogMessageFatal::~LogMessageFatal() + 117\n",
      "  [bt] (1) 2   libxgboost.dylib                    0x0000000136d207aa xgboost::MetaInfo::SetInfoFromHost(xgboost::GenericParameter const&, xgboost::StringView, xgboost::Json) + 4282\n",
      "  [bt] (2) 3   libxgboost.dylib                    0x0000000136d1f602 xgboost::MetaInfo::SetInfo(xgboost::GenericParameter const&, xgboost::StringView, xgboost::StringView) + 146\n",
      "  [bt] (3) 4   libxgboost.dylib                    0x0000000136ca11f9 XGDMatrixSetInfoFromInterface + 233\n",
      "  [bt] (4) 5   libffi.7.dylib                      0x000000010e553ead ffi_call_unix64 + 85\n",
      "  [bt] (5) 6   ???                                 0x000000030aefc090 0x0 + 13068386448\n",
      "\n",
      "\n",
      "\n",
      "--------------------------------------------------------------------------------\n",
      "1 fits failed with the following error:\n",
      "Traceback (most recent call last):\n",
      "  File \"/Users/nikulnayi/opt/anaconda3/lib/python3.9/site-packages/sklearn/model_selection/_validation.py\", line 680, in _fit_and_score\n",
      "    estimator.fit(X_train, y_train, **fit_params)\n",
      "  File \"/Users/nikulnayi/opt/anaconda3/lib/python3.9/site-packages/sklearn/pipeline.py\", line 394, in fit\n",
      "    self._final_estimator.fit(Xt, y, **fit_params_last_step)\n",
      "  File \"/Users/nikulnayi/opt/anaconda3/lib/python3.9/site-packages/xgboost/core.py\", line 620, in inner_f\n",
      "    return func(**kwargs)\n",
      "  File \"/Users/nikulnayi/opt/anaconda3/lib/python3.9/site-packages/xgboost/sklearn.py\", line 1471, in fit\n",
      "    train_dmatrix, evals = _wrap_evaluation_matrices(\n",
      "  File \"/Users/nikulnayi/opt/anaconda3/lib/python3.9/site-packages/xgboost/sklearn.py\", line 448, in _wrap_evaluation_matrices\n",
      "    train_dmatrix = create_dmatrix(\n",
      "  File \"/Users/nikulnayi/opt/anaconda3/lib/python3.9/site-packages/xgboost/sklearn.py\", line 908, in _create_dmatrix\n",
      "    return DMatrix(**kwargs, nthread=self.n_jobs)\n",
      "  File \"/Users/nikulnayi/opt/anaconda3/lib/python3.9/site-packages/xgboost/core.py\", line 620, in inner_f\n",
      "    return func(**kwargs)\n",
      "  File \"/Users/nikulnayi/opt/anaconda3/lib/python3.9/site-packages/xgboost/core.py\", line 754, in __init__\n",
      "    self.set_info(\n",
      "  File \"/Users/nikulnayi/opt/anaconda3/lib/python3.9/site-packages/xgboost/core.py\", line 620, in inner_f\n",
      "    return func(**kwargs)\n",
      "  File \"/Users/nikulnayi/opt/anaconda3/lib/python3.9/site-packages/xgboost/core.py\", line 819, in set_info\n",
      "    self.set_label(label)\n",
      "  File \"/Users/nikulnayi/opt/anaconda3/lib/python3.9/site-packages/xgboost/core.py\", line 950, in set_label\n",
      "    dispatch_meta_backend(self, label, 'label', 'float')\n",
      "  File \"/Users/nikulnayi/opt/anaconda3/lib/python3.9/site-packages/xgboost/data.py\", line 1134, in dispatch_meta_backend\n",
      "    _meta_from_pandas_series(data, name, dtype, handle)\n",
      "  File \"/Users/nikulnayi/opt/anaconda3/lib/python3.9/site-packages/xgboost/data.py\", line 443, in _meta_from_pandas_series\n",
      "    _meta_from_numpy(data, name, dtype, handle)\n",
      "  File \"/Users/nikulnayi/opt/anaconda3/lib/python3.9/site-packages/xgboost/data.py\", line 1050, in _meta_from_numpy\n",
      "    _check_call(_LIB.XGDMatrixSetInfoFromInterface(handle, c_str(field), interface_str))\n",
      "  File \"/Users/nikulnayi/opt/anaconda3/lib/python3.9/site-packages/xgboost/core.py\", line 279, in _check_call\n",
      "    raise XGBoostError(py_str(_LIB.XGBGetLastError()))\n",
      "xgboost.core.XGBoostError: [15:15:09] /Users/runner/work/xgboost/xgboost/python-package/build/temp.macosx-10.9-x86_64-cpython-38/xgboost/src/data/data.cc:455: Check failed: this->labels.Size() % this->num_row_ == 0 (20666 vs. 0) : Incorrect size for labels.\n",
      "Stack trace:\n",
      "  [bt] (0) 1   libxgboost.dylib                    0x0000000136a1bb15 dmlc::LogMessageFatal::~LogMessageFatal() + 117\n",
      "  [bt] (1) 2   libxgboost.dylib                    0x0000000136ab17aa xgboost::MetaInfo::SetInfoFromHost(xgboost::GenericParameter const&, xgboost::StringView, xgboost::Json) + 4282\n",
      "  [bt] (2) 3   libxgboost.dylib                    0x0000000136ab0602 xgboost::MetaInfo::SetInfo(xgboost::GenericParameter const&, xgboost::StringView, xgboost::StringView) + 146\n",
      "  [bt] (3) 4   libxgboost.dylib                    0x0000000136a321f9 XGDMatrixSetInfoFromInterface + 233\n",
      "  [bt] (4) 5   libffi.7.dylib                      0x000000010e2e4ead ffi_call_unix64 + 85\n",
      "  [bt] (5) 6   ???                                 0x000000030a850090 0x0 + 13061390480\n",
      "\n",
      "\n",
      "\n",
      "--------------------------------------------------------------------------------\n",
      "3 fits failed with the following error:\n",
      "Traceback (most recent call last):\n",
      "  File \"/Users/nikulnayi/opt/anaconda3/lib/python3.9/site-packages/sklearn/model_selection/_validation.py\", line 680, in _fit_and_score\n",
      "    estimator.fit(X_train, y_train, **fit_params)\n",
      "  File \"/Users/nikulnayi/opt/anaconda3/lib/python3.9/site-packages/sklearn/pipeline.py\", line 394, in fit\n",
      "    self._final_estimator.fit(Xt, y, **fit_params_last_step)\n",
      "  File \"/Users/nikulnayi/opt/anaconda3/lib/python3.9/site-packages/xgboost/core.py\", line 620, in inner_f\n",
      "    return func(**kwargs)\n",
      "  File \"/Users/nikulnayi/opt/anaconda3/lib/python3.9/site-packages/xgboost/sklearn.py\", line 1471, in fit\n",
      "    train_dmatrix, evals = _wrap_evaluation_matrices(\n",
      "  File \"/Users/nikulnayi/opt/anaconda3/lib/python3.9/site-packages/xgboost/sklearn.py\", line 448, in _wrap_evaluation_matrices\n",
      "    train_dmatrix = create_dmatrix(\n",
      "  File \"/Users/nikulnayi/opt/anaconda3/lib/python3.9/site-packages/xgboost/sklearn.py\", line 908, in _create_dmatrix\n",
      "    return DMatrix(**kwargs, nthread=self.n_jobs)\n",
      "  File \"/Users/nikulnayi/opt/anaconda3/lib/python3.9/site-packages/xgboost/core.py\", line 620, in inner_f\n",
      "    return func(**kwargs)\n",
      "  File \"/Users/nikulnayi/opt/anaconda3/lib/python3.9/site-packages/xgboost/core.py\", line 754, in __init__\n",
      "    self.set_info(\n",
      "  File \"/Users/nikulnayi/opt/anaconda3/lib/python3.9/site-packages/xgboost/core.py\", line 620, in inner_f\n",
      "    return func(**kwargs)\n",
      "  File \"/Users/nikulnayi/opt/anaconda3/lib/python3.9/site-packages/xgboost/core.py\", line 819, in set_info\n",
      "    self.set_label(label)\n",
      "  File \"/Users/nikulnayi/opt/anaconda3/lib/python3.9/site-packages/xgboost/core.py\", line 950, in set_label\n",
      "    dispatch_meta_backend(self, label, 'label', 'float')\n",
      "  File \"/Users/nikulnayi/opt/anaconda3/lib/python3.9/site-packages/xgboost/data.py\", line 1134, in dispatch_meta_backend\n",
      "    _meta_from_pandas_series(data, name, dtype, handle)\n",
      "  File \"/Users/nikulnayi/opt/anaconda3/lib/python3.9/site-packages/xgboost/data.py\", line 443, in _meta_from_pandas_series\n",
      "    _meta_from_numpy(data, name, dtype, handle)\n",
      "  File \"/Users/nikulnayi/opt/anaconda3/lib/python3.9/site-packages/xgboost/data.py\", line 1050, in _meta_from_numpy\n",
      "    _check_call(_LIB.XGDMatrixSetInfoFromInterface(handle, c_str(field), interface_str))\n",
      "  File \"/Users/nikulnayi/opt/anaconda3/lib/python3.9/site-packages/xgboost/core.py\", line 279, in _check_call\n",
      "    raise XGBoostError(py_str(_LIB.XGBGetLastError()))\n",
      "xgboost.core.XGBoostError: [15:15:10] /Users/runner/work/xgboost/xgboost/python-package/build/temp.macosx-10.9-x86_64-cpython-38/xgboost/src/data/data.cc:455: Check failed: this->labels.Size() % this->num_row_ == 0 (20665 vs. 0) : Incorrect size for labels.\n",
      "Stack trace:\n",
      "  [bt] (0) 1   libxgboost.dylib                    0x0000000136c8ab15 dmlc::LogMessageFatal::~LogMessageFatal() + 117\n",
      "  [bt] (1) 2   libxgboost.dylib                    0x0000000136d207aa xgboost::MetaInfo::SetInfoFromHost(xgboost::GenericParameter const&, xgboost::StringView, xgboost::Json) + 4282\n",
      "  [bt] (2) 3   libxgboost.dylib                    0x0000000136d1f602 xgboost::MetaInfo::SetInfo(xgboost::GenericParameter const&, xgboost::StringView, xgboost::StringView) + 146\n",
      "  [bt] (3) 4   libxgboost.dylib                    0x0000000136ca11f9 XGDMatrixSetInfoFromInterface + 233\n",
      "  [bt] (4) 5   libffi.7.dylib                      0x000000010e553ead ffi_call_unix64 + 85\n",
      "  [bt] (5) 6   ???                                 0x000000030aefc090 0x0 + 13068386448\n",
      "\n",
      "\n",
      "\n",
      "--------------------------------------------------------------------------------\n",
      "2 fits failed with the following error:\n",
      "Traceback (most recent call last):\n",
      "  File \"/Users/nikulnayi/opt/anaconda3/lib/python3.9/site-packages/sklearn/model_selection/_validation.py\", line 680, in _fit_and_score\n",
      "    estimator.fit(X_train, y_train, **fit_params)\n",
      "  File \"/Users/nikulnayi/opt/anaconda3/lib/python3.9/site-packages/sklearn/pipeline.py\", line 394, in fit\n",
      "    self._final_estimator.fit(Xt, y, **fit_params_last_step)\n",
      "  File \"/Users/nikulnayi/opt/anaconda3/lib/python3.9/site-packages/xgboost/core.py\", line 620, in inner_f\n",
      "    return func(**kwargs)\n",
      "  File \"/Users/nikulnayi/opt/anaconda3/lib/python3.9/site-packages/xgboost/sklearn.py\", line 1471, in fit\n",
      "    train_dmatrix, evals = _wrap_evaluation_matrices(\n",
      "  File \"/Users/nikulnayi/opt/anaconda3/lib/python3.9/site-packages/xgboost/sklearn.py\", line 448, in _wrap_evaluation_matrices\n",
      "    train_dmatrix = create_dmatrix(\n",
      "  File \"/Users/nikulnayi/opt/anaconda3/lib/python3.9/site-packages/xgboost/sklearn.py\", line 908, in _create_dmatrix\n",
      "    return DMatrix(**kwargs, nthread=self.n_jobs)\n",
      "  File \"/Users/nikulnayi/opt/anaconda3/lib/python3.9/site-packages/xgboost/core.py\", line 620, in inner_f\n",
      "    return func(**kwargs)\n",
      "  File \"/Users/nikulnayi/opt/anaconda3/lib/python3.9/site-packages/xgboost/core.py\", line 754, in __init__\n",
      "    self.set_info(\n",
      "  File \"/Users/nikulnayi/opt/anaconda3/lib/python3.9/site-packages/xgboost/core.py\", line 620, in inner_f\n",
      "    return func(**kwargs)\n",
      "  File \"/Users/nikulnayi/opt/anaconda3/lib/python3.9/site-packages/xgboost/core.py\", line 819, in set_info\n",
      "    self.set_label(label)\n",
      "  File \"/Users/nikulnayi/opt/anaconda3/lib/python3.9/site-packages/xgboost/core.py\", line 950, in set_label\n",
      "    dispatch_meta_backend(self, label, 'label', 'float')\n",
      "  File \"/Users/nikulnayi/opt/anaconda3/lib/python3.9/site-packages/xgboost/data.py\", line 1134, in dispatch_meta_backend\n",
      "    _meta_from_pandas_series(data, name, dtype, handle)\n",
      "  File \"/Users/nikulnayi/opt/anaconda3/lib/python3.9/site-packages/xgboost/data.py\", line 443, in _meta_from_pandas_series\n",
      "    _meta_from_numpy(data, name, dtype, handle)\n",
      "  File \"/Users/nikulnayi/opt/anaconda3/lib/python3.9/site-packages/xgboost/data.py\", line 1050, in _meta_from_numpy\n",
      "    _check_call(_LIB.XGDMatrixSetInfoFromInterface(handle, c_str(field), interface_str))\n",
      "  File \"/Users/nikulnayi/opt/anaconda3/lib/python3.9/site-packages/xgboost/core.py\", line 279, in _check_call\n",
      "    raise XGBoostError(py_str(_LIB.XGBGetLastError()))\n",
      "xgboost.core.XGBoostError: [15:15:10] /Users/runner/work/xgboost/xgboost/python-package/build/temp.macosx-10.9-x86_64-cpython-38/xgboost/src/data/data.cc:455: Check failed: this->labels.Size() % this->num_row_ == 0 (20665 vs. 0) : Incorrect size for labels.\n",
      "Stack trace:\n",
      "  [bt] (0) 1   libxgboost.dylib                    0x000000013211cb15 dmlc::LogMessageFatal::~LogMessageFatal() + 117\n",
      "  [bt] (1) 2   libxgboost.dylib                    0x00000001321b27aa xgboost::MetaInfo::SetInfoFromHost(xgboost::GenericParameter const&, xgboost::StringView, xgboost::Json) + 4282\n",
      "  [bt] (2) 3   libxgboost.dylib                    0x00000001321b1602 xgboost::MetaInfo::SetInfo(xgboost::GenericParameter const&, xgboost::StringView, xgboost::StringView) + 146\n",
      "  [bt] (3) 4   libxgboost.dylib                    0x00000001321331f9 XGDMatrixSetInfoFromInterface + 233\n",
      "  [bt] (4) 5   libffi.7.dylib                      0x00000001099e5ead ffi_call_unix64 + 85\n",
      "  [bt] (5) 6   ???                                 0x0000000301838090 0x0 + 12910297232\n",
      "\n",
      "\n",
      "\n",
      "--------------------------------------------------------------------------------\n",
      "1 fits failed with the following error:\n",
      "Traceback (most recent call last):\n",
      "  File \"/Users/nikulnayi/opt/anaconda3/lib/python3.9/site-packages/sklearn/model_selection/_validation.py\", line 680, in _fit_and_score\n",
      "    estimator.fit(X_train, y_train, **fit_params)\n",
      "  File \"/Users/nikulnayi/opt/anaconda3/lib/python3.9/site-packages/sklearn/pipeline.py\", line 394, in fit\n",
      "    self._final_estimator.fit(Xt, y, **fit_params_last_step)\n",
      "  File \"/Users/nikulnayi/opt/anaconda3/lib/python3.9/site-packages/xgboost/core.py\", line 620, in inner_f\n",
      "    return func(**kwargs)\n",
      "  File \"/Users/nikulnayi/opt/anaconda3/lib/python3.9/site-packages/xgboost/sklearn.py\", line 1471, in fit\n",
      "    train_dmatrix, evals = _wrap_evaluation_matrices(\n",
      "  File \"/Users/nikulnayi/opt/anaconda3/lib/python3.9/site-packages/xgboost/sklearn.py\", line 448, in _wrap_evaluation_matrices\n",
      "    train_dmatrix = create_dmatrix(\n",
      "  File \"/Users/nikulnayi/opt/anaconda3/lib/python3.9/site-packages/xgboost/sklearn.py\", line 908, in _create_dmatrix\n",
      "    return DMatrix(**kwargs, nthread=self.n_jobs)\n",
      "  File \"/Users/nikulnayi/opt/anaconda3/lib/python3.9/site-packages/xgboost/core.py\", line 620, in inner_f\n",
      "    return func(**kwargs)\n",
      "  File \"/Users/nikulnayi/opt/anaconda3/lib/python3.9/site-packages/xgboost/core.py\", line 754, in __init__\n",
      "    self.set_info(\n",
      "  File \"/Users/nikulnayi/opt/anaconda3/lib/python3.9/site-packages/xgboost/core.py\", line 620, in inner_f\n",
      "    return func(**kwargs)\n",
      "  File \"/Users/nikulnayi/opt/anaconda3/lib/python3.9/site-packages/xgboost/core.py\", line 819, in set_info\n",
      "    self.set_label(label)\n",
      "  File \"/Users/nikulnayi/opt/anaconda3/lib/python3.9/site-packages/xgboost/core.py\", line 950, in set_label\n",
      "    dispatch_meta_backend(self, label, 'label', 'float')\n",
      "  File \"/Users/nikulnayi/opt/anaconda3/lib/python3.9/site-packages/xgboost/data.py\", line 1134, in dispatch_meta_backend\n",
      "    _meta_from_pandas_series(data, name, dtype, handle)\n",
      "  File \"/Users/nikulnayi/opt/anaconda3/lib/python3.9/site-packages/xgboost/data.py\", line 443, in _meta_from_pandas_series\n",
      "    _meta_from_numpy(data, name, dtype, handle)\n",
      "  File \"/Users/nikulnayi/opt/anaconda3/lib/python3.9/site-packages/xgboost/data.py\", line 1050, in _meta_from_numpy\n",
      "    _check_call(_LIB.XGDMatrixSetInfoFromInterface(handle, c_str(field), interface_str))\n",
      "  File \"/Users/nikulnayi/opt/anaconda3/lib/python3.9/site-packages/xgboost/core.py\", line 279, in _check_call\n",
      "    raise XGBoostError(py_str(_LIB.XGBGetLastError()))\n",
      "xgboost.core.XGBoostError: [15:15:10] /Users/runner/work/xgboost/xgboost/python-package/build/temp.macosx-10.9-x86_64-cpython-38/xgboost/src/data/data.cc:455: Check failed: this->labels.Size() % this->num_row_ == 0 (20666 vs. 0) : Incorrect size for labels.\n",
      "Stack trace:\n",
      "  [bt] (0) 1   libxgboost.dylib                    0x0000000134f94b15 dmlc::LogMessageFatal::~LogMessageFatal() + 117\n",
      "  [bt] (1) 2   libxgboost.dylib                    0x000000013502a7aa xgboost::MetaInfo::SetInfoFromHost(xgboost::GenericParameter const&, xgboost::StringView, xgboost::Json) + 4282\n",
      "  [bt] (2) 3   libxgboost.dylib                    0x0000000135029602 xgboost::MetaInfo::SetInfo(xgboost::GenericParameter const&, xgboost::StringView, xgboost::StringView) + 146\n",
      "  [bt] (3) 4   libxgboost.dylib                    0x0000000134fab1f9 XGDMatrixSetInfoFromInterface + 233\n",
      "  [bt] (4) 5   libffi.7.dylib                      0x000000010c85dead ffi_call_unix64 + 85\n",
      "  [bt] (5) 6   ???                                 0x0000000307613090 0x0 + 13008711824\n",
      "\n",
      "\n",
      "\n",
      "--------------------------------------------------------------------------------\n",
      "3 fits failed with the following error:\n",
      "Traceback (most recent call last):\n",
      "  File \"/Users/nikulnayi/opt/anaconda3/lib/python3.9/site-packages/sklearn/model_selection/_validation.py\", line 680, in _fit_and_score\n",
      "    estimator.fit(X_train, y_train, **fit_params)\n",
      "  File \"/Users/nikulnayi/opt/anaconda3/lib/python3.9/site-packages/sklearn/pipeline.py\", line 394, in fit\n",
      "    self._final_estimator.fit(Xt, y, **fit_params_last_step)\n",
      "  File \"/Users/nikulnayi/opt/anaconda3/lib/python3.9/site-packages/xgboost/core.py\", line 620, in inner_f\n",
      "    return func(**kwargs)\n",
      "  File \"/Users/nikulnayi/opt/anaconda3/lib/python3.9/site-packages/xgboost/sklearn.py\", line 1471, in fit\n",
      "    train_dmatrix, evals = _wrap_evaluation_matrices(\n",
      "  File \"/Users/nikulnayi/opt/anaconda3/lib/python3.9/site-packages/xgboost/sklearn.py\", line 448, in _wrap_evaluation_matrices\n",
      "    train_dmatrix = create_dmatrix(\n",
      "  File \"/Users/nikulnayi/opt/anaconda3/lib/python3.9/site-packages/xgboost/sklearn.py\", line 908, in _create_dmatrix\n",
      "    return DMatrix(**kwargs, nthread=self.n_jobs)\n",
      "  File \"/Users/nikulnayi/opt/anaconda3/lib/python3.9/site-packages/xgboost/core.py\", line 620, in inner_f\n",
      "    return func(**kwargs)\n",
      "  File \"/Users/nikulnayi/opt/anaconda3/lib/python3.9/site-packages/xgboost/core.py\", line 754, in __init__\n",
      "    self.set_info(\n",
      "  File \"/Users/nikulnayi/opt/anaconda3/lib/python3.9/site-packages/xgboost/core.py\", line 620, in inner_f\n",
      "    return func(**kwargs)\n",
      "  File \"/Users/nikulnayi/opt/anaconda3/lib/python3.9/site-packages/xgboost/core.py\", line 819, in set_info\n",
      "    self.set_label(label)\n",
      "  File \"/Users/nikulnayi/opt/anaconda3/lib/python3.9/site-packages/xgboost/core.py\", line 950, in set_label\n",
      "    dispatch_meta_backend(self, label, 'label', 'float')\n",
      "  File \"/Users/nikulnayi/opt/anaconda3/lib/python3.9/site-packages/xgboost/data.py\", line 1134, in dispatch_meta_backend\n",
      "    _meta_from_pandas_series(data, name, dtype, handle)\n",
      "  File \"/Users/nikulnayi/opt/anaconda3/lib/python3.9/site-packages/xgboost/data.py\", line 443, in _meta_from_pandas_series\n",
      "    _meta_from_numpy(data, name, dtype, handle)\n",
      "  File \"/Users/nikulnayi/opt/anaconda3/lib/python3.9/site-packages/xgboost/data.py\", line 1050, in _meta_from_numpy\n",
      "    _check_call(_LIB.XGDMatrixSetInfoFromInterface(handle, c_str(field), interface_str))\n",
      "  File \"/Users/nikulnayi/opt/anaconda3/lib/python3.9/site-packages/xgboost/core.py\", line 279, in _check_call\n",
      "    raise XGBoostError(py_str(_LIB.XGBGetLastError()))\n",
      "xgboost.core.XGBoostError: [15:15:10] /Users/runner/work/xgboost/xgboost/python-package/build/temp.macosx-10.9-x86_64-cpython-38/xgboost/src/data/data.cc:455: Check failed: this->labels.Size() % this->num_row_ == 0 (20666 vs. 0) : Incorrect size for labels.\n",
      "Stack trace:\n",
      "  [bt] (0) 1   libxgboost.dylib                    0x0000000136c8ab15 dmlc::LogMessageFatal::~LogMessageFatal() + 117\n",
      "  [bt] (1) 2   libxgboost.dylib                    0x0000000136d207aa xgboost::MetaInfo::SetInfoFromHost(xgboost::GenericParameter const&, xgboost::StringView, xgboost::Json) + 4282\n",
      "  [bt] (2) 3   libxgboost.dylib                    0x0000000136d1f602 xgboost::MetaInfo::SetInfo(xgboost::GenericParameter const&, xgboost::StringView, xgboost::StringView) + 146\n",
      "  [bt] (3) 4   libxgboost.dylib                    0x0000000136ca11f9 XGDMatrixSetInfoFromInterface + 233\n",
      "  [bt] (4) 5   libffi.7.dylib                      0x000000010e553ead ffi_call_unix64 + 85\n",
      "  [bt] (5) 6   ???                                 0x000000030aefc090 0x0 + 13068386448\n",
      "\n",
      "\n",
      "\n",
      "--------------------------------------------------------------------------------\n",
      "1 fits failed with the following error:\n",
      "Traceback (most recent call last):\n",
      "  File \"/Users/nikulnayi/opt/anaconda3/lib/python3.9/site-packages/sklearn/model_selection/_validation.py\", line 680, in _fit_and_score\n",
      "    estimator.fit(X_train, y_train, **fit_params)\n",
      "  File \"/Users/nikulnayi/opt/anaconda3/lib/python3.9/site-packages/sklearn/pipeline.py\", line 394, in fit\n",
      "    self._final_estimator.fit(Xt, y, **fit_params_last_step)\n",
      "  File \"/Users/nikulnayi/opt/anaconda3/lib/python3.9/site-packages/xgboost/core.py\", line 620, in inner_f\n",
      "    return func(**kwargs)\n",
      "  File \"/Users/nikulnayi/opt/anaconda3/lib/python3.9/site-packages/xgboost/sklearn.py\", line 1471, in fit\n",
      "    train_dmatrix, evals = _wrap_evaluation_matrices(\n",
      "  File \"/Users/nikulnayi/opt/anaconda3/lib/python3.9/site-packages/xgboost/sklearn.py\", line 448, in _wrap_evaluation_matrices\n",
      "    train_dmatrix = create_dmatrix(\n",
      "  File \"/Users/nikulnayi/opt/anaconda3/lib/python3.9/site-packages/xgboost/sklearn.py\", line 908, in _create_dmatrix\n",
      "    return DMatrix(**kwargs, nthread=self.n_jobs)\n",
      "  File \"/Users/nikulnayi/opt/anaconda3/lib/python3.9/site-packages/xgboost/core.py\", line 620, in inner_f\n",
      "    return func(**kwargs)\n",
      "  File \"/Users/nikulnayi/opt/anaconda3/lib/python3.9/site-packages/xgboost/core.py\", line 754, in __init__\n",
      "    self.set_info(\n",
      "  File \"/Users/nikulnayi/opt/anaconda3/lib/python3.9/site-packages/xgboost/core.py\", line 620, in inner_f\n",
      "    return func(**kwargs)\n",
      "  File \"/Users/nikulnayi/opt/anaconda3/lib/python3.9/site-packages/xgboost/core.py\", line 819, in set_info\n",
      "    self.set_label(label)\n",
      "  File \"/Users/nikulnayi/opt/anaconda3/lib/python3.9/site-packages/xgboost/core.py\", line 950, in set_label\n",
      "    dispatch_meta_backend(self, label, 'label', 'float')\n",
      "  File \"/Users/nikulnayi/opt/anaconda3/lib/python3.9/site-packages/xgboost/data.py\", line 1134, in dispatch_meta_backend\n",
      "    _meta_from_pandas_series(data, name, dtype, handle)\n",
      "  File \"/Users/nikulnayi/opt/anaconda3/lib/python3.9/site-packages/xgboost/data.py\", line 443, in _meta_from_pandas_series\n",
      "    _meta_from_numpy(data, name, dtype, handle)\n",
      "  File \"/Users/nikulnayi/opt/anaconda3/lib/python3.9/site-packages/xgboost/data.py\", line 1050, in _meta_from_numpy\n",
      "    _check_call(_LIB.XGDMatrixSetInfoFromInterface(handle, c_str(field), interface_str))\n",
      "  File \"/Users/nikulnayi/opt/anaconda3/lib/python3.9/site-packages/xgboost/core.py\", line 279, in _check_call\n",
      "    raise XGBoostError(py_str(_LIB.XGBGetLastError()))\n",
      "xgboost.core.XGBoostError: [15:15:10] /Users/runner/work/xgboost/xgboost/python-package/build/temp.macosx-10.9-x86_64-cpython-38/xgboost/src/data/data.cc:455: Check failed: this->labels.Size() % this->num_row_ == 0 (20666 vs. 0) : Incorrect size for labels.\n",
      "Stack trace:\n",
      "  [bt] (0) 1   libxgboost.dylib                    0x000000013211cb15 dmlc::LogMessageFatal::~LogMessageFatal() + 117\n",
      "  [bt] (1) 2   libxgboost.dylib                    0x00000001321b27aa xgboost::MetaInfo::SetInfoFromHost(xgboost::GenericParameter const&, xgboost::StringView, xgboost::Json) + 4282\n",
      "  [bt] (2) 3   libxgboost.dylib                    0x00000001321b1602 xgboost::MetaInfo::SetInfo(xgboost::GenericParameter const&, xgboost::StringView, xgboost::StringView) + 146\n",
      "  [bt] (3) 4   libxgboost.dylib                    0x00000001321331f9 XGDMatrixSetInfoFromInterface + 233\n",
      "  [bt] (4) 5   libffi.7.dylib                      0x00000001099e5ead ffi_call_unix64 + 85\n",
      "  [bt] (5) 6   ???                                 0x0000000301838090 0x0 + 12910297232\n",
      "\n",
      "\n",
      "\n",
      "--------------------------------------------------------------------------------\n",
      "3 fits failed with the following error:\n",
      "Traceback (most recent call last):\n",
      "  File \"/Users/nikulnayi/opt/anaconda3/lib/python3.9/site-packages/sklearn/model_selection/_validation.py\", line 680, in _fit_and_score\n",
      "    estimator.fit(X_train, y_train, **fit_params)\n",
      "  File \"/Users/nikulnayi/opt/anaconda3/lib/python3.9/site-packages/sklearn/pipeline.py\", line 394, in fit\n",
      "    self._final_estimator.fit(Xt, y, **fit_params_last_step)\n",
      "  File \"/Users/nikulnayi/opt/anaconda3/lib/python3.9/site-packages/xgboost/core.py\", line 620, in inner_f\n",
      "    return func(**kwargs)\n",
      "  File \"/Users/nikulnayi/opt/anaconda3/lib/python3.9/site-packages/xgboost/sklearn.py\", line 1471, in fit\n",
      "    train_dmatrix, evals = _wrap_evaluation_matrices(\n",
      "  File \"/Users/nikulnayi/opt/anaconda3/lib/python3.9/site-packages/xgboost/sklearn.py\", line 448, in _wrap_evaluation_matrices\n",
      "    train_dmatrix = create_dmatrix(\n",
      "  File \"/Users/nikulnayi/opt/anaconda3/lib/python3.9/site-packages/xgboost/sklearn.py\", line 908, in _create_dmatrix\n",
      "    return DMatrix(**kwargs, nthread=self.n_jobs)\n",
      "  File \"/Users/nikulnayi/opt/anaconda3/lib/python3.9/site-packages/xgboost/core.py\", line 620, in inner_f\n",
      "    return func(**kwargs)\n",
      "  File \"/Users/nikulnayi/opt/anaconda3/lib/python3.9/site-packages/xgboost/core.py\", line 754, in __init__\n",
      "    self.set_info(\n",
      "  File \"/Users/nikulnayi/opt/anaconda3/lib/python3.9/site-packages/xgboost/core.py\", line 620, in inner_f\n",
      "    return func(**kwargs)\n",
      "  File \"/Users/nikulnayi/opt/anaconda3/lib/python3.9/site-packages/xgboost/core.py\", line 819, in set_info\n",
      "    self.set_label(label)\n",
      "  File \"/Users/nikulnayi/opt/anaconda3/lib/python3.9/site-packages/xgboost/core.py\", line 950, in set_label\n",
      "    dispatch_meta_backend(self, label, 'label', 'float')\n",
      "  File \"/Users/nikulnayi/opt/anaconda3/lib/python3.9/site-packages/xgboost/data.py\", line 1134, in dispatch_meta_backend\n",
      "    _meta_from_pandas_series(data, name, dtype, handle)\n",
      "  File \"/Users/nikulnayi/opt/anaconda3/lib/python3.9/site-packages/xgboost/data.py\", line 443, in _meta_from_pandas_series\n",
      "    _meta_from_numpy(data, name, dtype, handle)\n",
      "  File \"/Users/nikulnayi/opt/anaconda3/lib/python3.9/site-packages/xgboost/data.py\", line 1050, in _meta_from_numpy\n",
      "    _check_call(_LIB.XGDMatrixSetInfoFromInterface(handle, c_str(field), interface_str))\n",
      "  File \"/Users/nikulnayi/opt/anaconda3/lib/python3.9/site-packages/xgboost/core.py\", line 279, in _check_call\n",
      "    raise XGBoostError(py_str(_LIB.XGBGetLastError()))\n",
      "xgboost.core.XGBoostError: [15:15:11] /Users/runner/work/xgboost/xgboost/python-package/build/temp.macosx-10.9-x86_64-cpython-38/xgboost/src/data/data.cc:455: Check failed: this->labels.Size() % this->num_row_ == 0 (20666 vs. 0) : Incorrect size for labels.\n",
      "Stack trace:\n",
      "  [bt] (0) 1   libxgboost.dylib                    0x000000013643eb15 dmlc::LogMessageFatal::~LogMessageFatal() + 117\n",
      "  [bt] (1) 2   libxgboost.dylib                    0x00000001364d47aa xgboost::MetaInfo::SetInfoFromHost(xgboost::GenericParameter const&, xgboost::StringView, xgboost::Json) + 4282\n",
      "  [bt] (2) 3   libxgboost.dylib                    0x00000001364d3602 xgboost::MetaInfo::SetInfo(xgboost::GenericParameter const&, xgboost::StringView, xgboost::StringView) + 146\n",
      "  [bt] (3) 4   libxgboost.dylib                    0x00000001364551f9 XGDMatrixSetInfoFromInterface + 233\n",
      "  [bt] (4) 5   libffi.7.dylib                      0x000000010dd07ead ffi_call_unix64 + 85\n",
      "  [bt] (5) 6   ???                                 0x0000000309c88090 0x0 + 13049036944\n",
      "\n",
      "\n",
      "\n",
      "--------------------------------------------------------------------------------\n",
      "1 fits failed with the following error:\n",
      "Traceback (most recent call last):\n",
      "  File \"/Users/nikulnayi/opt/anaconda3/lib/python3.9/site-packages/sklearn/model_selection/_validation.py\", line 680, in _fit_and_score\n",
      "    estimator.fit(X_train, y_train, **fit_params)\n",
      "  File \"/Users/nikulnayi/opt/anaconda3/lib/python3.9/site-packages/sklearn/pipeline.py\", line 394, in fit\n",
      "    self._final_estimator.fit(Xt, y, **fit_params_last_step)\n",
      "  File \"/Users/nikulnayi/opt/anaconda3/lib/python3.9/site-packages/xgboost/core.py\", line 620, in inner_f\n",
      "    return func(**kwargs)\n",
      "  File \"/Users/nikulnayi/opt/anaconda3/lib/python3.9/site-packages/xgboost/sklearn.py\", line 1471, in fit\n",
      "    train_dmatrix, evals = _wrap_evaluation_matrices(\n",
      "  File \"/Users/nikulnayi/opt/anaconda3/lib/python3.9/site-packages/xgboost/sklearn.py\", line 448, in _wrap_evaluation_matrices\n",
      "    train_dmatrix = create_dmatrix(\n",
      "  File \"/Users/nikulnayi/opt/anaconda3/lib/python3.9/site-packages/xgboost/sklearn.py\", line 908, in _create_dmatrix\n",
      "    return DMatrix(**kwargs, nthread=self.n_jobs)\n",
      "  File \"/Users/nikulnayi/opt/anaconda3/lib/python3.9/site-packages/xgboost/core.py\", line 620, in inner_f\n",
      "    return func(**kwargs)\n",
      "  File \"/Users/nikulnayi/opt/anaconda3/lib/python3.9/site-packages/xgboost/core.py\", line 754, in __init__\n",
      "    self.set_info(\n",
      "  File \"/Users/nikulnayi/opt/anaconda3/lib/python3.9/site-packages/xgboost/core.py\", line 620, in inner_f\n",
      "    return func(**kwargs)\n",
      "  File \"/Users/nikulnayi/opt/anaconda3/lib/python3.9/site-packages/xgboost/core.py\", line 819, in set_info\n",
      "    self.set_label(label)\n",
      "  File \"/Users/nikulnayi/opt/anaconda3/lib/python3.9/site-packages/xgboost/core.py\", line 950, in set_label\n",
      "    dispatch_meta_backend(self, label, 'label', 'float')\n",
      "  File \"/Users/nikulnayi/opt/anaconda3/lib/python3.9/site-packages/xgboost/data.py\", line 1134, in dispatch_meta_backend\n",
      "    _meta_from_pandas_series(data, name, dtype, handle)\n",
      "  File \"/Users/nikulnayi/opt/anaconda3/lib/python3.9/site-packages/xgboost/data.py\", line 443, in _meta_from_pandas_series\n",
      "    _meta_from_numpy(data, name, dtype, handle)\n",
      "  File \"/Users/nikulnayi/opt/anaconda3/lib/python3.9/site-packages/xgboost/data.py\", line 1050, in _meta_from_numpy\n",
      "    _check_call(_LIB.XGDMatrixSetInfoFromInterface(handle, c_str(field), interface_str))\n",
      "  File \"/Users/nikulnayi/opt/anaconda3/lib/python3.9/site-packages/xgboost/core.py\", line 279, in _check_call\n",
      "    raise XGBoostError(py_str(_LIB.XGBGetLastError()))\n",
      "xgboost.core.XGBoostError: [15:15:11] /Users/runner/work/xgboost/xgboost/python-package/build/temp.macosx-10.9-x86_64-cpython-38/xgboost/src/data/data.cc:455: Check failed: this->labels.Size() % this->num_row_ == 0 (20665 vs. 0) : Incorrect size for labels.\n",
      "Stack trace:\n",
      "  [bt] (0) 1   libxgboost.dylib                    0x000000013633fb15 dmlc::LogMessageFatal::~LogMessageFatal() + 117\n",
      "  [bt] (1) 2   libxgboost.dylib                    0x00000001363d57aa xgboost::MetaInfo::SetInfoFromHost(xgboost::GenericParameter const&, xgboost::StringView, xgboost::Json) + 4282\n",
      "  [bt] (2) 3   libxgboost.dylib                    0x00000001363d4602 xgboost::MetaInfo::SetInfo(xgboost::GenericParameter const&, xgboost::StringView, xgboost::StringView) + 146\n",
      "  [bt] (3) 4   libxgboost.dylib                    0x00000001363561f9 XGDMatrixSetInfoFromInterface + 233\n",
      "  [bt] (4) 5   libffi.7.dylib                      0x000000010dc08ead ffi_call_unix64 + 85\n",
      "  [bt] (5) 6   ???                                 0x0000000309aae090 0x0 + 13047095440\n",
      "\n",
      "\n",
      "\n",
      "--------------------------------------------------------------------------------\n",
      "3 fits failed with the following error:\n",
      "Traceback (most recent call last):\n",
      "  File \"/Users/nikulnayi/opt/anaconda3/lib/python3.9/site-packages/sklearn/model_selection/_validation.py\", line 680, in _fit_and_score\n",
      "    estimator.fit(X_train, y_train, **fit_params)\n",
      "  File \"/Users/nikulnayi/opt/anaconda3/lib/python3.9/site-packages/sklearn/pipeline.py\", line 394, in fit\n",
      "    self._final_estimator.fit(Xt, y, **fit_params_last_step)\n",
      "  File \"/Users/nikulnayi/opt/anaconda3/lib/python3.9/site-packages/xgboost/core.py\", line 620, in inner_f\n",
      "    return func(**kwargs)\n",
      "  File \"/Users/nikulnayi/opt/anaconda3/lib/python3.9/site-packages/xgboost/sklearn.py\", line 1471, in fit\n",
      "    train_dmatrix, evals = _wrap_evaluation_matrices(\n",
      "  File \"/Users/nikulnayi/opt/anaconda3/lib/python3.9/site-packages/xgboost/sklearn.py\", line 448, in _wrap_evaluation_matrices\n",
      "    train_dmatrix = create_dmatrix(\n",
      "  File \"/Users/nikulnayi/opt/anaconda3/lib/python3.9/site-packages/xgboost/sklearn.py\", line 908, in _create_dmatrix\n",
      "    return DMatrix(**kwargs, nthread=self.n_jobs)\n",
      "  File \"/Users/nikulnayi/opt/anaconda3/lib/python3.9/site-packages/xgboost/core.py\", line 620, in inner_f\n",
      "    return func(**kwargs)\n",
      "  File \"/Users/nikulnayi/opt/anaconda3/lib/python3.9/site-packages/xgboost/core.py\", line 754, in __init__\n",
      "    self.set_info(\n",
      "  File \"/Users/nikulnayi/opt/anaconda3/lib/python3.9/site-packages/xgboost/core.py\", line 620, in inner_f\n",
      "    return func(**kwargs)\n",
      "  File \"/Users/nikulnayi/opt/anaconda3/lib/python3.9/site-packages/xgboost/core.py\", line 819, in set_info\n",
      "    self.set_label(label)\n",
      "  File \"/Users/nikulnayi/opt/anaconda3/lib/python3.9/site-packages/xgboost/core.py\", line 950, in set_label\n",
      "    dispatch_meta_backend(self, label, 'label', 'float')\n",
      "  File \"/Users/nikulnayi/opt/anaconda3/lib/python3.9/site-packages/xgboost/data.py\", line 1134, in dispatch_meta_backend\n",
      "    _meta_from_pandas_series(data, name, dtype, handle)\n",
      "  File \"/Users/nikulnayi/opt/anaconda3/lib/python3.9/site-packages/xgboost/data.py\", line 443, in _meta_from_pandas_series\n",
      "    _meta_from_numpy(data, name, dtype, handle)\n",
      "  File \"/Users/nikulnayi/opt/anaconda3/lib/python3.9/site-packages/xgboost/data.py\", line 1050, in _meta_from_numpy\n",
      "    _check_call(_LIB.XGDMatrixSetInfoFromInterface(handle, c_str(field), interface_str))\n",
      "  File \"/Users/nikulnayi/opt/anaconda3/lib/python3.9/site-packages/xgboost/core.py\", line 279, in _check_call\n",
      "    raise XGBoostError(py_str(_LIB.XGBGetLastError()))\n",
      "xgboost.core.XGBoostError: [15:15:11] /Users/runner/work/xgboost/xgboost/python-package/build/temp.macosx-10.9-x86_64-cpython-38/xgboost/src/data/data.cc:455: Check failed: this->labels.Size() % this->num_row_ == 0 (20665 vs. 0) : Incorrect size for labels.\n",
      "Stack trace:\n",
      "  [bt] (0) 1   libxgboost.dylib                    0x000000013643eb15 dmlc::LogMessageFatal::~LogMessageFatal() + 117\n",
      "  [bt] (1) 2   libxgboost.dylib                    0x00000001364d47aa xgboost::MetaInfo::SetInfoFromHost(xgboost::GenericParameter const&, xgboost::StringView, xgboost::Json) + 4282\n",
      "  [bt] (2) 3   libxgboost.dylib                    0x00000001364d3602 xgboost::MetaInfo::SetInfo(xgboost::GenericParameter const&, xgboost::StringView, xgboost::StringView) + 146\n",
      "  [bt] (3) 4   libxgboost.dylib                    0x00000001364551f9 XGDMatrixSetInfoFromInterface + 233\n",
      "  [bt] (4) 5   libffi.7.dylib                      0x000000010dd07ead ffi_call_unix64 + 85\n",
      "  [bt] (5) 6   ???                                 0x0000000309c88090 0x0 + 13049036944\n",
      "\n",
      "\n",
      "\n",
      "--------------------------------------------------------------------------------\n",
      "1 fits failed with the following error:\n",
      "Traceback (most recent call last):\n",
      "  File \"/Users/nikulnayi/opt/anaconda3/lib/python3.9/site-packages/sklearn/model_selection/_validation.py\", line 680, in _fit_and_score\n",
      "    estimator.fit(X_train, y_train, **fit_params)\n",
      "  File \"/Users/nikulnayi/opt/anaconda3/lib/python3.9/site-packages/sklearn/pipeline.py\", line 394, in fit\n",
      "    self._final_estimator.fit(Xt, y, **fit_params_last_step)\n",
      "  File \"/Users/nikulnayi/opt/anaconda3/lib/python3.9/site-packages/xgboost/core.py\", line 620, in inner_f\n",
      "    return func(**kwargs)\n",
      "  File \"/Users/nikulnayi/opt/anaconda3/lib/python3.9/site-packages/xgboost/sklearn.py\", line 1471, in fit\n",
      "    train_dmatrix, evals = _wrap_evaluation_matrices(\n",
      "  File \"/Users/nikulnayi/opt/anaconda3/lib/python3.9/site-packages/xgboost/sklearn.py\", line 448, in _wrap_evaluation_matrices\n",
      "    train_dmatrix = create_dmatrix(\n",
      "  File \"/Users/nikulnayi/opt/anaconda3/lib/python3.9/site-packages/xgboost/sklearn.py\", line 908, in _create_dmatrix\n",
      "    return DMatrix(**kwargs, nthread=self.n_jobs)\n",
      "  File \"/Users/nikulnayi/opt/anaconda3/lib/python3.9/site-packages/xgboost/core.py\", line 620, in inner_f\n",
      "    return func(**kwargs)\n",
      "  File \"/Users/nikulnayi/opt/anaconda3/lib/python3.9/site-packages/xgboost/core.py\", line 754, in __init__\n",
      "    self.set_info(\n",
      "  File \"/Users/nikulnayi/opt/anaconda3/lib/python3.9/site-packages/xgboost/core.py\", line 620, in inner_f\n",
      "    return func(**kwargs)\n",
      "  File \"/Users/nikulnayi/opt/anaconda3/lib/python3.9/site-packages/xgboost/core.py\", line 819, in set_info\n",
      "    self.set_label(label)\n",
      "  File \"/Users/nikulnayi/opt/anaconda3/lib/python3.9/site-packages/xgboost/core.py\", line 950, in set_label\n",
      "    dispatch_meta_backend(self, label, 'label', 'float')\n",
      "  File \"/Users/nikulnayi/opt/anaconda3/lib/python3.9/site-packages/xgboost/data.py\", line 1134, in dispatch_meta_backend\n",
      "    _meta_from_pandas_series(data, name, dtype, handle)\n",
      "  File \"/Users/nikulnayi/opt/anaconda3/lib/python3.9/site-packages/xgboost/data.py\", line 443, in _meta_from_pandas_series\n",
      "    _meta_from_numpy(data, name, dtype, handle)\n",
      "  File \"/Users/nikulnayi/opt/anaconda3/lib/python3.9/site-packages/xgboost/data.py\", line 1050, in _meta_from_numpy\n",
      "    _check_call(_LIB.XGDMatrixSetInfoFromInterface(handle, c_str(field), interface_str))\n",
      "  File \"/Users/nikulnayi/opt/anaconda3/lib/python3.9/site-packages/xgboost/core.py\", line 279, in _check_call\n",
      "    raise XGBoostError(py_str(_LIB.XGBGetLastError()))\n",
      "xgboost.core.XGBoostError: [15:15:11] /Users/runner/work/xgboost/xgboost/python-package/build/temp.macosx-10.9-x86_64-cpython-38/xgboost/src/data/data.cc:455: Check failed: this->labels.Size() % this->num_row_ == 0 (20666 vs. 0) : Incorrect size for labels.\n",
      "Stack trace:\n",
      "  [bt] (0) 1   libxgboost.dylib                    0x000000013633fb15 dmlc::LogMessageFatal::~LogMessageFatal() + 117\n",
      "  [bt] (1) 2   libxgboost.dylib                    0x00000001363d57aa xgboost::MetaInfo::SetInfoFromHost(xgboost::GenericParameter const&, xgboost::StringView, xgboost::Json) + 4282\n",
      "  [bt] (2) 3   libxgboost.dylib                    0x00000001363d4602 xgboost::MetaInfo::SetInfo(xgboost::GenericParameter const&, xgboost::StringView, xgboost::StringView) + 146\n",
      "  [bt] (3) 4   libxgboost.dylib                    0x00000001363561f9 XGDMatrixSetInfoFromInterface + 233\n",
      "  [bt] (4) 5   libffi.7.dylib                      0x000000010dc08ead ffi_call_unix64 + 85\n",
      "  [bt] (5) 6   ???                                 0x0000000309aae090 0x0 + 13047095440\n",
      "\n",
      "\n",
      "\n",
      "--------------------------------------------------------------------------------\n",
      "1 fits failed with the following error:\n",
      "Traceback (most recent call last):\n",
      "  File \"/Users/nikulnayi/opt/anaconda3/lib/python3.9/site-packages/sklearn/model_selection/_validation.py\", line 680, in _fit_and_score\n",
      "    estimator.fit(X_train, y_train, **fit_params)\n",
      "  File \"/Users/nikulnayi/opt/anaconda3/lib/python3.9/site-packages/sklearn/pipeline.py\", line 394, in fit\n",
      "    self._final_estimator.fit(Xt, y, **fit_params_last_step)\n",
      "  File \"/Users/nikulnayi/opt/anaconda3/lib/python3.9/site-packages/xgboost/core.py\", line 620, in inner_f\n",
      "    return func(**kwargs)\n",
      "  File \"/Users/nikulnayi/opt/anaconda3/lib/python3.9/site-packages/xgboost/sklearn.py\", line 1471, in fit\n",
      "    train_dmatrix, evals = _wrap_evaluation_matrices(\n",
      "  File \"/Users/nikulnayi/opt/anaconda3/lib/python3.9/site-packages/xgboost/sklearn.py\", line 448, in _wrap_evaluation_matrices\n",
      "    train_dmatrix = create_dmatrix(\n",
      "  File \"/Users/nikulnayi/opt/anaconda3/lib/python3.9/site-packages/xgboost/sklearn.py\", line 908, in _create_dmatrix\n",
      "    return DMatrix(**kwargs, nthread=self.n_jobs)\n",
      "  File \"/Users/nikulnayi/opt/anaconda3/lib/python3.9/site-packages/xgboost/core.py\", line 620, in inner_f\n",
      "    return func(**kwargs)\n",
      "  File \"/Users/nikulnayi/opt/anaconda3/lib/python3.9/site-packages/xgboost/core.py\", line 754, in __init__\n",
      "    self.set_info(\n",
      "  File \"/Users/nikulnayi/opt/anaconda3/lib/python3.9/site-packages/xgboost/core.py\", line 620, in inner_f\n",
      "    return func(**kwargs)\n",
      "  File \"/Users/nikulnayi/opt/anaconda3/lib/python3.9/site-packages/xgboost/core.py\", line 819, in set_info\n",
      "    self.set_label(label)\n",
      "  File \"/Users/nikulnayi/opt/anaconda3/lib/python3.9/site-packages/xgboost/core.py\", line 950, in set_label\n",
      "    dispatch_meta_backend(self, label, 'label', 'float')\n",
      "  File \"/Users/nikulnayi/opt/anaconda3/lib/python3.9/site-packages/xgboost/data.py\", line 1134, in dispatch_meta_backend\n",
      "    _meta_from_pandas_series(data, name, dtype, handle)\n",
      "  File \"/Users/nikulnayi/opt/anaconda3/lib/python3.9/site-packages/xgboost/data.py\", line 443, in _meta_from_pandas_series\n",
      "    _meta_from_numpy(data, name, dtype, handle)\n",
      "  File \"/Users/nikulnayi/opt/anaconda3/lib/python3.9/site-packages/xgboost/data.py\", line 1050, in _meta_from_numpy\n",
      "    _check_call(_LIB.XGDMatrixSetInfoFromInterface(handle, c_str(field), interface_str))\n",
      "  File \"/Users/nikulnayi/opt/anaconda3/lib/python3.9/site-packages/xgboost/core.py\", line 279, in _check_call\n",
      "    raise XGBoostError(py_str(_LIB.XGBGetLastError()))\n",
      "xgboost.core.XGBoostError: [15:15:11] /Users/runner/work/xgboost/xgboost/python-package/build/temp.macosx-10.9-x86_64-cpython-38/xgboost/src/data/data.cc:455: Check failed: this->labels.Size() % this->num_row_ == 0 (20666 vs. 0) : Incorrect size for labels.\n",
      "Stack trace:\n",
      "  [bt] (0) 1   libxgboost.dylib                    0x00000001360ceb15 dmlc::LogMessageFatal::~LogMessageFatal() + 117\n",
      "  [bt] (1) 2   libxgboost.dylib                    0x00000001361647aa xgboost::MetaInfo::SetInfoFromHost(xgboost::GenericParameter const&, xgboost::StringView, xgboost::Json) + 4282\n",
      "  [bt] (2) 3   libxgboost.dylib                    0x0000000136163602 xgboost::MetaInfo::SetInfo(xgboost::GenericParameter const&, xgboost::StringView, xgboost::StringView) + 146\n",
      "  [bt] (3) 4   libxgboost.dylib                    0x00000001360e51f9 XGDMatrixSetInfoFromInterface + 233\n",
      "  [bt] (4) 5   libffi.7.dylib                      0x000000010d997ead ffi_call_unix64 + 85\n",
      "  [bt] (5) 6   ???                                 0x000000030972e090 0x0 + 13043425424\n",
      "\n",
      "\n",
      "\n",
      "--------------------------------------------------------------------------------\n",
      "2 fits failed with the following error:\n",
      "Traceback (most recent call last):\n",
      "  File \"/Users/nikulnayi/opt/anaconda3/lib/python3.9/site-packages/sklearn/model_selection/_validation.py\", line 680, in _fit_and_score\n",
      "    estimator.fit(X_train, y_train, **fit_params)\n",
      "  File \"/Users/nikulnayi/opt/anaconda3/lib/python3.9/site-packages/sklearn/pipeline.py\", line 394, in fit\n",
      "    self._final_estimator.fit(Xt, y, **fit_params_last_step)\n",
      "  File \"/Users/nikulnayi/opt/anaconda3/lib/python3.9/site-packages/xgboost/core.py\", line 620, in inner_f\n",
      "    return func(**kwargs)\n",
      "  File \"/Users/nikulnayi/opt/anaconda3/lib/python3.9/site-packages/xgboost/sklearn.py\", line 1471, in fit\n",
      "    train_dmatrix, evals = _wrap_evaluation_matrices(\n",
      "  File \"/Users/nikulnayi/opt/anaconda3/lib/python3.9/site-packages/xgboost/sklearn.py\", line 448, in _wrap_evaluation_matrices\n",
      "    train_dmatrix = create_dmatrix(\n",
      "  File \"/Users/nikulnayi/opt/anaconda3/lib/python3.9/site-packages/xgboost/sklearn.py\", line 908, in _create_dmatrix\n",
      "    return DMatrix(**kwargs, nthread=self.n_jobs)\n",
      "  File \"/Users/nikulnayi/opt/anaconda3/lib/python3.9/site-packages/xgboost/core.py\", line 620, in inner_f\n",
      "    return func(**kwargs)\n",
      "  File \"/Users/nikulnayi/opt/anaconda3/lib/python3.9/site-packages/xgboost/core.py\", line 754, in __init__\n",
      "    self.set_info(\n",
      "  File \"/Users/nikulnayi/opt/anaconda3/lib/python3.9/site-packages/xgboost/core.py\", line 620, in inner_f\n",
      "    return func(**kwargs)\n",
      "  File \"/Users/nikulnayi/opt/anaconda3/lib/python3.9/site-packages/xgboost/core.py\", line 819, in set_info\n",
      "    self.set_label(label)\n",
      "  File \"/Users/nikulnayi/opt/anaconda3/lib/python3.9/site-packages/xgboost/core.py\", line 950, in set_label\n",
      "    dispatch_meta_backend(self, label, 'label', 'float')\n",
      "  File \"/Users/nikulnayi/opt/anaconda3/lib/python3.9/site-packages/xgboost/data.py\", line 1134, in dispatch_meta_backend\n",
      "    _meta_from_pandas_series(data, name, dtype, handle)\n",
      "  File \"/Users/nikulnayi/opt/anaconda3/lib/python3.9/site-packages/xgboost/data.py\", line 443, in _meta_from_pandas_series\n",
      "    _meta_from_numpy(data, name, dtype, handle)\n",
      "  File \"/Users/nikulnayi/opt/anaconda3/lib/python3.9/site-packages/xgboost/data.py\", line 1050, in _meta_from_numpy\n",
      "    _check_call(_LIB.XGDMatrixSetInfoFromInterface(handle, c_str(field), interface_str))\n",
      "  File \"/Users/nikulnayi/opt/anaconda3/lib/python3.9/site-packages/xgboost/core.py\", line 279, in _check_call\n",
      "    raise XGBoostError(py_str(_LIB.XGBGetLastError()))\n",
      "xgboost.core.XGBoostError: [15:15:12] /Users/runner/work/xgboost/xgboost/python-package/build/temp.macosx-10.9-x86_64-cpython-38/xgboost/src/data/data.cc:455: Check failed: this->labels.Size() % this->num_row_ == 0 (20665 vs. 0) : Incorrect size for labels.\n",
      "Stack trace:\n",
      "  [bt] (0) 1   libxgboost.dylib                    0x000000013643eb15 dmlc::LogMessageFatal::~LogMessageFatal() + 117\n",
      "  [bt] (1) 2   libxgboost.dylib                    0x00000001364d47aa xgboost::MetaInfo::SetInfoFromHost(xgboost::GenericParameter const&, xgboost::StringView, xgboost::Json) + 4282\n",
      "  [bt] (2) 3   libxgboost.dylib                    0x00000001364d3602 xgboost::MetaInfo::SetInfo(xgboost::GenericParameter const&, xgboost::StringView, xgboost::StringView) + 146\n",
      "  [bt] (3) 4   libxgboost.dylib                    0x00000001364551f9 XGDMatrixSetInfoFromInterface + 233\n",
      "  [bt] (4) 5   libffi.7.dylib                      0x000000010dd07ead ffi_call_unix64 + 85\n",
      "  [bt] (5) 6   ???                                 0x0000000309c88090 0x0 + 13049036944\n",
      "\n",
      "\n",
      "\n",
      "--------------------------------------------------------------------------------\n",
      "1 fits failed with the following error:\n",
      "Traceback (most recent call last):\n",
      "  File \"/Users/nikulnayi/opt/anaconda3/lib/python3.9/site-packages/sklearn/model_selection/_validation.py\", line 680, in _fit_and_score\n",
      "    estimator.fit(X_train, y_train, **fit_params)\n",
      "  File \"/Users/nikulnayi/opt/anaconda3/lib/python3.9/site-packages/sklearn/pipeline.py\", line 394, in fit\n",
      "    self._final_estimator.fit(Xt, y, **fit_params_last_step)\n",
      "  File \"/Users/nikulnayi/opt/anaconda3/lib/python3.9/site-packages/xgboost/core.py\", line 620, in inner_f\n",
      "    return func(**kwargs)\n",
      "  File \"/Users/nikulnayi/opt/anaconda3/lib/python3.9/site-packages/xgboost/sklearn.py\", line 1471, in fit\n",
      "    train_dmatrix, evals = _wrap_evaluation_matrices(\n",
      "  File \"/Users/nikulnayi/opt/anaconda3/lib/python3.9/site-packages/xgboost/sklearn.py\", line 448, in _wrap_evaluation_matrices\n",
      "    train_dmatrix = create_dmatrix(\n",
      "  File \"/Users/nikulnayi/opt/anaconda3/lib/python3.9/site-packages/xgboost/sklearn.py\", line 908, in _create_dmatrix\n",
      "    return DMatrix(**kwargs, nthread=self.n_jobs)\n",
      "  File \"/Users/nikulnayi/opt/anaconda3/lib/python3.9/site-packages/xgboost/core.py\", line 620, in inner_f\n",
      "    return func(**kwargs)\n",
      "  File \"/Users/nikulnayi/opt/anaconda3/lib/python3.9/site-packages/xgboost/core.py\", line 754, in __init__\n",
      "    self.set_info(\n",
      "  File \"/Users/nikulnayi/opt/anaconda3/lib/python3.9/site-packages/xgboost/core.py\", line 620, in inner_f\n",
      "    return func(**kwargs)\n",
      "  File \"/Users/nikulnayi/opt/anaconda3/lib/python3.9/site-packages/xgboost/core.py\", line 819, in set_info\n",
      "    self.set_label(label)\n",
      "  File \"/Users/nikulnayi/opt/anaconda3/lib/python3.9/site-packages/xgboost/core.py\", line 950, in set_label\n",
      "    dispatch_meta_backend(self, label, 'label', 'float')\n",
      "  File \"/Users/nikulnayi/opt/anaconda3/lib/python3.9/site-packages/xgboost/data.py\", line 1134, in dispatch_meta_backend\n",
      "    _meta_from_pandas_series(data, name, dtype, handle)\n",
      "  File \"/Users/nikulnayi/opt/anaconda3/lib/python3.9/site-packages/xgboost/data.py\", line 443, in _meta_from_pandas_series\n",
      "    _meta_from_numpy(data, name, dtype, handle)\n",
      "  File \"/Users/nikulnayi/opt/anaconda3/lib/python3.9/site-packages/xgboost/data.py\", line 1050, in _meta_from_numpy\n",
      "    _check_call(_LIB.XGDMatrixSetInfoFromInterface(handle, c_str(field), interface_str))\n",
      "  File \"/Users/nikulnayi/opt/anaconda3/lib/python3.9/site-packages/xgboost/core.py\", line 279, in _check_call\n",
      "    raise XGBoostError(py_str(_LIB.XGBGetLastError()))\n",
      "xgboost.core.XGBoostError: [15:15:12] /Users/runner/work/xgboost/xgboost/python-package/build/temp.macosx-10.9-x86_64-cpython-38/xgboost/src/data/data.cc:455: Check failed: this->labels.Size() % this->num_row_ == 0 (20666 vs. 0) : Incorrect size for labels.\n",
      "Stack trace:\n",
      "  [bt] (0) 1   libxgboost.dylib                    0x000000013643eb15 dmlc::LogMessageFatal::~LogMessageFatal() + 117\n",
      "  [bt] (1) 2   libxgboost.dylib                    0x00000001364d47aa xgboost::MetaInfo::SetInfoFromHost(xgboost::GenericParameter const&, xgboost::StringView, xgboost::Json) + 4282\n",
      "  [bt] (2) 3   libxgboost.dylib                    0x00000001364d3602 xgboost::MetaInfo::SetInfo(xgboost::GenericParameter const&, xgboost::StringView, xgboost::StringView) + 146\n",
      "  [bt] (3) 4   libxgboost.dylib                    0x00000001364551f9 XGDMatrixSetInfoFromInterface + 233\n",
      "  [bt] (4) 5   libffi.7.dylib                      0x000000010dd07ead ffi_call_unix64 + 85\n",
      "  [bt] (5) 6   ???                                 0x0000000309c88090 0x0 + 13049036944\n",
      "\n",
      "\n",
      "\n",
      "--------------------------------------------------------------------------------\n",
      "1 fits failed with the following error:\n",
      "Traceback (most recent call last):\n",
      "  File \"/Users/nikulnayi/opt/anaconda3/lib/python3.9/site-packages/sklearn/model_selection/_validation.py\", line 680, in _fit_and_score\n",
      "    estimator.fit(X_train, y_train, **fit_params)\n",
      "  File \"/Users/nikulnayi/opt/anaconda3/lib/python3.9/site-packages/sklearn/pipeline.py\", line 394, in fit\n",
      "    self._final_estimator.fit(Xt, y, **fit_params_last_step)\n",
      "  File \"/Users/nikulnayi/opt/anaconda3/lib/python3.9/site-packages/xgboost/core.py\", line 620, in inner_f\n",
      "    return func(**kwargs)\n",
      "  File \"/Users/nikulnayi/opt/anaconda3/lib/python3.9/site-packages/xgboost/sklearn.py\", line 1471, in fit\n",
      "    train_dmatrix, evals = _wrap_evaluation_matrices(\n",
      "  File \"/Users/nikulnayi/opt/anaconda3/lib/python3.9/site-packages/xgboost/sklearn.py\", line 448, in _wrap_evaluation_matrices\n",
      "    train_dmatrix = create_dmatrix(\n",
      "  File \"/Users/nikulnayi/opt/anaconda3/lib/python3.9/site-packages/xgboost/sklearn.py\", line 908, in _create_dmatrix\n",
      "    return DMatrix(**kwargs, nthread=self.n_jobs)\n",
      "  File \"/Users/nikulnayi/opt/anaconda3/lib/python3.9/site-packages/xgboost/core.py\", line 620, in inner_f\n",
      "    return func(**kwargs)\n",
      "  File \"/Users/nikulnayi/opt/anaconda3/lib/python3.9/site-packages/xgboost/core.py\", line 754, in __init__\n",
      "    self.set_info(\n",
      "  File \"/Users/nikulnayi/opt/anaconda3/lib/python3.9/site-packages/xgboost/core.py\", line 620, in inner_f\n",
      "    return func(**kwargs)\n",
      "  File \"/Users/nikulnayi/opt/anaconda3/lib/python3.9/site-packages/xgboost/core.py\", line 819, in set_info\n",
      "    self.set_label(label)\n",
      "  File \"/Users/nikulnayi/opt/anaconda3/lib/python3.9/site-packages/xgboost/core.py\", line 950, in set_label\n",
      "    dispatch_meta_backend(self, label, 'label', 'float')\n",
      "  File \"/Users/nikulnayi/opt/anaconda3/lib/python3.9/site-packages/xgboost/data.py\", line 1134, in dispatch_meta_backend\n",
      "    _meta_from_pandas_series(data, name, dtype, handle)\n",
      "  File \"/Users/nikulnayi/opt/anaconda3/lib/python3.9/site-packages/xgboost/data.py\", line 443, in _meta_from_pandas_series\n",
      "    _meta_from_numpy(data, name, dtype, handle)\n",
      "  File \"/Users/nikulnayi/opt/anaconda3/lib/python3.9/site-packages/xgboost/data.py\", line 1050, in _meta_from_numpy\n",
      "    _check_call(_LIB.XGDMatrixSetInfoFromInterface(handle, c_str(field), interface_str))\n",
      "  File \"/Users/nikulnayi/opt/anaconda3/lib/python3.9/site-packages/xgboost/core.py\", line 279, in _check_call\n",
      "    raise XGBoostError(py_str(_LIB.XGBGetLastError()))\n",
      "xgboost.core.XGBoostError: [15:15:12] /Users/runner/work/xgboost/xgboost/python-package/build/temp.macosx-10.9-x86_64-cpython-38/xgboost/src/data/data.cc:455: Check failed: this->labels.Size() % this->num_row_ == 0 (20666 vs. 0) : Incorrect size for labels.\n",
      "Stack trace:\n",
      "  [bt] (0) 1   libxgboost.dylib                    0x0000000132ffeb15 dmlc::LogMessageFatal::~LogMessageFatal() + 117\n",
      "  [bt] (1) 2   libxgboost.dylib                    0x00000001330947aa xgboost::MetaInfo::SetInfoFromHost(xgboost::GenericParameter const&, xgboost::StringView, xgboost::Json) + 4282\n",
      "  [bt] (2) 3   libxgboost.dylib                    0x0000000133093602 xgboost::MetaInfo::SetInfo(xgboost::GenericParameter const&, xgboost::StringView, xgboost::StringView) + 146\n",
      "  [bt] (3) 4   libxgboost.dylib                    0x00000001330151f9 XGDMatrixSetInfoFromInterface + 233\n",
      "  [bt] (4) 5   libffi.7.dylib                      0x000000010a8c7ead ffi_call_unix64 + 85\n",
      "  [bt] (5) 6   ???                                 0x0000000303483090 0x0 + 12939964560\n",
      "\n",
      "\n",
      "\n",
      "--------------------------------------------------------------------------------\n",
      "2 fits failed with the following error:\n",
      "Traceback (most recent call last):\n",
      "  File \"/Users/nikulnayi/opt/anaconda3/lib/python3.9/site-packages/sklearn/model_selection/_validation.py\", line 680, in _fit_and_score\n",
      "    estimator.fit(X_train, y_train, **fit_params)\n",
      "  File \"/Users/nikulnayi/opt/anaconda3/lib/python3.9/site-packages/sklearn/pipeline.py\", line 394, in fit\n",
      "    self._final_estimator.fit(Xt, y, **fit_params_last_step)\n",
      "  File \"/Users/nikulnayi/opt/anaconda3/lib/python3.9/site-packages/xgboost/core.py\", line 620, in inner_f\n",
      "    return func(**kwargs)\n",
      "  File \"/Users/nikulnayi/opt/anaconda3/lib/python3.9/site-packages/xgboost/sklearn.py\", line 1471, in fit\n",
      "    train_dmatrix, evals = _wrap_evaluation_matrices(\n",
      "  File \"/Users/nikulnayi/opt/anaconda3/lib/python3.9/site-packages/xgboost/sklearn.py\", line 448, in _wrap_evaluation_matrices\n",
      "    train_dmatrix = create_dmatrix(\n",
      "  File \"/Users/nikulnayi/opt/anaconda3/lib/python3.9/site-packages/xgboost/sklearn.py\", line 908, in _create_dmatrix\n",
      "    return DMatrix(**kwargs, nthread=self.n_jobs)\n",
      "  File \"/Users/nikulnayi/opt/anaconda3/lib/python3.9/site-packages/xgboost/core.py\", line 620, in inner_f\n",
      "    return func(**kwargs)\n",
      "  File \"/Users/nikulnayi/opt/anaconda3/lib/python3.9/site-packages/xgboost/core.py\", line 754, in __init__\n",
      "    self.set_info(\n",
      "  File \"/Users/nikulnayi/opt/anaconda3/lib/python3.9/site-packages/xgboost/core.py\", line 620, in inner_f\n",
      "    return func(**kwargs)\n",
      "  File \"/Users/nikulnayi/opt/anaconda3/lib/python3.9/site-packages/xgboost/core.py\", line 819, in set_info\n",
      "    self.set_label(label)\n",
      "  File \"/Users/nikulnayi/opt/anaconda3/lib/python3.9/site-packages/xgboost/core.py\", line 950, in set_label\n",
      "    dispatch_meta_backend(self, label, 'label', 'float')\n",
      "  File \"/Users/nikulnayi/opt/anaconda3/lib/python3.9/site-packages/xgboost/data.py\", line 1134, in dispatch_meta_backend\n",
      "    _meta_from_pandas_series(data, name, dtype, handle)\n",
      "  File \"/Users/nikulnayi/opt/anaconda3/lib/python3.9/site-packages/xgboost/data.py\", line 443, in _meta_from_pandas_series\n",
      "    _meta_from_numpy(data, name, dtype, handle)\n",
      "  File \"/Users/nikulnayi/opt/anaconda3/lib/python3.9/site-packages/xgboost/data.py\", line 1050, in _meta_from_numpy\n",
      "    _check_call(_LIB.XGDMatrixSetInfoFromInterface(handle, c_str(field), interface_str))\n",
      "  File \"/Users/nikulnayi/opt/anaconda3/lib/python3.9/site-packages/xgboost/core.py\", line 279, in _check_call\n",
      "    raise XGBoostError(py_str(_LIB.XGBGetLastError()))\n",
      "xgboost.core.XGBoostError: [15:15:12] /Users/runner/work/xgboost/xgboost/python-package/build/temp.macosx-10.9-x86_64-cpython-38/xgboost/src/data/data.cc:455: Check failed: this->labels.Size() % this->num_row_ == 0 (20665 vs. 0) : Incorrect size for labels.\n",
      "Stack trace:\n",
      "  [bt] (0) 1   libxgboost.dylib                    0x0000000132ffeb15 dmlc::LogMessageFatal::~LogMessageFatal() + 117\n",
      "  [bt] (1) 2   libxgboost.dylib                    0x00000001330947aa xgboost::MetaInfo::SetInfoFromHost(xgboost::GenericParameter const&, xgboost::StringView, xgboost::Json) + 4282\n",
      "  [bt] (2) 3   libxgboost.dylib                    0x0000000133093602 xgboost::MetaInfo::SetInfo(xgboost::GenericParameter const&, xgboost::StringView, xgboost::StringView) + 146\n",
      "  [bt] (3) 4   libxgboost.dylib                    0x00000001330151f9 XGDMatrixSetInfoFromInterface + 233\n",
      "  [bt] (4) 5   libffi.7.dylib                      0x000000010a8c7ead ffi_call_unix64 + 85\n",
      "  [bt] (5) 6   ???                                 0x0000000303483090 0x0 + 12939964560\n",
      "\n",
      "\n",
      "\n",
      "--------------------------------------------------------------------------------\n",
      "1 fits failed with the following error:\n",
      "Traceback (most recent call last):\n",
      "  File \"/Users/nikulnayi/opt/anaconda3/lib/python3.9/site-packages/sklearn/model_selection/_validation.py\", line 680, in _fit_and_score\n",
      "    estimator.fit(X_train, y_train, **fit_params)\n",
      "  File \"/Users/nikulnayi/opt/anaconda3/lib/python3.9/site-packages/sklearn/pipeline.py\", line 394, in fit\n",
      "    self._final_estimator.fit(Xt, y, **fit_params_last_step)\n",
      "  File \"/Users/nikulnayi/opt/anaconda3/lib/python3.9/site-packages/xgboost/core.py\", line 620, in inner_f\n",
      "    return func(**kwargs)\n",
      "  File \"/Users/nikulnayi/opt/anaconda3/lib/python3.9/site-packages/xgboost/sklearn.py\", line 1471, in fit\n",
      "    train_dmatrix, evals = _wrap_evaluation_matrices(\n",
      "  File \"/Users/nikulnayi/opt/anaconda3/lib/python3.9/site-packages/xgboost/sklearn.py\", line 448, in _wrap_evaluation_matrices\n",
      "    train_dmatrix = create_dmatrix(\n",
      "  File \"/Users/nikulnayi/opt/anaconda3/lib/python3.9/site-packages/xgboost/sklearn.py\", line 908, in _create_dmatrix\n",
      "    return DMatrix(**kwargs, nthread=self.n_jobs)\n",
      "  File \"/Users/nikulnayi/opt/anaconda3/lib/python3.9/site-packages/xgboost/core.py\", line 620, in inner_f\n",
      "    return func(**kwargs)\n",
      "  File \"/Users/nikulnayi/opt/anaconda3/lib/python3.9/site-packages/xgboost/core.py\", line 754, in __init__\n",
      "    self.set_info(\n",
      "  File \"/Users/nikulnayi/opt/anaconda3/lib/python3.9/site-packages/xgboost/core.py\", line 620, in inner_f\n",
      "    return func(**kwargs)\n",
      "  File \"/Users/nikulnayi/opt/anaconda3/lib/python3.9/site-packages/xgboost/core.py\", line 819, in set_info\n",
      "    self.set_label(label)\n",
      "  File \"/Users/nikulnayi/opt/anaconda3/lib/python3.9/site-packages/xgboost/core.py\", line 950, in set_label\n",
      "    dispatch_meta_backend(self, label, 'label', 'float')\n",
      "  File \"/Users/nikulnayi/opt/anaconda3/lib/python3.9/site-packages/xgboost/data.py\", line 1134, in dispatch_meta_backend\n",
      "    _meta_from_pandas_series(data, name, dtype, handle)\n",
      "  File \"/Users/nikulnayi/opt/anaconda3/lib/python3.9/site-packages/xgboost/data.py\", line 443, in _meta_from_pandas_series\n",
      "    _meta_from_numpy(data, name, dtype, handle)\n",
      "  File \"/Users/nikulnayi/opt/anaconda3/lib/python3.9/site-packages/xgboost/data.py\", line 1050, in _meta_from_numpy\n",
      "    _check_call(_LIB.XGDMatrixSetInfoFromInterface(handle, c_str(field), interface_str))\n",
      "  File \"/Users/nikulnayi/opt/anaconda3/lib/python3.9/site-packages/xgboost/core.py\", line 279, in _check_call\n",
      "    raise XGBoostError(py_str(_LIB.XGBGetLastError()))\n",
      "xgboost.core.XGBoostError: [15:15:12] /Users/runner/work/xgboost/xgboost/python-package/build/temp.macosx-10.9-x86_64-cpython-38/xgboost/src/data/data.cc:455: Check failed: this->labels.Size() % this->num_row_ == 0 (20666 vs. 0) : Incorrect size for labels.\n",
      "Stack trace:\n",
      "  [bt] (0) 1   libxgboost.dylib                    0x0000000134f94b15 dmlc::LogMessageFatal::~LogMessageFatal() + 117\n",
      "  [bt] (1) 2   libxgboost.dylib                    0x000000013502a7aa xgboost::MetaInfo::SetInfoFromHost(xgboost::GenericParameter const&, xgboost::StringView, xgboost::Json) + 4282\n",
      "  [bt] (2) 3   libxgboost.dylib                    0x0000000135029602 xgboost::MetaInfo::SetInfo(xgboost::GenericParameter const&, xgboost::StringView, xgboost::StringView) + 146\n",
      "  [bt] (3) 4   libxgboost.dylib                    0x0000000134fab1f9 XGDMatrixSetInfoFromInterface + 233\n",
      "  [bt] (4) 5   libffi.7.dylib                      0x000000010c85dead ffi_call_unix64 + 85\n",
      "  [bt] (5) 6   ???                                 0x0000000307613090 0x0 + 13008711824\n",
      "\n",
      "\n",
      "\n",
      "--------------------------------------------------------------------------------\n",
      "3 fits failed with the following error:\n",
      "Traceback (most recent call last):\n",
      "  File \"/Users/nikulnayi/opt/anaconda3/lib/python3.9/site-packages/sklearn/model_selection/_validation.py\", line 680, in _fit_and_score\n",
      "    estimator.fit(X_train, y_train, **fit_params)\n",
      "  File \"/Users/nikulnayi/opt/anaconda3/lib/python3.9/site-packages/sklearn/pipeline.py\", line 394, in fit\n",
      "    self._final_estimator.fit(Xt, y, **fit_params_last_step)\n",
      "  File \"/Users/nikulnayi/opt/anaconda3/lib/python3.9/site-packages/xgboost/core.py\", line 620, in inner_f\n",
      "    return func(**kwargs)\n",
      "  File \"/Users/nikulnayi/opt/anaconda3/lib/python3.9/site-packages/xgboost/sklearn.py\", line 1471, in fit\n",
      "    train_dmatrix, evals = _wrap_evaluation_matrices(\n",
      "  File \"/Users/nikulnayi/opt/anaconda3/lib/python3.9/site-packages/xgboost/sklearn.py\", line 448, in _wrap_evaluation_matrices\n",
      "    train_dmatrix = create_dmatrix(\n",
      "  File \"/Users/nikulnayi/opt/anaconda3/lib/python3.9/site-packages/xgboost/sklearn.py\", line 908, in _create_dmatrix\n",
      "    return DMatrix(**kwargs, nthread=self.n_jobs)\n",
      "  File \"/Users/nikulnayi/opt/anaconda3/lib/python3.9/site-packages/xgboost/core.py\", line 620, in inner_f\n",
      "    return func(**kwargs)\n",
      "  File \"/Users/nikulnayi/opt/anaconda3/lib/python3.9/site-packages/xgboost/core.py\", line 754, in __init__\n",
      "    self.set_info(\n",
      "  File \"/Users/nikulnayi/opt/anaconda3/lib/python3.9/site-packages/xgboost/core.py\", line 620, in inner_f\n",
      "    return func(**kwargs)\n",
      "  File \"/Users/nikulnayi/opt/anaconda3/lib/python3.9/site-packages/xgboost/core.py\", line 819, in set_info\n",
      "    self.set_label(label)\n",
      "  File \"/Users/nikulnayi/opt/anaconda3/lib/python3.9/site-packages/xgboost/core.py\", line 950, in set_label\n",
      "    dispatch_meta_backend(self, label, 'label', 'float')\n",
      "  File \"/Users/nikulnayi/opt/anaconda3/lib/python3.9/site-packages/xgboost/data.py\", line 1134, in dispatch_meta_backend\n",
      "    _meta_from_pandas_series(data, name, dtype, handle)\n",
      "  File \"/Users/nikulnayi/opt/anaconda3/lib/python3.9/site-packages/xgboost/data.py\", line 443, in _meta_from_pandas_series\n",
      "    _meta_from_numpy(data, name, dtype, handle)\n",
      "  File \"/Users/nikulnayi/opt/anaconda3/lib/python3.9/site-packages/xgboost/data.py\", line 1050, in _meta_from_numpy\n",
      "    _check_call(_LIB.XGDMatrixSetInfoFromInterface(handle, c_str(field), interface_str))\n",
      "  File \"/Users/nikulnayi/opt/anaconda3/lib/python3.9/site-packages/xgboost/core.py\", line 279, in _check_call\n",
      "    raise XGBoostError(py_str(_LIB.XGBGetLastError()))\n",
      "xgboost.core.XGBoostError: [15:15:13] /Users/runner/work/xgboost/xgboost/python-package/build/temp.macosx-10.9-x86_64-cpython-38/xgboost/src/data/data.cc:455: Check failed: this->labels.Size() % this->num_row_ == 0 (20666 vs. 0) : Incorrect size for labels.\n",
      "Stack trace:\n",
      "  [bt] (0) 1   libxgboost.dylib                    0x0000000132ffeb15 dmlc::LogMessageFatal::~LogMessageFatal() + 117\n",
      "  [bt] (1) 2   libxgboost.dylib                    0x00000001330947aa xgboost::MetaInfo::SetInfoFromHost(xgboost::GenericParameter const&, xgboost::StringView, xgboost::Json) + 4282\n",
      "  [bt] (2) 3   libxgboost.dylib                    0x0000000133093602 xgboost::MetaInfo::SetInfo(xgboost::GenericParameter const&, xgboost::StringView, xgboost::StringView) + 146\n",
      "  [bt] (3) 4   libxgboost.dylib                    0x00000001330151f9 XGDMatrixSetInfoFromInterface + 233\n",
      "  [bt] (4) 5   libffi.7.dylib                      0x000000010a8c7ead ffi_call_unix64 + 85\n",
      "  [bt] (5) 6   ???                                 0x0000000303483090 0x0 + 12939964560\n",
      "\n",
      "\n",
      "\n",
      "--------------------------------------------------------------------------------\n",
      "1 fits failed with the following error:\n",
      "Traceback (most recent call last):\n",
      "  File \"/Users/nikulnayi/opt/anaconda3/lib/python3.9/site-packages/sklearn/model_selection/_validation.py\", line 680, in _fit_and_score\n",
      "    estimator.fit(X_train, y_train, **fit_params)\n",
      "  File \"/Users/nikulnayi/opt/anaconda3/lib/python3.9/site-packages/sklearn/pipeline.py\", line 394, in fit\n",
      "    self._final_estimator.fit(Xt, y, **fit_params_last_step)\n",
      "  File \"/Users/nikulnayi/opt/anaconda3/lib/python3.9/site-packages/xgboost/core.py\", line 620, in inner_f\n",
      "    return func(**kwargs)\n",
      "  File \"/Users/nikulnayi/opt/anaconda3/lib/python3.9/site-packages/xgboost/sklearn.py\", line 1471, in fit\n",
      "    train_dmatrix, evals = _wrap_evaluation_matrices(\n",
      "  File \"/Users/nikulnayi/opt/anaconda3/lib/python3.9/site-packages/xgboost/sklearn.py\", line 448, in _wrap_evaluation_matrices\n",
      "    train_dmatrix = create_dmatrix(\n",
      "  File \"/Users/nikulnayi/opt/anaconda3/lib/python3.9/site-packages/xgboost/sklearn.py\", line 908, in _create_dmatrix\n",
      "    return DMatrix(**kwargs, nthread=self.n_jobs)\n",
      "  File \"/Users/nikulnayi/opt/anaconda3/lib/python3.9/site-packages/xgboost/core.py\", line 620, in inner_f\n",
      "    return func(**kwargs)\n",
      "  File \"/Users/nikulnayi/opt/anaconda3/lib/python3.9/site-packages/xgboost/core.py\", line 754, in __init__\n",
      "    self.set_info(\n",
      "  File \"/Users/nikulnayi/opt/anaconda3/lib/python3.9/site-packages/xgboost/core.py\", line 620, in inner_f\n",
      "    return func(**kwargs)\n",
      "  File \"/Users/nikulnayi/opt/anaconda3/lib/python3.9/site-packages/xgboost/core.py\", line 819, in set_info\n",
      "    self.set_label(label)\n",
      "  File \"/Users/nikulnayi/opt/anaconda3/lib/python3.9/site-packages/xgboost/core.py\", line 950, in set_label\n",
      "    dispatch_meta_backend(self, label, 'label', 'float')\n",
      "  File \"/Users/nikulnayi/opt/anaconda3/lib/python3.9/site-packages/xgboost/data.py\", line 1134, in dispatch_meta_backend\n",
      "    _meta_from_pandas_series(data, name, dtype, handle)\n",
      "  File \"/Users/nikulnayi/opt/anaconda3/lib/python3.9/site-packages/xgboost/data.py\", line 443, in _meta_from_pandas_series\n",
      "    _meta_from_numpy(data, name, dtype, handle)\n",
      "  File \"/Users/nikulnayi/opt/anaconda3/lib/python3.9/site-packages/xgboost/data.py\", line 1050, in _meta_from_numpy\n",
      "    _check_call(_LIB.XGDMatrixSetInfoFromInterface(handle, c_str(field), interface_str))\n",
      "  File \"/Users/nikulnayi/opt/anaconda3/lib/python3.9/site-packages/xgboost/core.py\", line 279, in _check_call\n",
      "    raise XGBoostError(py_str(_LIB.XGBGetLastError()))\n",
      "xgboost.core.XGBoostError: [15:15:13] /Users/runner/work/xgboost/xgboost/python-package/build/temp.macosx-10.9-x86_64-cpython-38/xgboost/src/data/data.cc:455: Check failed: this->labels.Size() % this->num_row_ == 0 (20665 vs. 0) : Incorrect size for labels.\n",
      "Stack trace:\n",
      "  [bt] (0) 1   libxgboost.dylib                    0x000000013633fb15 dmlc::LogMessageFatal::~LogMessageFatal() + 117\n",
      "  [bt] (1) 2   libxgboost.dylib                    0x00000001363d57aa xgboost::MetaInfo::SetInfoFromHost(xgboost::GenericParameter const&, xgboost::StringView, xgboost::Json) + 4282\n",
      "  [bt] (2) 3   libxgboost.dylib                    0x00000001363d4602 xgboost::MetaInfo::SetInfo(xgboost::GenericParameter const&, xgboost::StringView, xgboost::StringView) + 146\n",
      "  [bt] (3) 4   libxgboost.dylib                    0x00000001363561f9 XGDMatrixSetInfoFromInterface + 233\n",
      "  [bt] (4) 5   libffi.7.dylib                      0x000000010dc08ead ffi_call_unix64 + 85\n",
      "  [bt] (5) 6   ???                                 0x0000000309aae090 0x0 + 13047095440\n",
      "\n",
      "\n",
      "\n",
      "--------------------------------------------------------------------------------\n",
      "3 fits failed with the following error:\n",
      "Traceback (most recent call last):\n",
      "  File \"/Users/nikulnayi/opt/anaconda3/lib/python3.9/site-packages/sklearn/model_selection/_validation.py\", line 680, in _fit_and_score\n",
      "    estimator.fit(X_train, y_train, **fit_params)\n",
      "  File \"/Users/nikulnayi/opt/anaconda3/lib/python3.9/site-packages/sklearn/pipeline.py\", line 394, in fit\n",
      "    self._final_estimator.fit(Xt, y, **fit_params_last_step)\n",
      "  File \"/Users/nikulnayi/opt/anaconda3/lib/python3.9/site-packages/xgboost/core.py\", line 620, in inner_f\n",
      "    return func(**kwargs)\n",
      "  File \"/Users/nikulnayi/opt/anaconda3/lib/python3.9/site-packages/xgboost/sklearn.py\", line 1471, in fit\n",
      "    train_dmatrix, evals = _wrap_evaluation_matrices(\n",
      "  File \"/Users/nikulnayi/opt/anaconda3/lib/python3.9/site-packages/xgboost/sklearn.py\", line 448, in _wrap_evaluation_matrices\n",
      "    train_dmatrix = create_dmatrix(\n",
      "  File \"/Users/nikulnayi/opt/anaconda3/lib/python3.9/site-packages/xgboost/sklearn.py\", line 908, in _create_dmatrix\n",
      "    return DMatrix(**kwargs, nthread=self.n_jobs)\n",
      "  File \"/Users/nikulnayi/opt/anaconda3/lib/python3.9/site-packages/xgboost/core.py\", line 620, in inner_f\n",
      "    return func(**kwargs)\n",
      "  File \"/Users/nikulnayi/opt/anaconda3/lib/python3.9/site-packages/xgboost/core.py\", line 754, in __init__\n",
      "    self.set_info(\n",
      "  File \"/Users/nikulnayi/opt/anaconda3/lib/python3.9/site-packages/xgboost/core.py\", line 620, in inner_f\n",
      "    return func(**kwargs)\n",
      "  File \"/Users/nikulnayi/opt/anaconda3/lib/python3.9/site-packages/xgboost/core.py\", line 819, in set_info\n",
      "    self.set_label(label)\n",
      "  File \"/Users/nikulnayi/opt/anaconda3/lib/python3.9/site-packages/xgboost/core.py\", line 950, in set_label\n",
      "    dispatch_meta_backend(self, label, 'label', 'float')\n",
      "  File \"/Users/nikulnayi/opt/anaconda3/lib/python3.9/site-packages/xgboost/data.py\", line 1134, in dispatch_meta_backend\n",
      "    _meta_from_pandas_series(data, name, dtype, handle)\n",
      "  File \"/Users/nikulnayi/opt/anaconda3/lib/python3.9/site-packages/xgboost/data.py\", line 443, in _meta_from_pandas_series\n",
      "    _meta_from_numpy(data, name, dtype, handle)\n",
      "  File \"/Users/nikulnayi/opt/anaconda3/lib/python3.9/site-packages/xgboost/data.py\", line 1050, in _meta_from_numpy\n",
      "    _check_call(_LIB.XGDMatrixSetInfoFromInterface(handle, c_str(field), interface_str))\n",
      "  File \"/Users/nikulnayi/opt/anaconda3/lib/python3.9/site-packages/xgboost/core.py\", line 279, in _check_call\n",
      "    raise XGBoostError(py_str(_LIB.XGBGetLastError()))\n",
      "xgboost.core.XGBoostError: [15:15:13] /Users/runner/work/xgboost/xgboost/python-package/build/temp.macosx-10.9-x86_64-cpython-38/xgboost/src/data/data.cc:455: Check failed: this->labels.Size() % this->num_row_ == 0 (20665 vs. 0) : Incorrect size for labels.\n",
      "Stack trace:\n",
      "  [bt] (0) 1   libxgboost.dylib                    0x0000000132ffeb15 dmlc::LogMessageFatal::~LogMessageFatal() + 117\n",
      "  [bt] (1) 2   libxgboost.dylib                    0x00000001330947aa xgboost::MetaInfo::SetInfoFromHost(xgboost::GenericParameter const&, xgboost::StringView, xgboost::Json) + 4282\n",
      "  [bt] (2) 3   libxgboost.dylib                    0x0000000133093602 xgboost::MetaInfo::SetInfo(xgboost::GenericParameter const&, xgboost::StringView, xgboost::StringView) + 146\n",
      "  [bt] (3) 4   libxgboost.dylib                    0x00000001330151f9 XGDMatrixSetInfoFromInterface + 233\n",
      "  [bt] (4) 5   libffi.7.dylib                      0x000000010a8c7ead ffi_call_unix64 + 85\n",
      "  [bt] (5) 6   ???                                 0x0000000303483090 0x0 + 12939964560\n",
      "\n",
      "\n",
      "\n",
      "--------------------------------------------------------------------------------\n",
      "1 fits failed with the following error:\n",
      "Traceback (most recent call last):\n",
      "  File \"/Users/nikulnayi/opt/anaconda3/lib/python3.9/site-packages/sklearn/model_selection/_validation.py\", line 680, in _fit_and_score\n",
      "    estimator.fit(X_train, y_train, **fit_params)\n",
      "  File \"/Users/nikulnayi/opt/anaconda3/lib/python3.9/site-packages/sklearn/pipeline.py\", line 394, in fit\n",
      "    self._final_estimator.fit(Xt, y, **fit_params_last_step)\n",
      "  File \"/Users/nikulnayi/opt/anaconda3/lib/python3.9/site-packages/xgboost/core.py\", line 620, in inner_f\n",
      "    return func(**kwargs)\n",
      "  File \"/Users/nikulnayi/opt/anaconda3/lib/python3.9/site-packages/xgboost/sklearn.py\", line 1471, in fit\n",
      "    train_dmatrix, evals = _wrap_evaluation_matrices(\n",
      "  File \"/Users/nikulnayi/opt/anaconda3/lib/python3.9/site-packages/xgboost/sklearn.py\", line 448, in _wrap_evaluation_matrices\n",
      "    train_dmatrix = create_dmatrix(\n",
      "  File \"/Users/nikulnayi/opt/anaconda3/lib/python3.9/site-packages/xgboost/sklearn.py\", line 908, in _create_dmatrix\n",
      "    return DMatrix(**kwargs, nthread=self.n_jobs)\n",
      "  File \"/Users/nikulnayi/opt/anaconda3/lib/python3.9/site-packages/xgboost/core.py\", line 620, in inner_f\n",
      "    return func(**kwargs)\n",
      "  File \"/Users/nikulnayi/opt/anaconda3/lib/python3.9/site-packages/xgboost/core.py\", line 754, in __init__\n",
      "    self.set_info(\n",
      "  File \"/Users/nikulnayi/opt/anaconda3/lib/python3.9/site-packages/xgboost/core.py\", line 620, in inner_f\n",
      "    return func(**kwargs)\n",
      "  File \"/Users/nikulnayi/opt/anaconda3/lib/python3.9/site-packages/xgboost/core.py\", line 819, in set_info\n",
      "    self.set_label(label)\n",
      "  File \"/Users/nikulnayi/opt/anaconda3/lib/python3.9/site-packages/xgboost/core.py\", line 950, in set_label\n",
      "    dispatch_meta_backend(self, label, 'label', 'float')\n",
      "  File \"/Users/nikulnayi/opt/anaconda3/lib/python3.9/site-packages/xgboost/data.py\", line 1134, in dispatch_meta_backend\n",
      "    _meta_from_pandas_series(data, name, dtype, handle)\n",
      "  File \"/Users/nikulnayi/opt/anaconda3/lib/python3.9/site-packages/xgboost/data.py\", line 443, in _meta_from_pandas_series\n",
      "    _meta_from_numpy(data, name, dtype, handle)\n",
      "  File \"/Users/nikulnayi/opt/anaconda3/lib/python3.9/site-packages/xgboost/data.py\", line 1050, in _meta_from_numpy\n",
      "    _check_call(_LIB.XGDMatrixSetInfoFromInterface(handle, c_str(field), interface_str))\n",
      "  File \"/Users/nikulnayi/opt/anaconda3/lib/python3.9/site-packages/xgboost/core.py\", line 279, in _check_call\n",
      "    raise XGBoostError(py_str(_LIB.XGBGetLastError()))\n",
      "xgboost.core.XGBoostError: [15:15:13] /Users/runner/work/xgboost/xgboost/python-package/build/temp.macosx-10.9-x86_64-cpython-38/xgboost/src/data/data.cc:455: Check failed: this->labels.Size() % this->num_row_ == 0 (20666 vs. 0) : Incorrect size for labels.\n",
      "Stack trace:\n",
      "  [bt] (0) 1   libxgboost.dylib                    0x000000013633fb15 dmlc::LogMessageFatal::~LogMessageFatal() + 117\n",
      "  [bt] (1) 2   libxgboost.dylib                    0x00000001363d57aa xgboost::MetaInfo::SetInfoFromHost(xgboost::GenericParameter const&, xgboost::StringView, xgboost::Json) + 4282\n",
      "  [bt] (2) 3   libxgboost.dylib                    0x00000001363d4602 xgboost::MetaInfo::SetInfo(xgboost::GenericParameter const&, xgboost::StringView, xgboost::StringView) + 146\n",
      "  [bt] (3) 4   libxgboost.dylib                    0x00000001363561f9 XGDMatrixSetInfoFromInterface + 233\n",
      "  [bt] (4) 5   libffi.7.dylib                      0x000000010dc08ead ffi_call_unix64 + 85\n",
      "  [bt] (5) 6   ???                                 0x0000000309aae090 0x0 + 13047095440\n",
      "\n",
      "\n",
      "\n",
      "--------------------------------------------------------------------------------\n",
      "1 fits failed with the following error:\n",
      "Traceback (most recent call last):\n",
      "  File \"/Users/nikulnayi/opt/anaconda3/lib/python3.9/site-packages/sklearn/model_selection/_validation.py\", line 680, in _fit_and_score\n",
      "    estimator.fit(X_train, y_train, **fit_params)\n",
      "  File \"/Users/nikulnayi/opt/anaconda3/lib/python3.9/site-packages/sklearn/pipeline.py\", line 394, in fit\n",
      "    self._final_estimator.fit(Xt, y, **fit_params_last_step)\n",
      "  File \"/Users/nikulnayi/opt/anaconda3/lib/python3.9/site-packages/xgboost/core.py\", line 620, in inner_f\n",
      "    return func(**kwargs)\n",
      "  File \"/Users/nikulnayi/opt/anaconda3/lib/python3.9/site-packages/xgboost/sklearn.py\", line 1471, in fit\n",
      "    train_dmatrix, evals = _wrap_evaluation_matrices(\n",
      "  File \"/Users/nikulnayi/opt/anaconda3/lib/python3.9/site-packages/xgboost/sklearn.py\", line 448, in _wrap_evaluation_matrices\n",
      "    train_dmatrix = create_dmatrix(\n",
      "  File \"/Users/nikulnayi/opt/anaconda3/lib/python3.9/site-packages/xgboost/sklearn.py\", line 908, in _create_dmatrix\n",
      "    return DMatrix(**kwargs, nthread=self.n_jobs)\n",
      "  File \"/Users/nikulnayi/opt/anaconda3/lib/python3.9/site-packages/xgboost/core.py\", line 620, in inner_f\n",
      "    return func(**kwargs)\n",
      "  File \"/Users/nikulnayi/opt/anaconda3/lib/python3.9/site-packages/xgboost/core.py\", line 754, in __init__\n",
      "    self.set_info(\n",
      "  File \"/Users/nikulnayi/opt/anaconda3/lib/python3.9/site-packages/xgboost/core.py\", line 620, in inner_f\n",
      "    return func(**kwargs)\n",
      "  File \"/Users/nikulnayi/opt/anaconda3/lib/python3.9/site-packages/xgboost/core.py\", line 819, in set_info\n",
      "    self.set_label(label)\n",
      "  File \"/Users/nikulnayi/opt/anaconda3/lib/python3.9/site-packages/xgboost/core.py\", line 950, in set_label\n",
      "    dispatch_meta_backend(self, label, 'label', 'float')\n",
      "  File \"/Users/nikulnayi/opt/anaconda3/lib/python3.9/site-packages/xgboost/data.py\", line 1134, in dispatch_meta_backend\n",
      "    _meta_from_pandas_series(data, name, dtype, handle)\n",
      "  File \"/Users/nikulnayi/opt/anaconda3/lib/python3.9/site-packages/xgboost/data.py\", line 443, in _meta_from_pandas_series\n",
      "    _meta_from_numpy(data, name, dtype, handle)\n",
      "  File \"/Users/nikulnayi/opt/anaconda3/lib/python3.9/site-packages/xgboost/data.py\", line 1050, in _meta_from_numpy\n",
      "    _check_call(_LIB.XGDMatrixSetInfoFromInterface(handle, c_str(field), interface_str))\n",
      "  File \"/Users/nikulnayi/opt/anaconda3/lib/python3.9/site-packages/xgboost/core.py\", line 279, in _check_call\n",
      "    raise XGBoostError(py_str(_LIB.XGBGetLastError()))\n",
      "xgboost.core.XGBoostError: [15:15:14] /Users/runner/work/xgboost/xgboost/python-package/build/temp.macosx-10.9-x86_64-cpython-38/xgboost/src/data/data.cc:455: Check failed: this->labels.Size() % this->num_row_ == 0 (20666 vs. 0) : Incorrect size for labels.\n",
      "Stack trace:\n",
      "  [bt] (0) 1   libxgboost.dylib                    0x0000000132ffeb15 dmlc::LogMessageFatal::~LogMessageFatal() + 117\n",
      "  [bt] (1) 2   libxgboost.dylib                    0x00000001330947aa xgboost::MetaInfo::SetInfoFromHost(xgboost::GenericParameter const&, xgboost::StringView, xgboost::Json) + 4282\n",
      "  [bt] (2) 3   libxgboost.dylib                    0x0000000133093602 xgboost::MetaInfo::SetInfo(xgboost::GenericParameter const&, xgboost::StringView, xgboost::StringView) + 146\n",
      "  [bt] (3) 4   libxgboost.dylib                    0x00000001330151f9 XGDMatrixSetInfoFromInterface + 233\n",
      "  [bt] (4) 5   libffi.7.dylib                      0x000000010a8c7ead ffi_call_unix64 + 85\n",
      "  [bt] (5) 6   ???                                 0x0000000303483090 0x0 + 12939964560\n",
      "\n",
      "\n",
      "\n",
      "  warnings.warn(some_fits_failed_message, FitFailedWarning)\n",
      "/Users/nikulnayi/opt/anaconda3/lib/python3.9/site-packages/sklearn/model_selection/_search.py:969: UserWarning: One or more of the test scores are non-finite: [nan nan nan nan nan nan nan nan nan nan nan nan nan nan nan nan nan nan\n",
      " nan nan nan nan nan nan nan nan nan nan nan nan]\n",
      "  warnings.warn(\n"
     ]
    },
    {
     "name": "stdout",
     "output_type": "stream",
     "text": [
      "Best hyperparameters: {'classifier': RandomForestClassifier(n_estimators=50), 'classifier__max_depth': None, 'classifier__min_samples_split': 2, 'classifier__n_estimators': 50}\n",
      "Best score: nan\n"
     ]
    }
   ],
   "source": [
    "# Define the hyperparameter grid for both classifiers\n",
    "param_grid = [rf_param_grid, xgb_param_grid]\n",
    "\n",
    "# Define the cross-validation strategy\n",
    "cv = 5\n",
    "\n",
    "# Define the GridSearchCV object\n",
    "grid_search = GridSearchCV(pipeline, param_grid = param_grid, cv=cv, n_jobs=-1, scoring='recall')\n",
    "\n",
    "# Fit the GridSearchCV object to the data\n",
    "grid_search.fit(X_train, y_train)\n",
    "\n",
    "# Print the best hyperparameters and score\n",
    "print('Best hyperparameters:', grid_search.best_params_)\n",
    "print('Best score:', grid_search.best_score_)"
   ]
  },
  {
   "cell_type": "code",
   "execution_count": 22,
   "metadata": {},
   "outputs": [
    {
     "name": "stdout",
     "output_type": "stream",
     "text": [
      "Test set score: 0.506363027461487\n"
     ]
    }
   ],
   "source": [
    "print(\"Test set score:\", grid_search.score(X_test, y_test))"
   ]
  },
  {
   "cell_type": "code",
   "execution_count": null,
   "metadata": {},
   "outputs": [],
   "source": []
  }
 ],
 "metadata": {
  "kernelspec": {
   "display_name": "Python 3 (ipykernel)",
   "language": "python",
   "name": "python3"
  },
  "language_info": {
   "codemirror_mode": {
    "name": "ipython",
    "version": 3
   },
   "file_extension": ".py",
   "mimetype": "text/x-python",
   "name": "python",
   "nbconvert_exporter": "python",
   "pygments_lexer": "ipython3",
   "version": "3.9.13"
  },
  "vscode": {
   "interpreter": {
    "hash": "1f7c1d7db85b32830ff0d55d734086d39ad7be3e9db2adfe068dfce6a42a57de"
   }
  }
 },
 "nbformat": 4,
 "nbformat_minor": 2
}
